Workbook
Name rngAccounts: Accounts!$B$2:$B$200
Name rngAccountStatus: Helpers!$A$70:$A$71
Name rngAccountType: Helpers!$A$91:$A$98
Name rngActiveAccounts: Helpers!$B$132
Name rngActiveAssets: Helpers!$B$134
Name rngActiveGoals: Helpers!$B$133
Name rngActiveLiabilities: Helpers!$B$135
Name rngAssets: Assets!$B$2:$B$200
Name rngAssetType: Helpers!$AG$2:$AG$25
Name rngBoolean: Helpers!$A$86:$A$87
Name rngCategories: Categories!$B$2:$B$200
Name rngCategoryType: Helpers!$A$102:$A$103
Name rngCurrency: Helpers!$A$2:$A$6
Name rngExpenseCategories: Helpers!$B$130
Name rngFinancialYears: Helpers!$A$126
Name rngFrequency: Helpers!$A$38:$A$41
Name rngGoals: Goals!$B$2:$B$200
Name rngGoalStatus: Helpers!$A$59:$A$61
Name rngIncomeCategories: Helpers!$B$131
Name rngIncomeSources: 'Income Sources'!$B$2:$B$200
Name rngIncomeType: Helpers!$AI$2:$AI$10
Name rngLiabilities: Liabilities!$B$2:$B$200
Name rngLiabilityType: Helpers!$AH$2:$AH$11
Name rngMonths: Helpers!$B$111:$B$122
Name rngPaymentMethods: Helpers!$A$10:$A$17
Name rngPriority: Helpers!$A$45:$A$47
Name rngTransactionType: Helpers!$A$21:$A$24
Name valAccountStatus: Helpers!$B$147
Name valAccountTypes: Helpers!$B$140
Name valActiveAccounts: Helpers!$B$132
Name valActiveAssets: Helpers!$B$134
Name valActiveGoals: Helpers!$B$133
Name valActiveLiabilities: Helpers!$B$135
Name valCategoryTypes: Helpers!$B$141
Name valCommitmentStatus: Helpers!$B$148
Name valCurrencies: Helpers!$B$143
Name valDestinationTypes: Helpers!$B$144
Name valExpenseCategories: Helpers!$B$130
Name valFrequency: Helpers!$B$138
Name valGoalStatus: Helpers!$B$146
Name valIncomeCategories: Helpers!$B$131
Name valIncomeSources: Helpers!$B$136
Name valPaymentMethods: Helpers!$B$137
Name valPriority: Helpers!$B$139
Name valThemes: Helpers!$B$142
Name valTransactionTypes: Helpers!$B$145
Name rngDestinationType: Helpers!$A$28:$A$34
Name rngOwnershipType: Helpers!$A$81:$A$82
Name rngCommitmentStatus: Helpers!$A$75:$A$77
Name rngLiabilityStatus: Helpers!$A$65:$A$66
Name rngYesNo: Helpers!$A$86:$A$87
Name rngTransactionStatus: Helpers!$D$1:$D$4

Sheet Settings
A1: Setting ID | B1: Setting Name | C1: Setting Value | D1: Setting Category | E1: Description

Sheet Categories
A1: Category ID | B1: Category Name | C1: Category Type | D1: Parent Category | E1: Status | F1: Display Order | G1: Notes
A2: CAT-001 | B2: Salary | C2: Income | E2: Active | F2: 1 | G2: Payroll
A3: CAT-002 | B3: Freelance | C3: Income | E3: Active | F3: 2 | G3: Side work
A4: CAT-003 | B4: Groceries | C4: Expense | E4: Active | F4: 3 | G4: Food
A5: CAT-004 | B5: Rent | C5: Expense | E5: Active | F5: 4 | G5: Housing

Sheet Accounts
A1: Account ID | B1: Account Name | C1: Account Type | D1: Institution | E1: Opening Balance | F1: Current Balance | G1: Currency | H1: Include in Dashboard | I1: Status | J1: Notes
A2: ACC-001 | B2: HDFC Salary | C2: Savings Bank | D2: HDFC | E2: 11999 | F2: =IF(tblAccounts[[#This Row],[Account Name]]="","",INDEX('Business Engine'!$H$2:$H$200,ROW()-ROW(tblAccounts[#Headers]))) | G2: INR | H2: Yes | I2: Active
A3: ACC-002 | B3: SBI Savings | C3: Savings Bank | D3: SBI | E3: 4000 | F3: =IF(tblAccounts[[#This Row],[Account Name]]="","",INDEX('Business Engine'!$H$2:$H$200,ROW()-ROW(tblAccounts[#Headers]))) | G3: INR | H3: Yes | I3: Active
A4: ACC-003 | B4: Cash Wallet | C4: Cash | E4: 10000 | F4: =IF(tblAccounts[[#This Row],[Account Name]]="","",INDEX('Business Engine'!$H$2:$H$200,ROW()-ROW(tblAccounts[#Headers]))) | G4: INR | H4: Yes | I4: Active
A5: ACC-004 | B5: Old SBI | C5: Savings Bank | D5: SBI | E5: 0 | F5: =IF(tblAccounts[[#This Row],[Account Name]]="","",INDEX('Business Engine'!$H$2:$H$200,ROW()-ROW(tblAccounts[#Headers]))) | G5: INR | H5: No | I5: Closed
A6: ACC-005 | B6: Credit Card | C6: Credit Card | D6: HDFC | E6: 0 | F6: =IF(tblAccounts[[#This Row],[Account Name]]="","",INDEX('Business Engine'!$H$2:$H$200,ROW()-ROW(tblAccounts[#Headers]))) | G6: INR | H6: Yes | I6: Active
F7: =IF(tblAccounts[[#This Row],[Account Name]]="","",INDEX('Business Engine'!$H$2:$H$200,ROW()-ROW(tblAccounts[#Headers])))
F8: =IF(tblAccounts[[#This Row],[Account Name]]="","",INDEX('Business Engine'!$H$2:$H$200,ROW()-ROW(tblAccounts[#Headers])))
F9: =IF(tblAccounts[[#This Row],[Account Name]]="","",INDEX('Business Engine'!$H$2:$H$200,ROW()-ROW(tblAccounts[#Headers])))
F10: =IF(tblAccounts[[#This Row],[Account Name]]="","",INDEX('Business Engine'!$H$2:$H$200,ROW()-ROW(tblAccounts[#Headers])))
F11: =IF(tblAccounts[[#This Row],[Account Name]]="","",INDEX('Business Engine'!$H$2:$H$200,ROW()-ROW(tblAccounts[#Headers])))
F12: =IF(tblAccounts[[#This Row],[Account Name]]="","",INDEX('Business Engine'!$H$2:$H$200,ROW()-ROW(tblAccounts[#Headers])))
F13: =IF(tblAccounts[[#This Row],[Account Name]]="","",INDEX('Business Engine'!$H$2:$H$200,ROW()-ROW(tblAccounts[#Headers])))
F14: =IF(tblAccounts[[#This Row],[Account Name]]="","",INDEX('Business Engine'!$H$2:$H$200,ROW()-ROW(tblAccounts[#Headers])))
F15: =IF(tblAccounts[[#This Row],[Account Name]]="","",INDEX('Business Engine'!$H$2:$H$200,ROW()-ROW(tblAccounts[#Headers])))
F16: =IF(tblAccounts[[#This Row],[Account Name]]="","",INDEX('Business Engine'!$H$2:$H$200,ROW()-ROW(tblAccounts[#Headers])))
F17: =IF(tblAccounts[[#This Row],[Account Name]]="","",INDEX('Business Engine'!$H$2:$H$200,ROW()-ROW(tblAccounts[#Headers])))
F18: =IF(tblAccounts[[#This Row],[Account Name]]="","",INDEX('Business Engine'!$H$2:$H$200,ROW()-ROW(tblAccounts[#Headers])))
... F200: =IF(tblAccounts[[#This Row],[Account Name]]="","",INDEX('Business Engine'!$H$2:$H$200,ROW()-ROW(tblAccounts[#Headers])))

Sheet Income Sources
A1: Income Source ID | B1: Income Source Name | C1: Income Category | D1: Default Receiving Account | E1: Status | F1: Notes
A2: INC-001 | B2: Acme Payroll | C2: Salary | D2: HDFC Salary | E2: Active
A3: INC-002 | B3: Design Freelance | C3: Freelance | D3: HDFC Salary | E3: Active
A4: INC-003 | B4: Old Job | C4: Salary | D4: HDFC Salary | E4: Closed

Sheet Assets
A1: Asset ID | B1: Asset Name | C1: Asset Category | D1: Asset Type | E1: Linked Account | F1: Purchase Date | G1: Purchase Value | H1: Current Value | I1: Appreciation Amount | J1: Appreciation % | K1: Ownership Type | L1: Status | M1: Notes
A2: AST-001 | B2: Nifty Index Fund | C2: Investments | D2: Mutual Fund | E2: SBI Savings | F2: 45672 | G2: 100000 | H2: 112000 | I2: =tblAssets[[#This Row],[Current Value]]-tblAssets[[#This Row],[Purchase Value]] | J2: =IFERROR(tblAssets[[#This Row],[Appreciation Amount]]/tblAssets[[#This Row],[Purchase Value]],0) | K2: Individual | L2: Active
A3: AST-002 | B3: Old FD | C3: Investments | D3: Fixed Deposit | E3: SBI Savings | F3: 43983 | G3: 50000 | H3: 50000 | I3: =tblAssets[[#This Row],[Current Value]]-tblAssets[[#This Row],[Purchase Value]] | J3: =IFERROR(tblAssets[[#This Row],[Appreciation Amount]]/tblAssets[[#This Row],[Purchase Value]],0) | K3: Individual | L3: Closed
I4: =tblAssets[[#This Row],[Current Value]]-tblAssets[[#This Row],[Purchase Value]] | J4: =IFERROR(tblAssets[[#This Row],[Appreciation Amount]]/tblAssets[[#This Row],[Purchase Value]],0)
I5: =tblAssets[[#This Row],[Current Value]]-tblAssets[[#This Row],[Purchase Value]] | J5: =IFERROR(tblAssets[[#This Row],[Appreciation Amount]]/tblAssets[[#This Row],[Purchase Value]],0)
I6: =tblAssets[[#This Row],[Current Value]]-tblAssets[[#This Row],[Purchase Value]] | J6: =IFERROR(tblAssets[[#This Row],[Appreciation Amount]]/tblAssets[[#This Row],[Purchase Value]],0)
I7: =tblAssets[[#This Row],[Current Value]]-tblAssets[[#This Row],[Purchase Value]] | J7: =IFERROR(tblAssets[[#This Row],[Appreciation Amount]]/tblAssets[[#This Row],[Purchase Value]],0)
I8: =tblAssets[[#This Row],[Current Value]]-tblAssets[[#This Row],[Purchase Value]] | J8: =IFERROR(tblAssets[[#This Row],[Appreciation Amount]]/tblAssets[[#This Row],[Purchase Value]],0)
I9: =tblAssets[[#This Row],[Current Value]]-tblAssets[[#This Row],[Purchase Value]] | J9: =IFERROR(tblAssets[[#This Row],[Appreciation Amount]]/tblAssets[[#This Row],[Purchase Value]],0)
I10: =tblAssets[[#This Row],[Current Value]]-tblAssets[[#This Row],[Purchase Value]] | J10: =IFERROR(tblAssets[[#This Row],[Appreciation Amount]]/tblAssets[[#This Row],[Purchase Value]],0)
I11: =tblAssets[[#This Row],[Current Value]]-tblAssets[[#This Row],[Purchase Value]] | J11: =IFERROR(tblAssets[[#This Row],[Appreciation Amount]]/tblAssets[[#This Row],[Purchase Value]],0)
I12: =tblAssets[[#This Row],[Current Value]]-tblAssets[[#This Row],[Purchase Value]] | J12: =IFERROR(tblAssets[[#This Row],[Appreciation Amount]]/tblAssets[[#This Row],[Purchase Value]],0)
I13: =tblAssets[[#This Row],[Current Value]]-tblAssets[[#This Row],[Purchase Value]] | J13: =IFERROR(tblAssets[[#This Row],[Appreciation Amount]]/tblAssets[[#This Row],[Purchase Value]],0)
I14: =tblAssets[[#This Row],[Current Value]]-tblAssets[[#This Row],[Purchase Value]] | J14: =IFERROR(tblAssets[[#This Row],[Appreciation Amount]]/tblAssets[[#This Row],[Purchase Value]],0)
I15: =tblAssets[[#This Row],[Current Value]]-tblAssets[[#This Row],[Purchase Value]] | J15: =IFERROR(tblAssets[[#This Row],[Appreciation Amount]]/tblAssets[[#This Row],[Purchase Value]],0)
... I200: =tblAssets[[#This Row],[Current Value]]-tblAssets[[#This Row],[Purchase Value]] | J200: =IFERROR(tblAssets[[#This Row],[Appreciation Amount]]/tblAssets[[#This Row],[Purchase Value]],0)

Sheet Liabilities
A1: Liability ID | B1: Liability Name | C1: Liability Type | D1: Institution | E1: Original Amount | F1: Outstanding Balance | G1: Interest Rate | H1: EMI Amount | I1: EMI Frequency | J1: EMI Due Day | K1: Start Date | L1: End Date | M1: Linked Payment Account | N1: Auto EMI | O1: Status | P1: Notes
A2: LIA-001 | B2: HDFC Home Loan | C2: Home Loan | D2: HDFC | E2: 2500000 | F2: 2100000 | G2: 0.085 | H2: 22000 | I2: Monthly | J2: 5 | K2: 44656 | L2: 51961 | M2: HDFC Salary | N2: Yes | O2: Active
A3: LIA-002 | B3: Old Personal Loan | C3: Personal Loan | D3: HDFC | E3: 100000 | F3: 0 | G3: 0 | H3: 0 | I3: Monthly | O3: Closed

Sheet Recurring Commitments
A1: Commitment ID | B1: Commitment Name | C1: Commitment Type | D1: Linked Liability ID | E1: Linked Goal ID | F1: Payment Account | G1: Amount | H1: Frequency | I1: Due Day | J1: Start Date | K1: End Date | L1: Auto Generate | M1: Status | N1: Notes

Sheet Transactions
A1: Transaction ID | B1: Transaction Date | C1: Transaction Type | D1: Source Account | E1: Destination Type | F1: Destination Name | G1: Category | H1: Income Source | I1: Amount | J1: Payment Method | K1: Transaction Status | L1: Notes | M1: Created Timestamp
A2: TXN-001 | B2: 46053 | C2: Income | D2: HDFC Salary | E2: Account | F2: HDFC Salary | G2: Salary | H2: Acme Payroll | I2: 89000 | J2: Bank Transfer | K2: Completed
A3: TXN-002 | B3: 46266 | C3: Income | D3: HDFC Salary | E3: Account | F3: HDFC Salary | G3: Salary | H3: Acme Payroll | I3: 85000 | J3: Bank Transfer | K3: Completed
A4: TXN-003 | B4: 46275 | C4: Income | D4: HDFC Salary | E4: Account | F4: HDFC Salary | G4: Freelance | H4: Design Freelance | I4: 15000 | J4: UPI | K4: Completed
A5: TXN-004 | B5: 46032 | C5: Expense | D5: HDFC Salary | E5: Expense Category | F5: Cash Wallet | G5: Groceries | I5: 3600 | J5: UPI | K5: Completed
A6: TXN-005 | B6: 46252 | C6: Expense | D6: HDFC Salary | E6: Expense Category | F6: Cash Wallet | G6: Groceries | I6: 8000 | J6: UPI | K6: Completed
A7: TXN-006 | B7: 46270 | C7: Expense | D7: HDFC Salary | E7: Expense Category | F7: Cash Wallet | G7: Groceries | I7: 4400 | J7: UPI | K7: Completed
A8: TXN-007 | B8: 46273 | C8: Expense | D8: HDFC Salary | E8: Expense Category | F8: Cash Wallet | G8: Rent | I8: 20000 | J8: Bank Transfer | K8: Completed
A9: TXN-008 | B9: 46285 | C9: Expense | D9: HDFC Salary | E9: Expense Category | F9: Cash Wallet | G9: Groceries | I9: 1000 | J9: UPI | K9: Completed
A10: TXN-009 | B10: 46296 | C10: Expense | D10: HDFC Salary | E10: Expense Category | F10: Cash Wallet | G10: Rent | I10: 9999 | J10: UPI | K10: Completed
A11: TXN-010 | B11: 46267 | C11: Transfer | D11: HDFC Salary | E11: Account | F11: SBI Savings | G11: Groceries | I11: 5000 | J11: Bank Transfer | K11: Completed

Sheet Goals
A1: Goal ID | B1: Goal Name | C1: Goal Category | D1: Goal Account | E1: Target Amount | F1: Current Saved Amount | G1: Remaining Amount | H1: Monthly Contribution Target | I1: Target Date | J1: Priority | K1: Goal Status | L1: Notes
A2: GOL-001 | B2: Emergency Fund | C2: Groceries | D2: SBI Savings | E2: 300000 | F2: 50000 | G2: =MAX(0,tblGoals[[#This Row],[Target Amount]]-tblGoals[[#This Row],[Current Saved Amount]]) | H2: 15000 | I2: 46752 | J2: High | K2: Active
A3: GOL-002 | B3: Goa Vacation | C3: Rent | D3: HDFC Salary | E3: 80000 | F3: 80000 | G3: =MAX(0,tblGoals[[#This Row],[Target Amount]]-tblGoals[[#This Row],[Current Saved Amount]]) | H3: 0 | I3: 46143 | J3: Medium | K3: Completed
A4: GOL-003 | B4: Bike Down Payment | C4: Groceries | D4: HDFC Salary | E4: 150000 | F4: 20000 | G4: =MAX(0,tblGoals[[#This Row],[Target Amount]]-tblGoals[[#This Row],[Current Saved Amount]]) | H4: 5000 | I4: 46934 | J4: Low | K4: Paused
G5: =MAX(0,tblGoals[[#This Row],[Target Amount]]-tblGoals[[#This Row],[Current Saved Amount]])
G6: =MAX(0,tblGoals[[#This Row],[Target Amount]]-tblGoals[[#This Row],[Current Saved Amount]])
G7: =MAX(0,tblGoals[[#This Row],[Target Amount]]-tblGoals[[#This Row],[Current Saved Amount]])
G8: =MAX(0,tblGoals[[#This Row],[Target Amount]]-tblGoals[[#This Row],[Current Saved Amount]])
G9: =MAX(0,tblGoals[[#This Row],[Target Amount]]-tblGoals[[#This Row],[Current Saved Amount]])
G10: =MAX(0,tblGoals[[#This Row],[Target Amount]]-tblGoals[[#This Row],[Current Saved Amount]])
G11: =MAX(0,tblGoals[[#This Row],[Target Amount]]-tblGoals[[#This Row],[Current Saved Amount]])
G12: =MAX(0,tblGoals[[#This Row],[Target Amount]]-tblGoals[[#This Row],[Current Saved Amount]])
G13: =MAX(0,tblGoals[[#This Row],[Target Amount]]-tblGoals[[#This Row],[Current Saved Amount]])
G14: =MAX(0,tblGoals[[#This Row],[Target Amount]]-tblGoals[[#This Row],[Current Saved Amount]])
G15: =MAX(0,tblGoals[[#This Row],[Target Amount]]-tblGoals[[#This Row],[Current Saved Amount]])
G16: =MAX(0,tblGoals[[#This Row],[Target Amount]]-tblGoals[[#This Row],[Current Saved Amount]])
... G200: =MAX(0,tblGoals[[#This Row],[Target Amount]]-tblGoals[[#This Row],[Current Saved Amount]])

Sheet Helpers
A1: Currency Code | B1: Currency Name | C1: Symbol | D1: Completed | AG1: Asset Type | AH1: Liability Type | AI1: Income Type
A2: INR | D2: Pending | AG2: Mutual Fund | AH2: Home Loan | AI2: Salary
A3: USD | D3: Cancelled | AG3: Stock | AH3: Personal Loan | AI3: Freelance
A4: EUR | D4: Reconciled | AG4: ETF | AH4: Education Loan | AI4: Bonus
A5: GBP | AG5: Gold ETF | AH5: Vehicle Loan | AI5: Rental Income
A6: AED | AG6: Bond | AH6: Gold Loan | AI6: Interest
AG7: SIP | AH7: Credit Card | AI7: Cashback
AG8: Fixed Deposit | AH8: Buy Now Pay Later | AI8: Refund
A9: Payment Method | AG9: PPF | AH9: Family Loan | AI9: Business Income
A10: Bank Transfer | AG10: EPF | AH10: Business Loan | AI10: Investment
A11: Cash | AG11: NPS | AH11: Other Liability
A12: UPI | AG12: Gold Jewellery
A13: Debit Card | AG13: Gold Coin
A14: Credit Card | AG14: Vehicle
A15: Wallet | AG15: Electronics
A16: Net Banking | AG16: Furniture
A17: Other | AG17: Watch
AG18: Other Physical Asset
AG19: Residential Property
A20: Transaction Type | AG20: Commercial Property
A21: Income | AG21: Land
A22: Expense | AG22: Plot
A23: Transfer | AG23: Emergency Cash
A24: Adjustment | AG24: Foreign Currency
AG25: Cash Reserve
A27: Destination Type
A28: Expense Category
A29: Income Category
A30: Account
A31: Goal
A32: Liability
A33: Asset
A34: Other
A37: Frequency
A38: Monthly
A39: Quarterly
A40: Half-Yearly
... A107: FinanceOS Default
A110: Month Number | B110: Month Name | C110: Short Name
A111: 1 | B111: January | C111: Jan
...

Sheet Business Engine
A1: As-Of Date | B1: 46277 | D1: Account Name | E1: Opening Balance | F1: Money In | G1: Money Out | H1: Current Balance | I1: Last Transaction Date | J1: Account Type | K1: Dashboard Enabled | L1: Status
D2: =IFERROR(IF(INDEX(tblAccounts[Account Name],ROW()-1)="","",INDEX(tblAccounts[Account Name],ROW()-1)),"") | E2: =IF($D2="","",IFERROR(INDEX(tblAccounts[Opening Balance],ROW()-1),0)) | F2: =IF($D2="","",IFERROR(SUMIFS(tblTransactions[Amount],tblTransactions[Transaction Type],"Income",tblTransactions[Source Account],$D2,tblTransactions[Transaction Status],"Completed")+SUMIFS(tblTransactions[Amount],tblTransactions[Transaction Type],"Income",tblTransactions[Source Account],$D2,tblTransactions[Transaction Status],"Reconciled")+SUMIFS(tblTransactions[Amount],tblTransactions[Transaction Type],"Transfer",tblTransactions[Destination Type],"Account",tblTransactions[Destination Name],$D2,tblTransactions[Transaction Status],"Completed")+SUMIFS(tblTransactions[Amount],tblTransactions[Transaction Type],"Transfer",tblTransactions[Destination Type],"Account",tblTransactions[Destination Name],$D2,tblTransactions[Transaction Status],"Reconciled")+SUMIFS(tblTransactions[Amount],tblTransactions[Transaction Type],"Adjustment",tblTransactions[Source Account],$D2,tblTransactions[Transaction Status],"Completed",tblTransactions[Amount],">0")+SUMIFS(tblTransactions[Amount],tblTransactions[Transaction Type],"Adjustment",tblTransactions[Source Account],$D2,tblTransactions[Transaction Status],"Reconciled",tblTransactions[Amount],">0"),0)) | G2: =IF($D2="","",IFERROR(SUMIFS(tblTransactions[Amount],tblTransactions[Transaction Type],"Expense",tblTransactions[Source Account],$D2,tblTransactions[Transaction Status],"Completed")+SUMIFS(tblTransactions[Amount],tblTransactions[Transaction Type],"Expense",tblTransactions[Source Account],$D2,tblTransactions[Transaction Status],"Reconciled")+SUMIFS(tblTransactions[Amount],tblTransactions[Transaction Type],"Transfer",tblTransactions[Source Account],$D2,tblTransactions[Transaction Status],"Completed")+SUMIFS(tblTransactions[Amount],tblTransactions[Transaction Type],"Transfer",tblTransactions[Source Account],$D2,tblTransactions[Transaction Status],"Reconciled")-SUMIFS(tblTransactions[Amount],tblTransactions[Transaction Type],"Adjustment",tblTransactions[Source Account],$D2,tblTransactions[Transaction Status],"Completed",tblTransactions[Amount],"<0")-SUMIFS(tblTransactions[Amount],tblTransactions[Transaction Type],"Adjustment",tblTransactions[Source Account],$D2,tblTransactions[Transaction Status],"Reconciled",tblTransactions[Amount],"<0"),0)) | H2: =IF($D2="","",$E2+$F2-$G2) | I2: =IF($D2="","",IFERROR(1/(1/AGGREGATE(14,6,tblTransactions[Transaction Date]/(((tblTransactions[Source Account]=$D2)+((tblTransactions[Transaction Type]="Transfer")*(tblTransactions[Destination Type]="Account")*(tblTransactions[Destination Name]=$D2)))*((tblTransactions[Transaction Status]="Completed")+(tblTransactions[Transaction Status]="Reconciled"))),1)),"")) | J2: =IF($D2="","",IFERROR(INDEX(tblAccounts[Account Type],ROW()-1),"")) | K2: =IF($D2="","",IFERROR(INDEX(tblAccounts[Include in Dashboard],ROW()-1),"")) | L2: =IF($D2="","",IFERROR(INDEX(tblAccounts[Status],ROW()-1),""))
A3: SECTION 1 — Accounts Summary | D3: =IFERROR(IF(INDEX(tblAccounts[Account Name],ROW()-1)="","",INDEX(tblAccounts[Account Name],ROW()-1)),"") | E3: =IF($D3="","",IFERROR(INDEX(tblAccounts[Opening Balance],ROW()-1),0)) | F3: =IF($D3="","",IFERROR(SUMIFS(tblTransactions[Amount],tblTransactions[Transaction Type],"Income",tblTransactions[Source Account],$D3,tblTransactions[Transaction Status],"Completed")+SUMIFS(tblTransactions[Amount],tblTransactions[Transaction Type],"Income",tblTransactions[Source Account],$D3,tblTransactions[Transaction Status],"Reconciled")+SUMIFS(tblTransactions[Amount],tblTransactions[Transaction Type],"Transfer",tblTransactions[Destination Type],"Account",tblTransactions[Destination Name],$D3,tblTransactions[Transaction Status],"Completed")+SUMIFS(tblTransactions[Amount],tblTransactions[Transaction Type],"Transfer",tblTransactions[Destination Type],"Account",tblTransactions[Destination Name],$D3,tblTransactions[Transaction Status],"Reconciled")+SUMIFS(tblTransactions[Amount],tblTransactions[Transaction Type],"Adjustment",tblTransactions[Source Account],$D3,tblTransactions[Transaction Status],"Completed",tblTransactions[Amount],">0")+SUMIFS(tblTransactions[Amount],tblTransactions[Transaction Type],"Adjustment",tblTransactions[Source Account],$D3,tblTransactions[Transaction Status],"Reconciled",tblTransactions[Amount],">0"),0)) | G3: =IF($D3="","",IFERROR(SUMIFS(tblTransactions[Amount],tblTransactions[Transaction Type],"Expense",tblTransactions[Source Account],$D3,tblTransactions[Transaction Status],"Completed")+SUMIFS(tblTransactions[Amount],tblTransactions[Transaction Type],"Expense",tblTransactions[Source Account],$D3,tblTransactions[Transaction Status],"Reconciled")+SUMIFS(tblTransactions[Amount],tblTransactions[Transaction Type],"Transfer",tblTransactions[Source Account],$D3,tblTransactions[Transaction Status],"Completed")+SUMIFS(tblTransactions[Amount],tblTransactions[Transaction Type],"Transfer",tblTransactions[Source Account],$D3,tblTransactions[Transaction Status],"Reconciled")-SUMIFS(tblTransactions[Amount],tblTransactions[Transaction Type],"Adjustment",tblTransactions[Source Account],$D3,tblTransactions[Transaction Status],"Completed",tblTransactions[Amount],"<0")-SUMIFS(tblTransactions[Amount],tblTransactions[Transaction Type],"Adjustment",tblTransactions[Source Account],$D3,tblTransactions[Transaction Status],"Reconciled",tblTransactions[Amount],"<0"),0)) | H3: =IF($D3="","",$E3+$F3-$G3) | I3: =IF($D3="","",IFERROR(1/(1/AGGREGATE(14,6,tblTransactions[Transaction Date]/(((tblTransactions[Source Account]=$D3)+((tblTransactions[Transaction Type]="Transfer")*(tblTransactions[Destination Type]="Account")*(tblTransactions[Destination Name]=$D3)))*((tblTransactions[Transaction Status]="Completed")+(tblTransactions[Transaction Status]="Reconciled"))),1)),"")) | J3: =IF($D3="","",IFERROR(INDEX(tblAccounts[Account Type],ROW()-1),"")) | K3: =IF($D3="","",IFERROR(INDEX(tblAccounts[Include in Dashboard],ROW()-1),"")) | L3: =IF($D3="","",IFERROR(INDEX(tblAccounts[Status],ROW()-1),""))
A4: Total Active Account Balance | B4: =IFERROR(SUMIFS($H$2:$H$200,$L$2:$L$200,"Active",$K$2:$K$200,"Yes"),0) | D4: =IFERROR(IF(INDEX(tblAccounts[Account Name],ROW()-1)="","",INDEX(tblAccounts[Account Name],ROW()-1)),"") | E4: =IF($D4="","",IFERROR(INDEX(tblAccounts[Opening Balance],ROW()-1),0)) | F4: =IF($D4="","",IFERROR(SUMIFS(tblTransactions[Amount],tblTransactions[Transaction Type],"Income",tblTransactions[Source Account],$D4,tblTransactions[Transaction Status],"Completed")+SUMIFS(tblTransactions[Amount],tblTransactions[Transaction Type],"Income",tblTransactions[Source Account],$D4,tblTransactions[Transaction Status],"Reconciled")+SUMIFS(tblTransactions[Amount],tblTransactions[Transaction Type],"Transfer",tblTransactions[Destination Type],"Account",tblTransactions[Destination Name],$D4,tblTransactions[Transaction Status],"Completed")+SUMIFS(tblTransactions[Amount],tblTransactions[Transaction Type],"Transfer",tblTransactions[Destination Type],"Account",tblTransactions[Destination Name],$D4,tblTransactions[Transaction Status],"Reconciled")+SUMIFS(tblTransactions[Amount],tblTransactions[Transaction Type],"Adjustment",tblTransactions[Source Account],$D4,tblTransactions[Transaction Status],"Completed",tblTransactions[Amount],">0")+SUMIFS(tblTransactions[Amount],tblTransactions[Transaction Type],"Adjustment",tblTransactions[Source Account],$D4,tblTransactions[Transaction Status],"Reconciled",tblTransactions[Amount],">0"),0)) | G4: =IF($D4="","",IFERROR(SUMIFS(tblTransactions[Amount],tblTransactions[Transaction Type],"Expense",tblTransactions[Source Account],$D4,tblTransactions[Transaction Status],"Completed")+SUMIFS(tblTransactions[Amount],tblTransactions[Transaction Type],"Expense",tblTransactions[Source Account],$D4,tblTransactions[Transaction Status],"Reconciled")+SUMIFS(tblTransactions[Amount],tblTransactions[Transaction Type],"Transfer",tblTransactions[Source Account],$D4,tblTransactions[Transaction Status],"Completed")+SUMIFS(tblTransactions[Amount],tblTransactions[Transaction Type],"Transfer",tblTransactions[Source Account],$D4,tblTransactions[Transaction Status],"Reconciled")-SUMIFS(tblTransactions[Amount],tblTransactions[Transaction Type],"Adjustment",tblTransactions[Source Account],$D4,tblTransactions[Transaction Status],"Completed",tblTransactions[Amount],"<0")-SUMIFS(tblTransactions[Amount],tblTransactions[Transaction Type],"Adjustment",tblTransactions[Source Account],$D4,tblTransactions[Transaction Status],"Reconciled",tblTransactions[Amount],"<0"),0)) | H4: =IF($D4="","",$E4+$F4-$G4) | I4: =IF($D4="","",IFERROR(1/(1/AGGREGATE(14,6,tblTransactions[Transaction Date]/(((tblTransactions[Source Account]=$D4)+((tblTransactions[Transaction Type]="Transfer")*(tblTransactions[Destination Type]="Account")*(tblTransactions[Destination Name]=$D4)))*((tblTransactions[Transaction Status]="Completed")+(tblTransactions[Transaction Status]="Reconciled"))),1)),"")) | J4: =IF($D4="","",IFERROR(INDEX(tblAccounts[Account Type],ROW()-1),"")) | K4: =IF($D4="","",IFERROR(INDEX(tblAccounts[Include in Dashboard],ROW()-1),"")) | L4: =IF($D4="","",IFERROR(INDEX(tblAccounts[Status],ROW()-1),""))
A5: Number of Active Accounts | B5: =COUNTIFS($D$2:$D$200,"<>",$L$2:$L$200,"Active",$K$2:$K$200,"Yes") | D5: =IFERROR(IF(INDEX(tblAccounts[Account Name],ROW()-1)="","",INDEX(tblAccounts[Account Name],ROW()-1)),"") | E5: =IF($D5="","",IFERROR(INDEX(tblAccounts[Opening Balance],ROW()-1),0)) | F5: =IF($D5="","",IFERROR(SUMIFS(tblTransactions[Amount],tblTransactions[Transaction Type],"Income",tblTransactions[Source Account],$D5,tblTransactions[Transaction Status],"Completed")+SUMIFS(tblTransactions[Amount],tblTransactions[Transaction Type],"Income",tblTransactions[Source Account],$D5,tblTransactions[Transaction Status],"Reconciled")+SUMIFS(tblTransactions[Amount],tblTransactions[Transaction Type],"Transfer",tblTransactions[Destination Type],"Account",tblTransactions[Destination Name],$D5,tblTransactions[Transaction Status],"Completed")+SUMIFS(tblTransactions[Amount],tblTransactions[Transaction Type],"Transfer",tblTransactions[Destination Type],"Account",tblTransactions[Destination Name],$D5,tblTransactions[Transaction Status],"Reconciled")+SUMIFS(tblTransactions[Amount],tblTransactions[Transaction Type],"Adjustment",tblTransactions[Source Account],$D5,tblTransactions[Transaction Status],"Completed",tblTransactions[Amount],">0")+SUMIFS(tblTransactions[Amount],tblTransactions[Transaction Type],"Adjustment",tblTransactions[Source Account],$D5,tblTransactions[Transaction Status],"Reconciled",tblTransactions[Amount],">0"),0)) | G5: =IF($D5="","",IFERROR(SUMIFS(tblTransactions[Amount],tblTransactions[Transaction Type],"Expense",tblTransactions[Source Account],$D5,tblTransactions[Transaction Status],"Completed")+SUMIFS(tblTransactions[Amount],tblTransactions[Transaction Type],"Expense",tblTransactions[Source Account],$D5,tblTransactions[Transaction Status],"Reconciled")+SUMIFS(tblTransactions[Amount],tblTransactions[Transaction Type],"Transfer",tblTransactions[Source Account],$D5,tblTransactions[Transaction Status],"Completed")+SUMIFS(tblTransactions[Amount],tblTransactions[Transaction Type],"Transfer",tblTransactions[Source Account],$D5,tblTransactions[Transaction Status],"Reconciled")-SUMIFS(tblTransactions[Amount],tblTransactions[Transaction Type],"Adjustment",tblTransactions[Source Account],$D5,tblTransactions[Transaction Status],"Completed",tblTransactions[Amount],"<0")-SUMIFS(tblTransactions[Amount],tblTransactions[Transaction Type],"Adjustment",tblTransactions[Source Account],$D5,tblTransactions[Transaction Status],"Reconciled",tblTransactions[Amount],"<0"),0)) | H5: =IF($D5="","",$E5+$F5-$G5) | I5: =IF($D5="","",IFERROR(1/(1/AGGREGATE(14,6,tblTransactions[Transaction Date]/(((tblTransactions[Source Account]=$D5)+((tblTransactions[Transaction Type]="Transfer")*(tblTransactions[Destination Type]="Account")*(tblTransactions[Destination Name]=$D5)))*((tblTransactions[Transaction Status]="Completed")+(tblTransactions[Transaction Status]="Reconciled"))),1)),"")) | J5: =IF($D5="","",IFERROR(INDEX(tblAccounts[Account Type],ROW()-1),"")) | K5: =IF($D5="","",IFERROR(INDEX(tblAccounts[Include in Dashboard],ROW()-1),"")) | L5: =IF($D5="","",IFERROR(INDEX(tblAccounts[Status],ROW()-1),""))
A6: Cash Accounts Total | B6: =IFERROR(SUMIFS($H$2:$H$200,$J$2:$J$200,"Cash",$L$2:$L$200,"Active",$K$2:$K$200,"Yes"),0) | D6: =IFERROR(IF(INDEX(tblAccounts[Account Name],ROW()-1)="","",INDEX(tblAccounts[Account Name],ROW()-1)),"") | E6: =IF($D6="","",IFERROR(INDEX(tblAccounts[Opening Balance],ROW()-1),0)) | F6: =IF($D6="","",IFERROR(SUMIFS(tblTransactions[Amount],tblTransactions[Transaction Type],"Income",tblTransactions[Source Account],$D6,tblTransactions[Transaction Status],"Completed")+SUMIFS(tblTransactions[Amount],tblTransactions[Transaction Type],"Income",tblTransactions[Source Account],$D6,tblTransactions[Transaction Status],"Reconciled")+SUMIFS(tblTransactions[Amount],tblTransactions[Transaction Type],"Transfer",tblTransactions[Destination Type],"Account",tblTransactions[Destination Name],$D6,tblTransactions[Transaction Status],"Completed")+SUMIFS(tblTransactions[Amount],tblTransactions[Transaction Type],"Transfer",tblTransactions[Destination Type],"Account",tblTransactions[Destination Name],$D6,tblTransactions[Transaction Status],"Reconciled")+SUMIFS(tblTransactions[Amount],tblTransactions[Transaction Type],"Adjustment",tblTransactions[Source Account],$D6,tblTransactions[Transaction Status],"Completed",tblTransactions[Amount],">0")+SUMIFS(tblTransactions[Amount],tblTransactions[Transaction Type],"Adjustment",tblTransactions[Source Account],$D6,tblTransactions[Transaction Status],"Reconciled",tblTransactions[Amount],">0"),0)) | G6: =IF($D6="","",IFERROR(SUMIFS(tblTransactions[Amount],tblTransactions[Transaction Type],"Expense",tblTransactions[Source Account],$D6,tblTransactions[Transaction Status],"Completed")+SUMIFS(tblTransactions[Amount],tblTransactions[Transaction Type],"Expense",tblTransactions[Source Account],$D6,tblTransactions[Transaction Status],"Reconciled")+SUMIFS(tblTransactions[Amount],tblTransactions[Transaction Type],"Transfer",tblTransactions[Source Account],$D6,tblTransactions[Transaction Status],"Completed")+SUMIFS(tblTransactions[Amount],tblTransactions[Transaction Type],"Transfer",tblTransactions[Source Account],$D6,tblTransactions[Transaction Status],"Reconciled")-SUMIFS(tblTransactions[Amount],tblTransactions[Transaction Type],"Adjustment",tblTransactions[Source Account],$D6,tblTransactions[Transaction Status],"Completed",tblTransactions[Amount],"<0")-SUMIFS(tblTransactions[Amount],tblTransactions[Transaction Type],"Adjustment",tblTransactions[Source Account],$D6,tblTransactions[Transaction Status],"Reconciled",tblTransactions[Amount],"<0"),0)) | H6: =IF($D6="","",$E6+$F6-$G6) | I6: =IF($D6="","",IFERROR(1/(1/AGGREGATE(14,6,tblTransactions[Transaction Date]/(((tblTransactions[Source Account]=$D6)+((tblTransactions[Transaction Type]="Transfer")*(tblTransactions[Destination Type]="Account")*(tblTransactions[Destination Name]=$D6)))*((tblTransactions[Transaction Status]="Completed")+(tblTransactions[Transaction Status]="Reconciled"))),1)),"")) | J6: =IF($D6="","",IFERROR(INDEX(tblAccounts[Account Type],ROW()-1),"")) | K6: =IF($D6="","",IFERROR(INDEX(tblAccounts[Include in Dashboard],ROW()-1),"")) | L6: =IF($D6="","",IFERROR(INDEX(tblAccounts[Status],ROW()-1),""))
A7: Savings Accounts Total | B7: =IFERROR(SUMIFS($H$2:$H$200,$J$2:$J$200,"Savings Bank",$L$2:$L$200,"Active",$K$2:$K$200,"Yes"),0) | D7: =IFERROR(IF(INDEX(tblAccounts[Account Name],ROW()-1)="","",INDEX(tblAccounts[Account Name],ROW()-1)),"") | E7: =IF($D7="","",IFERROR(INDEX(tblAccounts[Opening Balance],ROW()-1),0)) | F7: =IF($D7="","",IFERROR(SUMIFS(tblTransactions[Amount],tblTransactions[Transaction Type],"Income",tblTransactions[Source Account],$D7,tblTransactions[Transaction Status],"Completed")+SUMIFS(tblTransactions[Amount],tblTransactions[Transaction Type],"Income",tblTransactions[Source Account],$D7,tblTransactions[Transaction Status],"Reconciled")+SUMIFS(tblTransactions[Amount],tblTransactions[Transaction Type],"Transfer",tblTransactions[Destination Type],"Account",tblTransactions[Destination Name],$D7,tblTransactions[Transaction Status],"Completed")+SUMIFS(tblTransactions[Amount],tblTransactions[Transaction Type],"Transfer",tblTransactions[Destination Type],"Account",tblTransactions[Destination Name],$D7,tblTransactions[Transaction Status],"Reconciled")+SUMIFS(tblTransactions[Amount],tblTransactions[Transaction Type],"Adjustment",tblTransactions[Source Account],$D7,tblTransactions[Transaction Status],"Completed",tblTransactions[Amount],">0")+SUMIFS(tblTransactions[Amount],tblTransactions[Transaction Type],"Adjustment",tblTransactions[Source Account],$D7,tblTransactions[Transaction Status],"Reconciled",tblTransactions[Amount],">0"),0)) | G7: =IF($D7="","",IFERROR(SUMIFS(tblTransactions[Amount],tblTransactions[Transaction Type],"Expense",tblTransactions[Source Account],$D7,tblTransactions[Transaction Status],"Completed")+SUMIFS(tblTransactions[Amount],tblTransactions[Transaction Type],"Expense",tblTransactions[Source Account],$D7,tblTransactions[Transaction Status],"Reconciled")+SUMIFS(tblTransactions[Amount],tblTransactions[Transaction Type],"Transfer",tblTransactions[Source Account],$D7,tblTransactions[Transaction Status],"Completed")+SUMIFS(tblTransactions[Amount],tblTransactions[Transaction Type],"Transfer",tblTransactions[Source Account],$D7,tblTransactions[Transaction Status],"Reconciled")-SUMIFS(tblTransactions[Amount],tblTransactions[Transaction Type],"Adjustment",tblTransactions[Source Account],$D7,tblTransactions[Transaction Status],"Completed",tblTransactions[Amount],"<0")-SUMIFS(tblTransactions[Amount],tblTransactions[Transaction Type],"Adjustment",tblTransactions[Source Account],$D7,tblTransactions[Transaction Status],"Reconciled",tblTransactions[Amount],"<0"),0)) | H7: =IF($D7="","",$E7+$F7-$G7) | I7: =IF($D7="","",IFERROR(1/(1/AGGREGATE(14,6,tblTransactions[Transaction Date]/(((tblTransactions[Source Account]=$D7)+((tblTransactions[Transaction Type]="Transfer")*(tblTransactions[Destination Type]="Account")*(tblTransactions[Destination Name]=$D7)))*((tblTransactions[Transaction Status]="Completed")+(tblTransactions[Transaction Status]="Reconciled"))),1)),"")) | J7: =IF($D7="","",IFERROR(INDEX(tblAccounts[Account Type],ROW()-1),"")) | K7: =IF($D7="","",IFERROR(INDEX(tblAccounts[Include in Dashboard],ROW()-1),"")) | L7: =IF($D7="","",IFERROR(INDEX(tblAccounts[Status],ROW()-1),""))
A8: Investment Accounts Total | B8: =IFERROR(SUMIFS($H$2:$H$200,$J$2:$J$200,"Investment Account",$L$2:$L$200,"Active",$K$2:$K$200,"Yes"),0) | D8: =IFERROR(IF(INDEX(tblAccounts[Account Name],ROW()-1)="","",INDEX(tblAccounts[Account Name],ROW()-1)),"") | E8: =IF($D8="","",IFERROR(INDEX(tblAccounts[Opening Balance],ROW()-1),0)) | F8: =IF($D8="","",IFERROR(SUMIFS(tblTransactions[Amount],tblTransactions[Transaction Type],"Income",tblTransactions[Source Account],$D8,tblTransactions[Transaction Status],"Completed")+SUMIFS(tblTransactions[Amount],tblTransactions[Transaction Type],"Income",tblTransactions[Source Account],$D8,tblTransactions[Transaction Status],"Reconciled")+SUMIFS(tblTransactions[Amount],tblTransactions[Transaction Type],"Transfer",tblTransactions[Destination Type],"Account",tblTransactions[Destination Name],$D8,tblTransactions[Transaction Status],"Completed")+SUMIFS(tblTransactions[Amount],tblTransactions[Transaction Type],"Transfer",tblTransactions[Destination Type],"Account",tblTransactions[Destination Name],$D8,tblTransactions[Transaction Status],"Reconciled")+SUMIFS(tblTransactions[Amount],tblTransactions[Transaction Type],"Adjustment",tblTransactions[Source Account],$D8,tblTransactions[Transaction Status],"Completed",tblTransactions[Amount],">0")+SUMIFS(tblTransactions[Amount],tblTransactions[Transaction Type],"Adjustment",tblTransactions[Source Account],$D8,tblTransactions[Transaction Status],"Reconciled",tblTransactions[Amount],">0"),0)) | G8: =IF($D8="","",IFERROR(SUMIFS(tblTransactions[Amount],tblTransactions[Transaction Type],"Expense",tblTransactions[Source Account],$D8,tblTransactions[Transaction Status],"Completed")+SUMIFS(tblTransactions[Amount],tblTransactions[Transaction Type],"Expense",tblTransactions[Source Account],$D8,tblTransactions[Transaction Status],"Reconciled")+SUMIFS(tblTransactions[Amount],tblTransactions[Transaction Type],"Transfer",tblTransactions[Source Account],$D8,tblTransactions[Transaction Status],"Completed")+SUMIFS(tblTransactions[Amount],tblTransactions[Transaction Type],"Transfer",tblTransactions[Source Account],$D8,tblTransactions[Transaction Status],"Reconciled")-SUMIFS(tblTransactions[Amount],tblTransactions[Transaction Type],"Adjustment",tblTransactions[Source Account],$D8,tblTransactions[Transaction Status],"Completed",tblTransactions[Amount],"<0")-SUMIFS(tblTransactions[Amount],tblTransactions[Transaction Type],"Adjustment",tblTransactions[Source Account],$D8,tblTransactions[Transaction Status],"Reconciled",tblTransactions[Amount],"<0"),0)) | H8: =IF($D8="","",$E8+$F8-$G8) | I8: =IF($D8="","",IFERROR(1/(1/AGGREGATE(14,6,tblTransactions[Transaction Date]/(((tblTransactions[Source Account]=$D8)+((tblTransactions[Transaction Type]="Transfer")*(tblTransactions[Destination Type]="Account")*(tblTransactions[Destination Name]=$D8)))*((tblTransactions[Transaction Status]="Completed")+(tblTransactions[Transaction Status]="Reconciled"))),1)),"")) | J8: =IF($D8="","",IFERROR(INDEX(tblAccounts[Account Type],ROW()-1),"")) | K8: =IF($D8="","",IFERROR(INDEX(tblAccounts[Include in Dashboard],ROW()-1),"")) | L8: =IF($D8="","",IFERROR(INDEX(tblAccounts[Status],ROW()-1),""))
A9: Credit Accounts Total | B9: =IFERROR(SUMIFS($H$2:$H$200,$J$2:$J$200,"Credit Card",$L$2:$L$200,"Active",$K$2:$K$200,"Yes"),0) | D9: =IFERROR(IF(INDEX(tblAccounts[Account Name],ROW()-1)="","",INDEX(tblAccounts[Account Name],ROW()-1)),"") | E9: =IF($D9="","",IFERROR(INDEX(tblAccounts[Opening Balance],ROW()-1),0)) | F9: =IF($D9="","",IFERROR(SUMIFS(tblTransactions[Amount],tblTransactions[Transaction Type],"Income",tblTransactions[Source Account],$D9,tblTransactions[Transaction Status],"Completed")+SUMIFS(tblTransactions[Amount],tblTransactions[Transaction Type],"Income",tblTransactions[Source Account],$D9,tblTransactions[Transaction Status],"Reconciled")+SUMIFS(tblTransactions[Amount],tblTransactions[Transaction Type],"Transfer",tblTransactions[Destination Type],"Account",tblTransactions[Destination Name],$D9,tblTransactions[Transaction Status],"Completed")+SUMIFS(tblTransactions[Amount],tblTransactions[Transaction Type],"Transfer",tblTransactions[Destination Type],"Account",tblTransactions[Destination Name],$D9,tblTransactions[Transaction Status],"Reconciled")+SUMIFS(tblTransactions[Amount],tblTransactions[Transaction Type],"Adjustment",tblTransactions[Source Account],$D9,tblTransactions[Transaction Status],"Completed",tblTransactions[Amount],">0")+SUMIFS(tblTransactions[Amount],tblTransactions[Transaction Type],"Adjustment",tblTransactions[Source Account],$D9,tblTransactions[Transaction Status],"Reconciled",tblTransactions[Amount],">0"),0)) | G9: =IF($D9="","",IFERROR(SUMIFS(tblTransactions[Amount],tblTransactions[Transaction Type],"Expense",tblTransactions[Source Account],$D9,tblTransactions[Transaction Status],"Completed")+SUMIFS(tblTransactions[Amount],tblTransactions[Transaction Type],"Expense",tblTransactions[Source Account],$D9,tblTransactions[Transaction Status],"Reconciled")+SUMIFS(tblTransactions[Amount],tblTransactions[Transaction Type],"Transfer",tblTransactions[Source Account],$D9,tblTransactions[Transaction Status],"Completed")+SUMIFS(tblTransactions[Amount],tblTransactions[Transaction Type],"Transfer",tblTransactions[Source Account],$D9,tblTransactions[Transaction Status],"Reconciled")-SUMIFS(tblTransactions[Amount],tblTransactions[Transaction Type],"Adjustment",tblTransactions[Source Account],$D9,tblTransactions[Transaction Status],"Completed",tblTransactions[Amount],"<0")-SUMIFS(tblTransactions[Amount],tblTransactions[Transaction Type],"Adjustment",tblTransactions[Source Account],$D9,tblTransactions[Transaction Status],"Reconciled",tblTransactions[Amount],"<0"),0)) | H9: =IF($D9="","",$E9+$F9-$G9) | I9: =IF($D9="","",IFERROR(1/(1/AGGREGATE(14,6,tblTransactions[Transaction Date]/(((tblTransactions[Source Account]=$D9)+((tblTransactions[Transaction Type]="Transfer")*(tblTransactions[Destination Type]="Account")*(tblTransactions[Destination Name]=$D9)))*((tblTransactions[Transaction Status]="Completed")+(tblTransactions[Transaction Status]="Reconciled"))),1)),"")) | J9: =IF($D9="","",IFERROR(INDEX(tblAccounts[Account Type],ROW()-1),"")) | K9: =IF($D9="","",IFERROR(INDEX(tblAccounts[Include in Dashboard],ROW()-1),"")) | L9: =IF($D9="","",IFERROR(INDEX(tblAccounts[Status],ROW()-1),""))
D10: =IFERROR(IF(INDEX(tblAccounts[Account Name],ROW()-1)="","",INDEX(tblAccounts[Account Name],ROW()-1)),"") | E10: =IF($D10="","",IFERROR(INDEX(tblAccounts[Opening Balance],ROW()-1),0)) | F10: =IF($D10="","",IFERROR(SUMIFS(tblTransactions[Amount],tblTransactions[Transaction Type],"Income",tblTransactions[Source Account],$D10,tblTransactions[Transaction Status],"Completed")+SUMIFS(tblTransactions[Amount],tblTransactions[Transaction Type],"Income",tblTransactions[Source Account],$D10,tblTransactions[Transaction Status],"Reconciled")+SUMIFS(tblTransactions[Amount],tblTransactions[Transaction Type],"Transfer",tblTransactions[Destination Type],"Account",tblTransactions[Destination Name],$D10,tblTransactions[Transaction Status],"Completed")+SUMIFS(tblTransactions[Amount],tblTransactions[Transaction Type],"Transfer",tblTransactions[Destination Type],"Account",tblTransactions[Destination Name],$D10,tblTransactions[Transaction Status],"Reconciled")+SUMIFS(tblTransactions[Amount],tblTransactions[Transaction Type],"Adjustment",tblTransactions[Source Account],$D10,tblTransactions[Transaction Status],"Completed",tblTransactions[Amount],">0")+SUMIFS(tblTransactions[Amount],tblTransactions[Transaction Type],"Adjustment",tblTransactions[Source Account],$D10,tblTransactions[Transaction Status],"Reconciled",tblTransactions[Amount],">0"),0)) | G10: =IF($D10="","",IFERROR(SUMIFS(tblTransactions[Amount],tblTransactions[Transaction Type],"Expense",tblTransactions[Source Account],$D10,tblTransactions[Transaction Status],"Completed")+SUMIFS(tblTransactions[Amount],tblTransactions[Transaction Type],"Expense",tblTransactions[Source Account],$D10,tblTransactions[Transaction Status],"Reconciled")+SUMIFS(tblTransactions[Amount],tblTransactions[Transaction Type],"Transfer",tblTransactions[Source Account],$D10,tblTransactions[Transaction Status],"Completed")+SUMIFS(tblTransactions[Amount],tblTransactions[Transaction Type],"Transfer",tblTransactions[Source Account],$D10,tblTransactions[Transaction Status],"Reconciled")-SUMIFS(tblTransactions[Amount],tblTransactions[Transaction Type],"Adjustment",tblTransactions[Source Account],$D10,tblTransactions[Transaction Status],"Completed",tblTransactions[Amount],"<0")-SUMIFS(tblTransactions[Amount],tblTransactions[Transaction Type],"Adjustment",tblTransactions[Source Account],$D10,tblTransactions[Transaction Status],"Reconciled",tblTransactions[Amount],"<0"),0)) | H10: =IF($D10="","",$E10+$F10-$G10) | I10: =IF($D10="","",IFERROR(1/(1/AGGREGATE(14,6,tblTransactions[Transaction Date]/(((tblTransactions[Source Account]=$D10)+((tblTransactions[Transaction Type]="Transfer")*(tblTransactions[Destination Type]="Account")*(tblTransactions[Destination Name]=$D10)))*((tblTransactions[Transaction Status]="Completed")+(tblTransactions[Transaction Status]="Reconciled"))),1)),"")) | J10: =IF($D10="","",IFERROR(INDEX(tblAccounts[Account Type],ROW()-1),"")) | K10: =IF($D10="","",IFERROR(INDEX(tblAccounts[Include in Dashboard],ROW()-1),"")) | L10: =IF($D10="","",IFERROR(INDEX(tblAccounts[Status],ROW()-1),""))
A11: SECTION 2 — Income Summary | D11: =IFERROR(IF(INDEX(tblAccounts[Account Name],ROW()-1)="","",INDEX(tblAccounts[Account Name],ROW()-1)),"") | E11: =IF($D11="","",IFERROR(INDEX(tblAccounts[Opening Balance],ROW()-1),0)) | F11: =IF($D11="","",IFERROR(SUMIFS(tblTransactions[Amount],tblTransactions[Transaction Type],"Income",tblTransactions[Source Account],$D11,tblTransactions[Transaction Status],"Completed")+SUMIFS(tblTransactions[Amount],tblTransactions[Transaction Type],"Income",tblTransactions[Source Account],$D11,tblTransactions[Transaction Status],"Reconciled")+SUMIFS(tblTransactions[Amount],tblTransactions[Transaction Type],"Transfer",tblTransactions[Destination Type],"Account",tblTransactions[Destination Name],$D11,tblTransactions[Transaction Status],"Completed")+SUMIFS(tblTransactions[Amount],tblTransactions[Transaction Type],"Transfer",tblTransactions[Destination Type],"Account",tblTransactions[Destination Name],$D11,tblTransactions[Transaction Status],"Reconciled")+SUMIFS(tblTransactions[Amount],tblTransactions[Transaction Type],"Adjustment",tblTransactions[Source Account],$D11,tblTransactions[Transaction Status],"Completed",tblTransactions[Amount],">0")+SUMIFS(tblTransactions[Amount],tblTransactions[Transaction Type],"Adjustment",tblTransactions[Source Account],$D11,tblTransactions[Transaction Status],"Reconciled",tblTransactions[Amount],">0"),0)) | G11: =IF($D11="","",IFERROR(SUMIFS(tblTransactions[Amount],tblTransactions[Transaction Type],"Expense",tblTransactions[Source Account],$D11,tblTransactions[Transaction Status],"Completed")+SUMIFS(tblTransactions[Amount],tblTransactions[Transaction Type],"Expense",tblTransactions[Source Account],$D11,tblTransactions[Transaction Status],"Reconciled")+SUMIFS(tblTransactions[Amount],tblTransactions[Transaction Type],"Transfer",tblTransactions[Source Account],$D11,tblTransactions[Transaction Status],"Completed")+SUMIFS(tblTransactions[Amount],tblTransactions[Transaction Type],"Transfer",tblTransactions[Source Account],$D11,tblTransactions[Transaction Status],"Reconciled")-SUMIFS(tblTransactions[Amount],tblTransactions[Transaction Type],"Adjustment",tblTransactions[Source Account],$D11,tblTransactions[Transaction Status],"Completed",tblTransactions[Amount],"<0")-SUMIFS(tblTransactions[Amount],tblTransactions[Transaction Type],"Adjustment",tblTransactions[Source Account],$D11,tblTransactions[Transaction Status],"Reconciled",tblTransactions[Amount],"<0"),0)) | H11: =IF($D11="","",$E11+$F11-$G11) | I11: =IF($D11="","",IFERROR(1/(1/AGGREGATE(14,6,tblTransactions[Transaction Date]/(((tblTransactions[Source Account]=$D11)+((tblTransactions[Transaction Type]="Transfer")*(tblTransactions[Destination Type]="Account")*(tblTransactions[Destination Name]=$D11)))*((tblTransactions[Transaction Status]="Completed")+(tblTransactions[Transaction Status]="Reconciled"))),1)),"")) | J11: =IF($D11="","",IFERROR(INDEX(tblAccounts[Account Type],ROW()-1),"")) | K11: =IF($D11="","",IFERROR(INDEX(tblAccounts[Include in Dashboard],ROW()-1),"")) | L11: =IF($D11="","",IFERROR(INDEX(tblAccounts[Status],ROW()-1),""))
A12: Monthly Salary Income | B12: =IFERROR(SUMPRODUCT((tblTransactions[Transaction Type]="Income")*(tblTransactions[Transaction Date]>=DATE(YEAR($B$1),MONTH($B$1),1))*(tblTransactions[Transaction Date]<DATE(YEAR($B$1),MONTH($B$1)+1,1))*(tblTransactions[Amount])*(IFERROR(INDEX(tblIncomeSources[Income Category],MATCH(tblTransactions[Income Source],tblIncomeSources[Income Source Name],0)),"")="Salary")),0) | D12: =IFERROR(IF(INDEX(tblAccounts[Account Name],ROW()-1)="","",INDEX(tblAccounts[Account Name],ROW()-1)),"") | E12: =IF($D12="","",IFERROR(INDEX(tblAccounts[Opening Balance],ROW()-1),0)) | F12: =IF($D12="","",IFERROR(SUMIFS(tblTransactions[Amount],tblTransactions[Transaction Type],"Income",tblTransactions[Source Account],$D12,tblTransactions[Transaction Status],"Completed")+SUMIFS(tblTransactions[Amount],tblTransactions[Transaction Type],"Income",tblTransactions[Source Account],$D12,tblTransactions[Transaction Status],"Reconciled")+SUMIFS(tblTransactions[Amount],tblTransactions[Transaction Type],"Transfer",tblTransactions[Destination Type],"Account",tblTransactions[Destination Name],$D12,tblTransactions[Transaction Status],"Completed")+SUMIFS(tblTransactions[Amount],tblTransactions[Transaction Type],"Transfer",tblTransactions[Destination Type],"Account",tblTransactions[Destination Name],$D12,tblTransactions[Transaction Status],"Reconciled")+SUMIFS(tblTransactions[Amount],tblTransactions[Transaction Type],"Adjustment",tblTransactions[Source Account],$D12,tblTransactions[Transaction Status],"Completed",tblTransactions[Amount],">0")+SUMIFS(tblTransactions[Amount],tblTransactions[Transaction Type],"Adjustment",tblTransactions[Source Account],$D12,tblTransactions[Transaction Status],"Reconciled",tblTransactions[Amount],">0"),0)) | G12: =IF($D12="","",IFERROR(SUMIFS(tblTransactions[Amount],tblTransactions[Transaction Type],"Expense",tblTransactions[Source Account],$D12,tblTransactions[Transaction Status],"Completed")+SUMIFS(tblTransactions[Amount],tblTransactions[Transaction Type],"Expense",tblTransactions[Source Account],$D12,tblTransactions[Transaction Status],"Reconciled")+SUMIFS(tblTransactions[Amount],tblTransactions[Transaction Type],"Transfer",tblTransactions[Source Account],$D12,tblTransactions[Transaction Status],"Completed")+SUMIFS(tblTransactions[Amount],tblTransactions[Transaction Type],"Transfer",tblTransactions[Source Account],$D12,tblTransactions[Transaction Status],"Reconciled")-SUMIFS(tblTransactions[Amount],tblTransactions[Transaction Type],"Adjustment",tblTransactions[Source Account],$D12,tblTransactions[Transaction Status],"Completed",tblTransactions[Amount],"<0")-SUMIFS(tblTransactions[Amount],tblTransactions[Transaction Type],"Adjustment",tblTransactions[Source Account],$D12,tblTransactions[Transaction Status],"Reconciled",tblTransactions[Amount],"<0"),0)) | H12: =IF($D12="","",$E12+$F12-$G12) | I12: =IF($D12="","",IFERROR(1/(1/AGGREGATE(14,6,tblTransactions[Transaction Date]/(((tblTransactions[Source Account]=$D12)+((tblTransactions[Transaction Type]="Transfer")*(tblTransactions[Destination Type]="Account")*(tblTransactions[Destination Name]=$D12)))*((tblTransactions[Transaction Status]="Completed")+(tblTransactions[Transaction Status]="Reconciled"))),1)),"")) | J12: =IF($D12="","",IFERROR(INDEX(tblAccounts[Account Type],ROW()-1),"")) | K12: =IF($D12="","",IFERROR(INDEX(tblAccounts[Include in Dashboard],ROW()-1),"")) | L12: =IF($D12="","",IFERROR(INDEX(tblAccounts[Status],ROW()-1),""))
A13: Monthly Business Income | B13: =IFERROR(SUMPRODUCT((tblTransactions[Transaction Type]="Income")*(tblTransactions[Transaction Date]>=DATE(YEAR($B$1),MONTH($B$1),1))*(tblTransactions[Transaction Date]<DATE(YEAR($B$1),MONTH($B$1)+1,1))*(tblTransactions[Amount])*(IFERROR(INDEX(tblIncomeSources[Income Category],MATCH(tblTransactions[Income Source],tblIncomeSources[Income Source Name],0)),"")="Business Income")),0) | D13: =IFERROR(IF(INDEX(tblAccounts[Account Name],ROW()-1)="","",INDEX(tblAccounts[Account Name],ROW()-1)),"") | E13: =IF($D13="","",IFERROR(INDEX(tblAccounts[Opening Balance],ROW()-1),0)) | F13: =IF($D13="","",IFERROR(SUMIFS(tblTransactions[Amount],tblTransactions[Transaction Type],"Income",tblTransactions[Source Account],$D13,tblTransactions[Transaction Status],"Completed")+SUMIFS(tblTransactions[Amount],tblTransactions[Transaction Type],"Income",tblTransactions[Source Account],$D13,tblTransactions[Transaction Status],"Reconciled")+SUMIFS(tblTransactions[Amount],tblTransactions[Transaction Type],"Transfer",tblTransactions[Destination Type],"Account",tblTransactions[Destination Name],$D13,tblTransactions[Transaction Status],"Completed")+SUMIFS(tblTransactions[Amount],tblTransactions[Transaction Type],"Transfer",tblTransactions[Destination Type],"Account",tblTransactions[Destination Name],$D13,tblTransactions[Transaction Status],"Reconciled")+SUMIFS(tblTransactions[Amount],tblTransactions[Transaction Type],"Adjustment",tblTransactions[Source Account],$D13,tblTransactions[Transaction Status],"Completed",tblTransactions[Amount],">0")+SUMIFS(tblTransactions[Amount],tblTransactions[Transaction Type],"Adjustment",tblTransactions[Source Account],$D13,tblTransactions[Transaction Status],"Reconciled",tblTransactions[Amount],">0"),0)) | G13: =IF($D13="","",IFERROR(SUMIFS(tblTransactions[Amount],tblTransactions[Transaction Type],"Expense",tblTransactions[Source Account],$D13,tblTransactions[Transaction Status],"Completed")+SUMIFS(tblTransactions[Amount],tblTransactions[Transaction Type],"Expense",tblTransactions[Source Account],$D13,tblTransactions[Transaction Status],"Reconciled")+SUMIFS(tblTransactions[Amount],tblTransactions[Transaction Type],"Transfer",tblTransactions[Source Account],$D13,tblTransactions[Transaction Status],"Completed")+SUMIFS(tblTransactions[Amount],tblTransactions[Transaction Type],"Transfer",tblTransactions[Source Account],$D13,tblTransactions[Transaction Status],"Reconciled")-SUMIFS(tblTransactions[Amount],tblTransactions[Transaction Type],"Adjustment",tblTransactions[Source Account],$D13,tblTransactions[Transaction Status],"Completed",tblTransactions[Amount],"<0")-SUMIFS(tblTransactions[Amount],tblTransactions[Transaction Type],"Adjustment",tblTransactions[Source Account],$D13,tblTransactions[Transaction Status],"Reconciled",tblTransactions[Amount],"<0"),0)) | H13: =IF($D13="","",$E13+$F13-$G13) | I13: =IF($D13="","",IFERROR(1/(1/AGGREGATE(14,6,tblTransactions[Transaction Date]/(((tblTransactions[Source Account]=$D13)+((tblTransactions[Transaction Type]="Transfer")*(tblTransactions[Destination Type]="Account")*(tblTransactions[Destination Name]=$D13)))*((tblTransactions[Transaction Status]="Completed")+(tblTransactions[Transaction Status]="Reconciled"))),1)),"")) | J13: =IF($D13="","",IFERROR(INDEX(tblAccounts[Account Type],ROW()-1),"")) | K13: =IF($D13="","",IFERROR(INDEX(tblAccounts[Include in Dashboard],ROW()-1),"")) | L13: =IF($D13="","",IFERROR(INDEX(tblAccounts[Status],ROW()-1),""))
A14: Monthly Freelance Income | B14: =IFERROR(SUMPRODUCT((tblTransactions[Transaction Type]="Income")*(tblTransactions[Transaction Date]>=DATE(YEAR($B$1),MONTH($B$1),1))*(tblTransactions[Transaction Date]<DATE(YEAR($B$1),MONTH($B$1)+1,1))*(tblTransactions[Amount])*(IFERROR(INDEX(tblIncomeSources[Income Category],MATCH(tblTransactions[Income Source],tblIncomeSources[Income Source Name],0)),"")="Freelance")),0) | D14: =IFERROR(IF(INDEX(tblAccounts[Account Name],ROW()-1)="","",INDEX(tblAccounts[Account Name],ROW()-1)),"") | E14: =IF($D14="","",IFERROR(INDEX(tblAccounts[Opening Balance],ROW()-1),0)) | F14: =IF($D14="","",IFERROR(SUMIFS(tblTransactions[Amount],tblTransactions[Transaction Type],"Income",tblTransactions[Source Account],$D14,tblTransactions[Transaction Status],"Completed")+SUMIFS(tblTransactions[Amount],tblTransactions[Transaction Type],"Income",tblTransactions[Source Account],$D14,tblTransactions[Transaction Status],"Reconciled")+SUMIFS(tblTransactions[Amount],tblTransactions[Transaction Type],"Transfer",tblTransactions[Destination Type],"Account",tblTransactions[Destination Name],$D14,tblTransactions[Transaction Status],"Completed")+SUMIFS(tblTransactions[Amount],tblTransactions[Transaction Type],"Transfer",tblTransactions[Destination Type],"Account",tblTransactions[Destination Name],$D14,tblTransactions[Transaction Status],"Reconciled")+SUMIFS(tblTransactions[Amount],tblTransactions[Transaction Type],"Adjustment",tblTransactions[Source Account],$D14,tblTransactions[Transaction Status],"Completed",tblTransactions[Amount],">0")+SUMIFS(tblTransactions[Amount],tblTransactions[Transaction Type],"Adjustment",tblTransactions[Source Account],$D14,tblTransactions[Transaction Status],"Reconciled",tblTransactions[Amount],">0"),0)) | G14: =IF($D14="","",IFERROR(SUMIFS(tblTransactions[Amount],tblTransactions[Transaction Type],"Expense",tblTransactions[Source Account],$D14,tblTransactions[Transaction Status],"Completed")+SUMIFS(tblTransactions[Amount],tblTransactions[Transaction Type],"Expense",tblTransactions[Source Account],$D14,tblTransactions[Transaction Status],"Reconciled")+SUMIFS(tblTransactions[Amount],tblTransactions[Transaction Type],"Transfer",tblTransactions[Source Account],$D14,tblTransactions[Transaction Status],"Completed")+SUMIFS(tblTransactions[Amount],tblTransactions[Transaction Type],"Transfer",tblTransactions[Source Account],$D14,tblTransactions[Transaction Status],"Reconciled")-SUMIFS(tblTransactions[Amount],tblTransactions[Transaction Type],"Adjustment",tblTransactions[Source Account],$D14,tblTransactions[Transaction Status],"Completed",tblTransactions[Amount],"<0")-SUMIFS(tblTransactions[Amount],tblTransactions[Transaction Type],"Adjustment",tblTransactions[Source Account],$D14,tblTransactions[Transaction Status],"Reconciled",tblTransactions[Amount],"<0"),0)) | H14: =IF($D14="","",$E14+$F14-$G14) | I14: =IF($D14="","",IFERROR(1/(1/AGGREGATE(14,6,tblTransactions[Transaction Date]/(((tblTransactions[Source Account]=$D14)+((tblTransactions[Transaction Type]="Transfer")*(tblTransactions[Destination Type]="Account")*(tblTransactions[Destination Name]=$D14)))*((tblTransactions[Transaction Status]="Completed")+(tblTransactions[Transaction Status]="Reconciled"))),1)),"")) | J14: =IF($D14="","",IFERROR(INDEX(tblAccounts[Account Type],ROW()-1),"")) | K14: =IF($D14="","",IFERROR(INDEX(tblAccounts[Include in Dashboard],ROW()-1),"")) | L14: =IF($D14="","",IFERROR(INDEX(tblAccounts[Status],ROW()-1),""))
