Workbook

Sheet QA Dashboard
A1: FinanceOS RC1 QA — Linked Regression (Excel Web 3-tab)
A3: FinanceOS Version Tested | B3: v1.0 RC1
A4: QA Workbook Version | B4: RC1 QA Master 2026-09-19
A5: Testing environment | B5: Excel Web — three tabs, one browser session
A6: Tab 1 Baseline (frozen) | B6: FinanceOS_QA_Baseline.xlsx
A7: Tab 2 Under test | B7: FinanceOS_v1.0-QA-RC1.xlsx
A8: Active Scenario | B8: SCN-BASE
A9: Timestamp | B9: =NOW()
A10: PASS Count | B10: =COUNTIF('Difference Engine'!F:F,"PASS")
A11: FAIL Count | B11: =COUNTIF('Difference Engine'!F:F,"FAIL")
A12: WAIT Count | B12: =COUNTIF('Difference Engine'!F:F,"WAIT")
A13: MAXIFS Gate | B13: ='Formula Inventory'!G16
A14: Compatibility Status | B14: ='Compatibility Gate'!B13
A15: Regression Status | B15: =IF(OR(B11>0,B12>0,ISNUMBER(SEARCH("MAXIFS PRESENT",B13)),B14<>"PASS"),"DO NOT PROMOTE","READY FOR PROMOTION")
A17: Open FinanceOS_QA_Baseline.xlsx, FinanceOS_v1.0-QA-RC1.xlsx, and this file as three tabs in the SAME Excel Web window (same Microsoft account, same folder). Click Trust workbook links once. Edit only the QA-RC1 tab. Difference Engine compares Baseline vs QA-RC1 automatically. No paste-values.

Sheet Test Scenarios
A1: Scenario ID | B1: Test Name | C1: Preconditions | D1: Test Data | E1: Step 1 | F1: Step 2 | G1: Expected outputs | H1: Rollback | I1: Amount | J1: From Account | K1: To Account | L1: Txn Type | M1: Status | N1: Date Mode | O1: Executed? | P1: Result
A2: SCN-BASE | B2: Baseline identical | C2: Baseline and QA-RC1 start identical. | D2: Do not edit either engine. | E2: Open all three Excel Web tabs. Trust workbook links. | F2: Confirm Difference Engine is all ~0 / PASS. | G2: All differences 0. | H2: None. | I2: 0 | M2: Completed | N2: ASOF | P2: =IF(O2<>"Yes","",IF('QA Dashboard'!$B$8<>A2,"OTHER",IF('QA Dashboard'!$B$11>0,"FAIL",IF('QA Dashboard'!$B$12>0,"WAIT","PASS"))))
A3: SCN-A | B3: Add income | C3: Baseline frozen. Edit QA-RC1 only. | D3: Completed Income 3000 HDFC Salary, Acme Payroll, date=As-Of. | E3: Add the income row on QA-RC1 Transactions. | F3: Wait for links to refresh. | G3: Monthly/annual income +3000. B23 unchanged. | H3: Delete the new row. | I3: 3000 | J3: HDFC Salary | L3: Income | M3: Completed | N3: ASOF | P3: =IF(O3<>"Yes","",IF('QA Dashboard'!$B$8<>A3,"OTHER",IF('QA Dashboard'!$B$11>0,"FAIL",IF('QA Dashboard'!$B$12>0,"WAIT","PASS"))))
A4: SCN-B | B4: Add expense | C4: Baseline frozen. | D4: Completed Expense 2500 HDFC Salary Groceries, As-Of. | E4: Add expense on QA-RC1. | F4: Refresh. | G4: CM expenses +2500. Savings -2500. B23 unchanged. | H4: Delete the row. | I4: 2500 | J4: HDFC Salary | L4: Expense | M4: Completed | N4: ASOF | P4: =IF(O4<>"Yes","",IF('QA Dashboard'!$B$8<>A4,"OTHER",IF('QA Dashboard'!$B$11>0,"FAIL",IF('QA Dashboard'!$B$12>0,"WAIT","PASS"))))
A5: SCN-C | B5: Add transfer | C5: Baseline frozen. | D5: Completed Transfer 1000 HDFC Salary → SBI Savings, As-Of. | E5: Add transfer on QA-RC1. | F5: Refresh. | G5: Income/expense 0 change. Account-summary B4 stays 0 on this RC1 freeze. | H5: Delete the row. | I5: 1000 | J5: HDFC Salary | K5: SBI Savings | L5: Transfer | M5: Completed | N5: ASOF | P5: =IF(O5<>"Yes","",IF('QA Dashboard'!$B$8<>A5,"OTHER",IF('QA Dashboard'!$B$11>0,"FAIL",IF('QA Dashboard'!$B$12>0,"WAIT","PASS"))))
A6: SCN-D | B6: Pending ignored | C6: Baseline frozen. | D6: Pending Expense 2500 HDFC, As-Of. | E6: Add pending expense. | F6: Refresh. | G6: RC1 SUMIFS does not filter status — record actual vs expected. Desired: no change. | H6: Delete the row. | I6: 2500 | J6: HDFC Salary | L6: Expense | M6: Pending | N6: ASOF | P6: =IF(O6<>"Yes","",IF('QA Dashboard'!$B$8<>A6,"OTHER",IF('QA Dashboard'!$B$11>0,"FAIL",IF('QA Dashboard'!$B$12>0,"WAIT","PASS"))))
A7: SCN-E | B7: Cancelled ignored | C7: Baseline frozen. | D7: Cancelled Expense 2500 HDFC, As-Of. | E7: Add cancelled expense. | F7: Refresh. | G7: Desired: no change. RC1 SUMIFS may still include it. | H7: Delete the row. | I7: 2500 | J7: HDFC Salary | L7: Expense | M7: Cancelled | N7: ASOF | P7: =IF(O7<>"Yes","",IF('QA Dashboard'!$B$8<>A7,"OTHER",IF('QA Dashboard'!$B$11>0,"FAIL",IF('QA Dashboard'!$B$12>0,"WAIT","PASS"))))
A8: SCN-F | B8: Reconciled counted | C8: Baseline frozen. | D8: Reconciled Income 1000 HDFC, As-Of. | E8: Add reconciled income. | F8: Refresh. | G8: Income totals +1000. | H8: Delete the row. | I8: 1000 | J8: HDFC Salary | L8: Income | M8: Reconciled | N8: ASOF | P8: =IF(O8<>"Yes","",IF('QA Dashboard'!$B$8<>A8,"OTHER",IF('QA Dashboard'!$B$11>0,"FAIL",IF('QA Dashboard'!$B$12>0,"WAIT","PASS"))))
A9: SCN-G | B9: Goal contribution | C9: Baseline frozen. | D9: Expense 5000 Destination Type=Goal Destination=Emergency Fund. | E9: Add goal contribution. | F9: Refresh. | G9: CM expenses +5000. Goal table saved amount is not auto-updated on this RC1 freeze. | H9: Delete the row. | I9: 5000 | J9: HDFC Salary | K9: Emergency Fund | L9: Expense | M9: Completed | N9: ASOF | P9: =IF(O9<>"Yes","",IF('QA Dashboard'!$B$8<>A9,"OTHER",IF('QA Dashboard'!$B$11>0,"FAIL",IF('QA Dashboard'!$B$12>0,"WAIT","PASS"))))
A10: SCN-H | B10: Credit card spend | C10: Baseline frozen. | D10: Expense 2000 from ICICI Credit Card, Shopping, Completed, As-Of. | E10: Add CC spend. | F10: Refresh. | G10: CM expenses +2000. | H10: Delete the row. | I10: 2000 | J10: ICICI Credit Card | L10: Expense | M10: Completed | N10: ASOF | P10: =IF(O10<>"Yes","",IF('QA Dashboard'!$B$8<>A10,"OTHER",IF('QA Dashboard'!$B$11>0,"FAIL",IF('QA Dashboard'!$B$12>0,"WAIT","PASS"))))
A11: SCN-I | B11: Credit card payment | C11: Baseline frozen. | D11: Transfer 2000 HDFC Salary → ICICI Credit Card. | E11: Add CC payment transfer. | F11: Refresh. | G11: Income/expense 0 change. | H11: Delete the row. | I11: 2000 | J11: HDFC Salary | K11: ICICI Credit Card | L11: Transfer | M11: Completed | N11: ASOF | P11: =IF(O11<>"Yes","",IF('QA Dashboard'!$B$8<>A11,"OTHER",IF('QA Dashboard'!$B$11>0,"FAIL",IF('QA Dashboard'!$B$12>0,"WAIT","PASS"))))
A12: SCN-J | B12: Asset purchase | C12: Baseline frozen. | D12: Expense 15000 Destination Type=Asset Destination=Gold. | E12: Add asset purchase expense. | F12: Refresh. | G12: CM expenses +15000. Asset current value is not auto-updated. | H12: Delete the row. | I12: 15000 | J12: HDFC Salary | K12: Gold | L12: Expense | M12: Completed | N12: ASOF | P12: =IF(O12<>"Yes","",IF('QA Dashboard'!$B$8<>A12,"OTHER",IF('QA Dashboard'!$B$11>0,"FAIL",IF('QA Dashboard'!$B$12>0,"WAIT","PASS"))))
A13: SCN-K | B13: BUG-003 latest date vs row order | C13: Baseline already has TXN-000090 30-Sep above TXN-000010 01-Jan. | D13: Do not add rows. Inspect order. | E13: Confirm row 2 date is 30-Sep-2026 and row 3 is 01-Jan-2026. | F13: Refresh. | G13: RC1 has no Last Transaction Date engine cell. Record N/A unless Account Engine is added later. | H13: None. | I13: 0 | J13: HDFC Salary | L13: Income | M13: Completed | N13: BUG003 | P13: =IF(O13<>"Yes","",IF('QA Dashboard'!$B$8<>A13,"OTHER",IF('QA Dashboard'!$B$11>0,"FAIL",IF('QA Dashboard'!$B$12>0,"WAIT","PASS"))))
A14: SCN-L | B14: Pending latest ignored | C14: Pending 25-Sep already in fixture. | D14: Optional: add another pending dated after last completed. | E14: Inspect pending row. | F14: Refresh. | G14: Desired: pending does not become last completed date. No LAST cell on this RC1 freeze. | H14: Delete extra pending if added. | I14: 0 | J14: HDFC Salary | L14: Expense | M14: Pending | N14: ASOF | P14: =IF(O14<>"Yes","",IF('QA Dashboard'!$B$8<>A14,"OTHER",IF('QA Dashboard'!$B$11>0,"FAIL",IF('QA Dashboard'!$B$12>0,"WAIT","PASS"))))
A15: SCN-M | B15: Cancelled latest ignored | C15: Cancelled 22-Sep already in fixture. | D15: Optional extra cancelled after as-of. | E15: Inspect cancelled row. | F15: Refresh. | G15: Desired: cancelled ignored for last date. No LAST cell on this RC1 freeze. | H15: Delete extra row. | I15: 0 | J15: HDFC Salary | L15: Expense | M15: Cancelled | N15: ASOF | P15: =IF(O15<>"Yes","",IF('QA Dashboard'!$B$8<>A15,"OTHER",IF('QA Dashboard'!$B$11>0,"FAIL",IF('QA Dashboard'!$B$12>0,"WAIT","PASS"))))
A16: SCN-N | B16: Inbound transfer dest account | C16: Baseline frozen. | D16: Completed Transfer 2500 SBI Savings → HDFC Salary. | E16: Add inbound transfer. | F16: Refresh. | G16: Income/expense 0. Dest account should increase when Account Engine exists. | H16: Delete the row. | I16: 2500 | J16: SBI Savings | K16: HDFC Salary | L16: Transfer | M16: Completed | N16: ASOF | P16: =IF(O16<>"Yes","",IF('QA Dashboard'!$B$8<>A16,"OTHER",IF('QA Dashboard'!$B$11>0,"FAIL",IF('QA Dashboard'!$B$12>0,"WAIT","PASS"))))
A17: SCN-O | B17: Outbound transfer source account | C17: Baseline frozen. | D17: Completed Transfer 2500 HDFC Salary → SBI Savings. | E17: Add outbound transfer. | F17: Refresh. | G17: Income/expense 0. Source account should decrease when Account Engine exists. | H17: Delete the row. | I17: 2500 | J17: HDFC Salary | K17: SBI Savings | L17: Transfer | M17: Completed | N17: ASOF | P17: =IF(O17<>"Yes","",IF('QA Dashboard'!$B$8<>A17,"OTHER",IF('QA Dashboard'!$B$11>0,"FAIL",IF('QA Dashboard'!$B$12>0,"WAIT","PASS"))))
A18: SCN-P | B18: Mixed statuses + row order | C18: Use existing fixture plus one completed, one pending, one cancelled. | D18: Mix dates and row positions. | E18: Add three rows then inspect. | F18: Refresh. | G18: Completed affects income/expense; pending/cancelled desired ignored; row order must not change last date. | H18: Delete the three rows. | I18: 100 | J18: HDFC Salary | L18: Income | M18: Completed | N18: ASOF | P18: =IF(O18<>"Yes","",IF('QA Dashboard'!$B$8<>A18,"OTHER",IF('QA Dashboard'!$B$11>0,"FAIL",IF('QA Dashboard'!$B$12>0,"WAIT","PASS"))))

Sheet Difference Engine
A1: Metric ID | B1: Baseline | C1: QA-RC1 | D1: Difference | E1: Expected Difference | F1: PASS / FAIL | G1: Metric | H1: Section | I1: Cell | J1: Sheet
A2: ACC_TOTAL_BAL | B2: ='[FinanceOS_QA_Baseline.xlsx]Business Engine'!B4 | C2: ='[FinanceOS_v1.0-QA-RC1.xlsx]Business Engine'!B4 | D2: =IF(OR(B2="",C2=""),"",IF(AND(ISNUMBER(B2),ISNUMBER(C2)),C2-B2,IF(B2=C2,0,"≠"))) | E2: =0 | F2: =IF(OR(B2="",C2=""),"WAIT",IF(AND(ISNUMBER(D2),ISNUMBER(E2)),IF(ABS(D2-E2)<0.005,"PASS","FAIL"),IF(D2=E2,"PASS","FAIL"))) | G2: Total Active Account Balance | H2: Accounts Summary | I2: B4 | J2: Business Engine
A3: ACC_ACTIVE_N | B3: ='[FinanceOS_QA_Baseline.xlsx]Business Engine'!B5 | C3: ='[FinanceOS_v1.0-QA-RC1.xlsx]Business Engine'!B5 | D3: =IF(OR(B3="",C3=""),"",IF(AND(ISNUMBER(B3),ISNUMBER(C3)),C3-B3,IF(B3=C3,0,"≠"))) | E3: =0 | F3: =IF(OR(B3="",C3=""),"WAIT",IF(AND(ISNUMBER(D3),ISNUMBER(E3)),IF(ABS(D3-E3)<0.005,"PASS","FAIL"),IF(D3=E3,"PASS","FAIL"))) | G3: Number of Active Accounts | H3: Accounts Summary | I3: B5 | J3: Business Engine
A4: ACC_CASH | B4: ='[FinanceOS_QA_Baseline.xlsx]Business Engine'!B6 | C4: ='[FinanceOS_v1.0-QA-RC1.xlsx]Business Engine'!B6 | D4: =IF(OR(B4="",C4=""),"",IF(AND(ISNUMBER(B4),ISNUMBER(C4)),C4-B4,IF(B4=C4,0,"≠"))) | E4: =0 | F4: =IF(OR(B4="",C4=""),"WAIT",IF(AND(ISNUMBER(D4),ISNUMBER(E4)),IF(ABS(D4-E4)<0.005,"PASS","FAIL"),IF(D4=E4,"PASS","FAIL"))) | G4: Cash Accounts Total | H4: Accounts Summary | I4: B6 | J4: Business Engine
A5: ACC_SAVINGS | B5: ='[FinanceOS_QA_Baseline.xlsx]Business Engine'!B7 | C5: ='[FinanceOS_v1.0-QA-RC1.xlsx]Business Engine'!B7 | D5: =IF(OR(B5="",C5=""),"",IF(AND(ISNUMBER(B5),ISNUMBER(C5)),C5-B5,IF(B5=C5,0,"≠"))) | E5: =0 | F5: =IF(OR(B5="",C5=""),"WAIT",IF(AND(ISNUMBER(D5),ISNUMBER(E5)),IF(ABS(D5-E5)<0.005,"PASS","FAIL"),IF(D5=E5,"PASS","FAIL"))) | G5: Savings Accounts Total | H5: Accounts Summary | I5: B7 | J5: Business Engine
A6: ACC_INVEST | B6: ='[FinanceOS_QA_Baseline.xlsx]Business Engine'!B8 | C6: ='[FinanceOS_v1.0-QA-RC1.xlsx]Business Engine'!B8 | D6: =IF(OR(B6="",C6=""),"",IF(AND(ISNUMBER(B6),ISNUMBER(C6)),C6-B6,IF(B6=C6,0,"≠"))) | E6: =0 | F6: =IF(OR(B6="",C6=""),"WAIT",IF(AND(ISNUMBER(D6),ISNUMBER(E6)),IF(ABS(D6-E6)<0.005,"PASS","FAIL"),IF(D6=E6,"PASS","FAIL"))) | G6: Investment Accounts Total | H6: Accounts Summary | I6: B8 | J6: Business Engine
A7: ACC_CREDIT | B7: ='[FinanceOS_QA_Baseline.xlsx]Business Engine'!B9 | C7: ='[FinanceOS_v1.0-QA-RC1.xlsx]Business Engine'!B9 | D7: =IF(OR(B7="",C7=""),"",IF(AND(ISNUMBER(B7),ISNUMBER(C7)),C7-B7,IF(B7=C7,0,"≠"))) | E7: =0 | F7: =IF(OR(B7="",C7=""),"WAIT",IF(AND(ISNUMBER(D7),ISNUMBER(E7)),IF(ABS(D7-E7)<0.005,"PASS","FAIL"),IF(D7=E7,"PASS","FAIL"))) | G7: Credit Accounts Total | H7: Accounts Summary | I7: B9 | J7: Business Engine
A8: INC_SALARY | B8: ='[FinanceOS_QA_Baseline.xlsx]Business Engine'!B12 | C8: ='[FinanceOS_v1.0-QA-RC1.xlsx]Business Engine'!B12 | D8: =IF(OR(B8="",C8=""),"",IF(AND(ISNUMBER(B8),ISNUMBER(C8)),C8-B8,IF(B8=C8,0,"≠"))) | E8: =IF(AND(OR($J$7="Completed",$J$7="Reconciled"),$J$6="Income",$J$9),$J$3,0) | F8: =IF(OR(B8="",C8=""),"WAIT",IF(AND(ISNUMBER(D8),ISNUMBER(E8)),IF(ABS(D8-E8)<0.005,"PASS","FAIL"),IF(D8=E8,"PASS","FAIL"))) | G8: Monthly Salary Income | H8: Income Summary | I8: B12 | J8: Business Engine
A9: INC_BIZ | B9: ='[FinanceOS_QA_Baseline.xlsx]Business Engine'!B13 | C9: ='[FinanceOS_v1.0-QA-RC1.xlsx]Business Engine'!B13 | D9: =IF(OR(B9="",C9=""),"",IF(AND(ISNUMBER(B9),ISNUMBER(C9)),C9-B9,IF(B9=C9,0,"≠"))) | E9: =0 | F9: =IF(OR(B9="",C9=""),"WAIT",IF(AND(ISNUMBER(D9),ISNUMBER(E9)),IF(ABS(D9-E9)<0.005,"PASS","FAIL"),IF(D9=E9,"PASS","FAIL"))) | G9: Monthly Business Income | H9: Income Summary | I9: B13 | J9: Business Engine
A10: INC_FREE | B10: ='[FinanceOS_QA_Baseline.xlsx]Business Engine'!B14 | C10: ='[FinanceOS_v1.0-QA-RC1.xlsx]Business Engine'!B14 | D10: =IF(OR(B10="",C10=""),"",IF(AND(ISNUMBER(B10),ISNUMBER(C10)),C10-B10,IF(B10=C10,0,"≠"))) | E10: =IF(AND(OR($J$7="Completed",$J$7="Reconciled"),$J$6="Income",$J$5="Freelance Gigs",$J$9),$J$3,0) | F10: =IF(OR(B10="",C10=""),"WAIT",IF(AND(ISNUMBER(D10),ISNUMBER(E10)),IF(ABS(D10-E10)<0.005,"PASS","FAIL"),IF(D10=E10,"PASS","FAIL"))) | G10: Monthly Freelance Income | H10: Income Summary | I10: B14 | J10: Business Engine
A11: INC_INV | B11: ='[FinanceOS_QA_Baseline.xlsx]Business Engine'!B15 | C11: ='[FinanceOS_v1.0-QA-RC1.xlsx]Business Engine'!B15 | D11: =IF(OR(B11="",C11=""),"",IF(AND(ISNUMBER(B11),ISNUMBER(C11)),C11-B11,IF(B11=C11,0,"≠"))) | E11: =0 | F11: =IF(OR(B11="",C11=""),"WAIT",IF(AND(ISNUMBER(D11),ISNUMBER(E11)),IF(ABS(D11-E11)<0.005,"PASS","FAIL"),IF(D11=E11,"PASS","FAIL"))) | G11: Monthly Investment Income | H11: Income Summary | I11: B15 | J11: Business Engine
A12: INC_MONTH | B12: ='[FinanceOS_QA_Baseline.xlsx]Business Engine'!B16 | C12: ='[FinanceOS_v1.0-QA-RC1.xlsx]Business Engine'!B16 | D12: =IF(OR(B12="",C12=""),"",IF(AND(ISNUMBER(B12),ISNUMBER(C12)),C12-B12,IF(B12=C12,0,"≠"))) | E12: =IF(AND(OR($J$7="Completed",$J$7="Reconciled"),$J$6="Income",$J$9),$J$3,0) | F12: =IF(OR(B12="",C12=""),"WAIT",IF(AND(ISNUMBER(D12),ISNUMBER(E12)),IF(ABS(D12-E12)<0.005,"PASS","FAIL"),IF(D12=E12,"PASS","FAIL"))) | G12: Total Monthly Income | H12: Income Summary | I12: B16 | J12: Business Engine
A13: INC_OTHER | B13: ='[FinanceOS_QA_Baseline.xlsx]Business Engine'!B17 | C13: ='[FinanceOS_v1.0-QA-RC1.xlsx]Business Engine'!B17 | D13: =IF(OR(B13="",C13=""),"",IF(AND(ISNUMBER(B13),ISNUMBER(C13)),C13-B13,IF(B13=C13,0,"≠"))) | E13: =0 | F13: =IF(OR(B13="",C13=""),"WAIT",IF(AND(ISNUMBER(D13),ISNUMBER(E13)),IF(ABS(D13-E13)<0.005,"PASS","FAIL"),IF(D13=E13,"PASS","FAIL"))) | G13: Monthly Other Income | H13: Income Summary | I13: B17 | J13: Business Engine
A14: INC_ANNUAL | B14: ='[FinanceOS_QA_Baseline.xlsx]Business Engine'!B18 | C14: ='[FinanceOS_v1.0-QA-RC1.xlsx]Business Engine'!B18 | D14: =IF(OR(B14="",C14=""),"",IF(AND(ISNUMBER(B14),ISNUMBER(C14)),C14-B14,IF(B14=C14,0,"≠"))) | E14: =IF(AND(OR($J$7="Completed",$J$7="Reconciled"),$J$6="Income"),$J$3,0) | F14: =IF(OR(B14="",C14=""),"WAIT",IF(AND(ISNUMBER(D14),ISNUMBER(E14)),IF(ABS(D14-E14)<0.005,"PASS","FAIL"),IF(D14=E14,"PASS","FAIL"))) | G14: Total Annual Income | H14: Income Summary | I14: B18 | J14: Business Engine
A15: INC_SRC_N | B15: ='[FinanceOS_QA_Baseline.xlsx]Business Engine'!B19 | C15: ='[FinanceOS_v1.0-QA-RC1.xlsx]Business Engine'!B19 | D15: =IF(OR(B15="",C15=""),"",IF(AND(ISNUMBER(B15),ISNUMBER(C15)),C15-B15,IF(B15=C15,0,"≠"))) | E15: =0 | F15: =IF(OR(B15="",C15=""),"WAIT",IF(AND(ISNUMBER(D15),ISNUMBER(E15)),IF(ABS(D15-E15)<0.005,"PASS","FAIL"),IF(D15=E15,"PASS","FAIL"))) | G15: Active Income Source Count | H15: Income Summary | I15: B19 | J15: Business Engine
A16: EXP_CM | B16: ='[FinanceOS_QA_Baseline.xlsx]Business Engine'!B22 | C16: ='[FinanceOS_v1.0-QA-RC1.xlsx]Business Engine'!B22 | D16: =IF(OR(B16="",C16=""),"",IF(AND(ISNUMBER(B16),ISNUMBER(C16)),C16-B16,IF(B16=C16,0,"≠"))) | E16: =IF(AND(OR($J$7="Completed",$J$7="Reconciled"),$J$6="Expense",$J$9),$J$3,0) | F16: =IF(OR(B16="",C16=""),"WAIT",IF(AND(ISNUMBER(D16),ISNUMBER(E16)),IF(ABS(D16-E16)<0.005,"PASS","FAIL"),IF(D16=E16,"PASS","FAIL"))) | G16: Current Month Expenses | H16: Expense Summary | I16: B22 | J16: Business Engine
A17: EXP_PM | B17: ='[FinanceOS_QA_Baseline.xlsx]Business Engine'!B23 | C17: ='[FinanceOS_v1.0-QA-RC1.xlsx]Business Engine'!B23 | D17: =IF(OR(B17="",C17=""),"",IF(AND(ISNUMBER(B17),ISNUMBER(C17)),C17-B17,IF(B17=C17,0,"≠"))) | E17: =0 | F17: =IF(OR(B17="",C17=""),"WAIT",IF(AND(ISNUMBER(D17),ISNUMBER(E17)),IF(ABS(D17-E17)<0.005,"PASS","FAIL"),IF(D17=E17,"PASS","FAIL"))) | G17: Previous Month Expenses | H17: Expense Summary | I17: B23 | J17: Business Engine
A18: EXP_YTD | B18: ='[FinanceOS_QA_Baseline.xlsx]Business Engine'!B24 | C18: ='[FinanceOS_v1.0-QA-RC1.xlsx]Business Engine'!B24 | D18: =IF(OR(B18="",C18=""),"",IF(AND(ISNUMBER(B18),ISNUMBER(C18)),C18-B18,IF(B18=C18,0,"≠"))) | E18: =IF(AND(OR($J$7="Completed",$J$7="Reconciled"),$J$6="Expense"),$J$3,0) | F18: =IF(OR(B18="",C18=""),"WAIT",IF(AND(ISNUMBER(D18),ISNUMBER(E18)),IF(ABS(D18-E18)<0.005,"PASS","FAIL"),IF(D18=E18,"PASS","FAIL"))) | G18: Year-to-Date Expenses | H18: Expense Summary | I18: B24 | J18: Business Engine
A19: EXP_N | B19: ='[FinanceOS_QA_Baseline.xlsx]Business Engine'!B25 | C19: ='[FinanceOS_v1.0-QA-RC1.xlsx]Business Engine'!B25 | D19: =IF(OR(B19="",C19=""),"",IF(AND(ISNUMBER(B19),ISNUMBER(C19)),C19-B19,IF(B19=C19,0,"≠"))) | E19: =IF(AND(OR($J$7="Completed",$J$7="Reconciled"),$J$6="Expense",$J$9),1,0) | F19: =IF(OR(B19="",C19=""),"WAIT",IF(AND(ISNUMBER(D19),ISNUMBER(E19)),IF(ABS(D19-E19)<0.005,"PASS","FAIL"),IF(D19=E19,"PASS","FAIL"))) | G19: Expense Transaction Count | H19: Expense Summary | I19: B25 | J19: Business Engine
A20: SAV_INC | B20: ='[FinanceOS_QA_Baseline.xlsx]Business Engine'!B28 | C20: ='[FinanceOS_v1.0-QA-RC1.xlsx]Business Engine'!B28 | D20: =IF(OR(B20="",C20=""),"",IF(AND(ISNUMBER(B20),ISNUMBER(C20)),C20-B20,IF(B20=C20,0,"≠"))) | E20: =IF(AND(OR($J$7="Completed",$J$7="Reconciled"),$J$6="Income",$J$9),$J$3,0) | F20: =IF(OR(B20="",C20=""),"WAIT",IF(AND(ISNUMBER(D20),ISNUMBER(E20)),IF(ABS(D20-E20)<0.005,"PASS","FAIL"),IF(D20=E20,"PASS","FAIL"))) | G20: Current Month Income | H20: Savings Summary | I20: B28 | J20: Business Engine
A21: SAV_AMT | B21: ='[FinanceOS_QA_Baseline.xlsx]Business Engine'!B29 | C21: ='[FinanceOS_v1.0-QA-RC1.xlsx]Business Engine'!B29 | D21: =IF(OR(B21="",C21=""),"",IF(AND(ISNUMBER(B21),ISNUMBER(C21)),C21-B21,IF(B21=C21,0,"≠"))) | E21: =IF(AND(OR($J$7="Completed",$J$7="Reconciled"),$J$9),IF($J$6="Income",$J$3,IF($J$6="Expense",-$J$3,0)),0) | F21: =IF(OR(B21="",C21=""),"WAIT",IF(AND(ISNUMBER(D21),ISNUMBER(E21)),IF(ABS(D21-E21)<0.005,"PASS","FAIL"),IF(D21=E21,"PASS","FAIL"))) | G21: Current Month Savings | H21: Savings Summary | I21: B29 | J21: Business Engine
A22: SAV_RATE | B22: ='[FinanceOS_QA_Baseline.xlsx]Business Engine'!B30 | C22: ='[FinanceOS_v1.0-QA-RC1.xlsx]Business Engine'!B30 | D22: =IF(OR(B22="",C22=""),"",IF(AND(ISNUMBER(B22),ISNUMBER(C22)),C22-B22,IF(B22=C22,0,"≠"))) | E22: =0 | F22: =IF(OR(B22="",C22=""),"WAIT",IF(AND(ISNUMBER(D22),ISNUMBER(E22)),IF(ABS(D22-E22)<0.005,"PASS","FAIL"),IF(D22=E22,"PASS","FAIL"))) | G22: Savings Rate (%) | H22: Savings Summary | I22: B30 | J22: Business Engine
A23: SAV_AVG | B23: ='[FinanceOS_QA_Baseline.xlsx]Business Engine'!B31 | C23: ='[FinanceOS_v1.0-QA-RC1.xlsx]Business Engine'!B31 | D23: =IF(OR(B23="",C23=""),"",IF(AND(ISNUMBER(B23),ISNUMBER(C23)),C23-B23,IF(B23=C23,0,"≠"))) | E23: =0 | F23: =IF(OR(B23="",C23=""),"WAIT",IF(AND(ISNUMBER(D23),ISNUMBER(E23)),IF(ABS(D23-E23)<0.005,"PASS","FAIL"),IF(D23=E23,"PASS","FAIL"))) | G23: Average Monthly Savings | H23: Savings Summary | I23: B31 | J23: Business Engine
A24: AST_PUR | B24: ='[FinanceOS_QA_Baseline.xlsx]Business Engine'!B34 | C24: ='[FinanceOS_v1.0-QA-RC1.xlsx]Business Engine'!B34 | D24: =IF(OR(B24="",C24=""),"",IF(AND(ISNUMBER(B24),ISNUMBER(C24)),C24-B24,IF(B24=C24,0,"≠"))) | E24: =0 | F24: =IF(OR(B24="",C24=""),"WAIT",IF(AND(ISNUMBER(D24),ISNUMBER(E24)),IF(ABS(D24-E24)<0.005,"PASS","FAIL"),IF(D24=E24,"PASS","FAIL"))) | G24: Total Purchase Value | H24: Asset Summary | I24: B34 | J24: Business Engine
A25: AST_CUR | B25: ='[FinanceOS_QA_Baseline.xlsx]Business Engine'!B35 | C25: ='[FinanceOS_v1.0-QA-RC1.xlsx]Business Engine'!B35 | D25: =IF(OR(B25="",C25=""),"",IF(AND(ISNUMBER(B25),ISNUMBER(C25)),C25-B25,IF(B25=C25,0,"≠"))) | E25: =0 | F25: =IF(OR(B25="",C25=""),"WAIT",IF(AND(ISNUMBER(D25),ISNUMBER(E25)),IF(ABS(D25-E25)<0.005,"PASS","FAIL"),IF(D25=E25,"PASS","FAIL"))) | G25: Total Current Value | H25: Asset Summary | I25: B35 | J25: Business Engine
A26: AST_APP | B26: ='[FinanceOS_QA_Baseline.xlsx]Business Engine'!B36 | C26: ='[FinanceOS_v1.0-QA-RC1.xlsx]Business Engine'!B36 | D26: =IF(OR(B26="",C26=""),"",IF(AND(ISNUMBER(B26),ISNUMBER(C26)),C26-B26,IF(B26=C26,0,"≠"))) | E26: =0 | F26: =IF(OR(B26="",C26=""),"WAIT",IF(AND(ISNUMBER(D26),ISNUMBER(E26)),IF(ABS(D26-E26)<0.005,"PASS","FAIL"),IF(D26=E26,"PASS","FAIL"))) | G26: Total Appreciation Amount | H26: Asset Summary | I26: B36 | J26: Business Engine
A27: AST_PCT | B27: ='[FinanceOS_QA_Baseline.xlsx]Business Engine'!B37 | C27: ='[FinanceOS_v1.0-QA-RC1.xlsx]Business Engine'!B37 | D27: =IF(OR(B27="",C27=""),"",IF(AND(ISNUMBER(B27),ISNUMBER(C27)),C27-B27,IF(B27=C27,0,"≠"))) | E27: =0 | F27: =IF(OR(B27="",C27=""),"WAIT",IF(AND(ISNUMBER(D27),ISNUMBER(E27)),IF(ABS(D27-E27)<0.005,"PASS","FAIL"),IF(D27=E27,"PASS","FAIL"))) | G27: Weighted Appreciation % | H27: Asset Summary | I27: B37 | J27: Business Engine
A28: AST_N | B28: ='[FinanceOS_QA_Baseline.xlsx]Business Engine'!B38 | C28: ='[FinanceOS_v1.0-QA-RC1.xlsx]Business Engine'!B38 | D28: =IF(OR(B28="",C28=""),"",IF(AND(ISNUMBER(B28),ISNUMBER(C28)),C28-B28,IF(B28=C28,0,"≠"))) | E28: =0 | F28: =IF(OR(B28="",C28=""),"WAIT",IF(AND(ISNUMBER(D28),ISNUMBER(E28)),IF(ABS(D28-E28)<0.005,"PASS","FAIL"),IF(D28=E28,"PASS","FAIL"))) | G28: Active Asset Count | H28: Asset Summary | I28: B38 | J28: Business Engine
A29: LIA_ORIG | B29: ='[FinanceOS_QA_Baseline.xlsx]Business Engine'!B41 | C29: ='[FinanceOS_v1.0-QA-RC1.xlsx]Business Engine'!B41 | D29: =IF(OR(B29="",C29=""),"",IF(AND(ISNUMBER(B29),ISNUMBER(C29)),C29-B29,IF(B29=C29,0,"≠"))) | E29: =0 | F29: =IF(OR(B29="",C29=""),"WAIT",IF(AND(ISNUMBER(D29),ISNUMBER(E29)),IF(ABS(D29-E29)<0.005,"PASS","FAIL"),IF(D29=E29,"PASS","FAIL"))) | G29: Total Original Liability | H29: Liability Summary | I29: B41 | J29: Business Engine
A30: LIA_OUT | B30: ='[FinanceOS_QA_Baseline.xlsx]Business Engine'!B42 | C30: ='[FinanceOS_v1.0-QA-RC1.xlsx]Business Engine'!B42 | D30: =IF(OR(B30="",C30=""),"",IF(AND(ISNUMBER(B30),ISNUMBER(C30)),C30-B30,IF(B30=C30,0,"≠"))) | E30: =0 | F30: =IF(OR(B30="",C30=""),"WAIT",IF(AND(ISNUMBER(D30),ISNUMBER(E30)),IF(ABS(D30-E30)<0.005,"PASS","FAIL"),IF(D30=E30,"PASS","FAIL"))) | G30: Total Outstanding Balance | H30: Liability Summary | I30: B42 | J30: Business Engine
A31: LIA_EMI | B31: ='[FinanceOS_QA_Baseline.xlsx]Business Engine'!B43 | C31: ='[FinanceOS_v1.0-QA-RC1.xlsx]Business Engine'!B43 | D31: =IF(OR(B31="",C31=""),"",IF(AND(ISNUMBER(B31),ISNUMBER(C31)),C31-B31,IF(B31=C31,0,"≠"))) | E31: =0 | F31: =IF(OR(B31="",C31=""),"WAIT",IF(AND(ISNUMBER(D31),ISNUMBER(E31)),IF(ABS(D31-E31)<0.005,"PASS","FAIL"),IF(D31=E31,"PASS","FAIL"))) | G31: Total Monthly EMI | H31: Liability Summary | I31: B43 | J31: Business Engine
A32: LIA_INT | B32: ='[FinanceOS_QA_Baseline.xlsx]Business Engine'!B44 | C32: ='[FinanceOS_v1.0-QA-RC1.xlsx]Business Engine'!B44 | D32: =IF(OR(B32="",C32=""),"",IF(AND(ISNUMBER(B32),ISNUMBER(C32)),C32-B32,IF(B32=C32,0,"≠"))) | E32: =0 | F32: =IF(OR(B32="",C32=""),"WAIT",IF(AND(ISNUMBER(D32),ISNUMBER(E32)),IF(ABS(D32-E32)<0.005,"PASS","FAIL"),IF(D32=E32,"PASS","FAIL"))) | G32: Weighted Interest Rate | H32: Liability Summary | I32: B44 | J32: Business Engine
A33: LIA_N | B33: ='[FinanceOS_QA_Baseline.xlsx]Business Engine'!B45 | C33: ='[FinanceOS_v1.0-QA-RC1.xlsx]Business Engine'!B45 | D33: =IF(OR(B33="",C33=""),"",IF(AND(ISNUMBER(B33),ISNUMBER(C33)),C33-B33,IF(B33=C33,0,"≠"))) | E33: =0 | F33: =IF(OR(B33="",C33=""),"WAIT",IF(AND(ISNUMBER(D33),ISNUMBER(E33)),IF(ABS(D33-E33)<0.005,"PASS","FAIL"),IF(D33=E33,"PASS","FAIL"))) | G33: Active Liability Count | H33: Liability Summary | I33: B45 | J33: Business Engine
A34: NW_TOTAL | B34: ='[FinanceOS_QA_Baseline.xlsx]Business Engine'!B48 | C34: ='[FinanceOS_v1.0-QA-RC1.xlsx]Business Engine'!B48 | D34: =IF(OR(B34="",C34=""),"",IF(AND(ISNUMBER(B34),ISNUMBER(C34)),C34-B34,IF(B34=C34,0,"≠"))) | E34: =0 | F34: =IF(OR(B34="",C34=""),"WAIT",IF(AND(ISNUMBER(D34),ISNUMBER(E34)),IF(ABS(D34-E34)<0.005,"PASS","FAIL"),IF(D34=E34,"PASS","FAIL"))) | G34: Net Worth | H34: Net Worth | I34: B48 | J34: Business Engine
A35: NW_LIQ | B35: ='[FinanceOS_QA_Baseline.xlsx]Business Engine'!B49 | C35: ='[FinanceOS_v1.0-QA-RC1.xlsx]Business Engine'!B49 | D35: =IF(OR(B35="",C35=""),"",IF(AND(ISNUMBER(B35),ISNUMBER(C35)),C35-B35,IF(B35=C35,0,"≠"))) | E35: =0 | F35: =IF(OR(B35="",C35=""),"WAIT",IF(AND(ISNUMBER(D35),ISNUMBER(E35)),IF(ABS(D35-E35)<0.005,"PASS","FAIL"),IF(D35=E35,"PASS","FAIL"))) | G35: Liquid Net Worth | H35: Net Worth | I35: B49 | J35: Business Engine
A36: NW_INV | B36: ='[FinanceOS_QA_Baseline.xlsx]Business Engine'!B50 | C36: ='[FinanceOS_v1.0-QA-RC1.xlsx]Business Engine'!B50 | D36: =IF(OR(B36="",C36=""),"",IF(AND(ISNUMBER(B36),ISNUMBER(C36)),C36-B36,IF(B36=C36,0,"≠"))) | E36: =0 | F36: =IF(OR(B36="",C36=""),"WAIT",IF(AND(ISNUMBER(D36),ISNUMBER(E36)),IF(ABS(D36-E36)<0.005,"PASS","FAIL"),IF(D36=E36,"PASS","FAIL"))) | G36: Invested Net Worth | H36: Net Worth | I36: B50 | J36: Business Engine
A37: GOAL_TGT | B37: ='[FinanceOS_QA_Baseline.xlsx]Business Engine'!B53 | C37: ='[FinanceOS_v1.0-QA-RC1.xlsx]Business Engine'!B53 | D37: =IF(OR(B37="",C37=""),"",IF(AND(ISNUMBER(B37),ISNUMBER(C37)),C37-B37,IF(B37=C37,0,"≠"))) | E37: =0 | F37: =IF(OR(B37="",C37=""),"WAIT",IF(AND(ISNUMBER(D37),ISNUMBER(E37)),IF(ABS(D37-E37)<0.005,"PASS","FAIL"),IF(D37=E37,"PASS","FAIL"))) | G37: Total Goal Target Amount | H37: Goal Summary | I37: B53 | J37: Business Engine
A38: GOAL_SAV | B38: ='[FinanceOS_QA_Baseline.xlsx]Business Engine'!B54 | C38: ='[FinanceOS_v1.0-QA-RC1.xlsx]Business Engine'!B54 | D38: =IF(OR(B38="",C38=""),"",IF(AND(ISNUMBER(B38),ISNUMBER(C38)),C38-B38,IF(B38=C38,0,"≠"))) | E38: =0 | F38: =IF(OR(B38="",C38=""),"WAIT",IF(AND(ISNUMBER(D38),ISNUMBER(E38)),IF(ABS(D38-E38)<0.005,"PASS","FAIL"),IF(D38=E38,"PASS","FAIL"))) | G38: Total Saved Toward Goals | H38: Goal Summary | I38: B54 | J38: Business Engine
A39: GOAL_REM | B39: ='[FinanceOS_QA_Baseline.xlsx]Business Engine'!B55 | C39: ='[FinanceOS_v1.0-QA-RC1.xlsx]Business Engine'!B55 | D39: =IF(OR(B39="",C39=""),"",IF(AND(ISNUMBER(B39),ISNUMBER(C39)),C39-B39,IF(B39=C39,0,"≠"))) | E39: =0 | F39: =IF(OR(B39="",C39=""),"WAIT",IF(AND(ISNUMBER(D39),ISNUMBER(E39)),IF(ABS(D39-E39)<0.005,"PASS","FAIL"),IF(D39=E39,"PASS","FAIL"))) | G39: Remaining Goal Amount | H39: Goal Summary | I39: B55 | J39: Business Engine
A40: GOAL_ACT | B40: ='[FinanceOS_QA_Baseline.xlsx]Business Engine'!B56 | C40: ='[FinanceOS_v1.0-QA-RC1.xlsx]Business Engine'!B56 | D40: =IF(OR(B40="",C40=""),"",IF(AND(ISNUMBER(B40),ISNUMBER(C40)),C40-B40,IF(B40=C40,0,"≠"))) | E40: =0 | F40: =IF(OR(B40="",C40=""),"WAIT",IF(AND(ISNUMBER(D40),ISNUMBER(E40)),IF(ABS(D40-E40)<0.005,"PASS","FAIL"),IF(D40=E40,"PASS","FAIL"))) | G40: Active Goal Count | H40: Goal Summary | I40: B56 | J40: Business Engine
...

Sheet Cell Regression
A1: Cell | B1: Sheet | C1: Formula (QA-RC1 FORMULATEXT) | D1: Value Baseline | E1: Value QA-RC1 | F1: Changed? | G1: Expected to change? | H1: PASS / FAIL
A2: B4 | B2: Business Engine | C2: =IFERROR(FORMULATEXT('[FinanceOS_v1.0-QA-RC1.xlsx]Business Engine'!B4),"(value/no formula)") | D2: ='Difference Engine'!B2 | E2: ='Difference Engine'!C2 | F2: =IF(OR(D2="",E2=""),"WAIT",IF(AND(ISNUMBER(D2),ISNUMBER(E2)),IF(ABS(E2-D2)>0.005,"YES","NO"),IF(D2=E2,"NO","YES"))) | G2: =IF(AND(ISNUMBER('Difference Engine'!E2),ABS('Difference Engine'!E2)>0.005),"YES","NO") | H2: =IF(OR(F2="WAIT",D2=""),"WAIT",IF(F2=G2,"PASS","FAIL"))
A3: B5 | B3: Business Engine | C3: =IFERROR(FORMULATEXT('[FinanceOS_v1.0-QA-RC1.xlsx]Business Engine'!B5),"(value/no formula)") | D3: ='Difference Engine'!B3 | E3: ='Difference Engine'!C3 | F3: =IF(OR(D3="",E3=""),"WAIT",IF(AND(ISNUMBER(D3),ISNUMBER(E3)),IF(ABS(E3-D3)>0.005,"YES","NO"),IF(D3=E3,"NO","YES"))) | G3: =IF(AND(ISNUMBER('Difference Engine'!E3),ABS('Difference Engine'!E3)>0.005),"YES","NO") | H3: =IF(OR(F3="WAIT",D3=""),"WAIT",IF(F3=G3,"PASS","FAIL"))
A4: B6 | B4: Business Engine | C4: =IFERROR(FORMULATEXT('[FinanceOS_v1.0-QA-RC1.xlsx]Business Engine'!B6),"(value/no formula)") | D4: ='Difference Engine'!B4 | E4: ='Difference Engine'!C4 | F4: =IF(OR(D4="",E4=""),"WAIT",IF(AND(ISNUMBER(D4),ISNUMBER(E4)),IF(ABS(E4-D4)>0.005,"YES","NO"),IF(D4=E4,"NO","YES"))) | G4: =IF(AND(ISNUMBER('Difference Engine'!E4),ABS('Difference Engine'!E4)>0.005),"YES","NO") | H4: =IF(OR(F4="WAIT",D4=""),"WAIT",IF(F4=G4,"PASS","FAIL"))
A5: B7 | B5: Business Engine | C5: =IFERROR(FORMULATEXT('[FinanceOS_v1.0-QA-RC1.xlsx]Business Engine'!B7),"(value/no formula)") | D5: ='Difference Engine'!B5 | E5: ='Difference Engine'!C5 | F5: =IF(OR(D5="",E5=""),"WAIT",IF(AND(ISNUMBER(D5),ISNUMBER(E5)),IF(ABS(E5-D5)>0.005,"YES","NO"),IF(D5=E5,"NO","YES"))) | G5: =IF(AND(ISNUMBER('Difference Engine'!E5),ABS('Difference Engine'!E5)>0.005),"YES","NO") | H5: =IF(OR(F5="WAIT",D5=""),"WAIT",IF(F5=G5,"PASS","FAIL"))
A6: B8 | B6: Business Engine | C6: =IFERROR(FORMULATEXT('[FinanceOS_v1.0-QA-RC1.xlsx]Business Engine'!B8),"(value/no formula)") | D6: ='Difference Engine'!B6 | E6: ='Difference Engine'!C6 | F6: =IF(OR(D6="",E6=""),"WAIT",IF(AND(ISNUMBER(D6),ISNUMBER(E6)),IF(ABS(E6-D6)>0.005,"YES","NO"),IF(D6=E6,"NO","YES"))) | G6: =IF(AND(ISNUMBER('Difference Engine'!E6),ABS('Difference Engine'!E6)>0.005),"YES","NO") | H6: =IF(OR(F6="WAIT",D6=""),"WAIT",IF(F6=G6,"PASS","FAIL"))
A7: B9 | B7: Business Engine | C7: =IFERROR(FORMULATEXT('[FinanceOS_v1.0-QA-RC1.xlsx]Business Engine'!B9),"(value/no formula)") | D7: ='Difference Engine'!B7 | E7: ='Difference Engine'!C7 | F7: =IF(OR(D7="",E7=""),"WAIT",IF(AND(ISNUMBER(D7),ISNUMBER(E7)),IF(ABS(E7-D7)>0.005,"YES","NO"),IF(D7=E7,"NO","YES"))) | G7: =IF(AND(ISNUMBER('Difference Engine'!E7),ABS('Difference Engine'!E7)>0.005),"YES","NO") | H7: =IF(OR(F7="WAIT",D7=""),"WAIT",IF(F7=G7,"PASS","FAIL"))
A8: B12 | B8: Business Engine | C8: =IFERROR(FORMULATEXT('[FinanceOS_v1.0-QA-RC1.xlsx]Business Engine'!B12),"(value/no formula)") | D8: ='Difference Engine'!B8 | E8: ='Difference Engine'!C8 | F8: =IF(OR(D8="",E8=""),"WAIT",IF(AND(ISNUMBER(D8),ISNUMBER(E8)),IF(ABS(E8-D8)>0.005,"YES","NO"),IF(D8=E8,"NO","YES"))) | G8: =IF(AND(ISNUMBER('Difference Engine'!E8),ABS('Difference Engine'!E8)>0.005),"YES","NO") | H8: =IF(OR(F8="WAIT",D8=""),"WAIT",IF(F8=G8,"PASS","FAIL"))
A9: B13 | B9: Business Engine | C9: =IFERROR(FORMULATEXT('[FinanceOS_v1.0-QA-RC1.xlsx]Business Engine'!B13),"(value/no formula)") | D9: ='Difference Engine'!B9 | E9: ='Difference Engine'!C9 | F9: =IF(OR(D9="",E9=""),"WAIT",IF(AND(ISNUMBER(D9),ISNUMBER(E9)),IF(ABS(E9-D9)>0.005,"YES","NO"),IF(D9=E9,"NO","YES"))) | G9: =IF(AND(ISNUMBER('Difference Engine'!E9),ABS('Difference Engine'!E9)>0.005),"YES","NO") | H9: =IF(OR(F9="WAIT",D9=""),"WAIT",IF(F9=G9,"PASS","FAIL"))
A10: B14 | B10: Business Engine | C10: =IFERROR(FORMULATEXT('[FinanceOS_v1.0-QA-RC1.xlsx]Business Engine'!B14),"(value/no formula)") | D10: ='Difference Engine'!B10 | E10: ='Difference Engine'!C10 | F10: =IF(OR(D10="",E10=""),"WAIT",IF(AND(ISNUMBER(D10),ISNUMBER(E10)),IF(ABS(E10-D10)>0.005,"YES","NO"),IF(D10=E10,"NO","YES"))) | G10: =IF(AND(ISNUMBER('Difference Engine'!E10),ABS('Difference Engine'!E10)>0.005),"YES","NO") | H10: =IF(OR(F10="WAIT",D10=""),"WAIT",IF(F10=G10,"PASS","FAIL"))
A11: B15 | B11: Business Engine | C11: =IFERROR(FORMULATEXT('[FinanceOS_v1.0-QA-RC1.xlsx]Business Engine'!B15),"(value/no formula)") | D11: ='Difference Engine'!B11 | E11: ='Difference Engine'!C11 | F11: =IF(OR(D11="",E11=""),"WAIT",IF(AND(ISNUMBER(D11),ISNUMBER(E11)),IF(ABS(E11-D11)>0.005,"YES","NO"),IF(D11=E11,"NO","YES"))) | G11: =IF(AND(ISNUMBER('Difference Engine'!E11),ABS('Difference Engine'!E11)>0.005),"YES","NO") | H11: =IF(OR(F11="WAIT",D11=""),"WAIT",IF(F11=G11,"PASS","FAIL"))
A12: B16 | B12: Business Engine | C12: =IFERROR(FORMULATEXT('[FinanceOS_v1.0-QA-RC1.xlsx]Business Engine'!B16),"(value/no formula)") | D12: ='Difference Engine'!B12 | E12: ='Difference Engine'!C12 | F12: =IF(OR(D12="",E12=""),"WAIT",IF(AND(ISNUMBER(D12),ISNUMBER(E12)),IF(ABS(E12-D12)>0.005,"YES","NO"),IF(D12=E12,"NO","YES"))) | G12: =IF(AND(ISNUMBER('Difference Engine'!E12),ABS('Difference Engine'!E12)>0.005),"YES","NO") | H12: =IF(OR(F12="WAIT",D12=""),"WAIT",IF(F12=G12,"PASS","FAIL"))
A13: B17 | B13: Business Engine | C13: =IFERROR(FORMULATEXT('[FinanceOS_v1.0-QA-RC1.xlsx]Business Engine'!B17),"(value/no formula)") | D13: ='Difference Engine'!B13 | E13: ='Difference Engine'!C13 | F13: =IF(OR(D13="",E13=""),"WAIT",IF(AND(ISNUMBER(D13),ISNUMBER(E13)),IF(ABS(E13-D13)>0.005,"YES","NO"),IF(D13=E13,"NO","YES"))) | G13: =IF(AND(ISNUMBER('Difference Engine'!E13),ABS('Difference Engine'!E13)>0.005),"YES","NO") | H13: =IF(OR(F13="WAIT",D13=""),"WAIT",IF(F13=G13,"PASS","FAIL"))
A14: B18 | B14: Business Engine | C14: =IFERROR(FORMULATEXT('[FinanceOS_v1.0-QA-RC1.xlsx]Business Engine'!B18),"(value/no formula)") | D14: ='Difference Engine'!B14 | E14: ='Difference Engine'!C14 | F14: =IF(OR(D14="",E14=""),"WAIT",IF(AND(ISNUMBER(D14),ISNUMBER(E14)),IF(ABS(E14-D14)>0.005,"YES","NO"),IF(D14=E14,"NO","YES"))) | G14: =IF(AND(ISNUMBER('Difference Engine'!E14),ABS('Difference Engine'!E14)>0.005),"YES","NO") | H14: =IF(OR(F14="WAIT",D14=""),"WAIT",IF(F14=G14,"PASS","FAIL"))
A15: B19 | B15: Business Engine | C15: =IFERROR(FORMULATEXT('[FinanceOS_v1.0-QA-RC1.xlsx]Business Engine'!B19),"(value/no formula)") | D15: ='Difference Engine'!B15 | E15: ='Difference Engine'!C15 | F15: =IF(OR(D15="",E15=""),"WAIT",IF(AND(ISNUMBER(D15),ISNUMBER(E15)),IF(ABS(E15-D15)>0.005,"YES","NO"),IF(D15=E15,"NO","YES"))) | G15: =IF(AND(ISNUMBER('Difference Engine'!E15),ABS('Difference Engine'!E15)>0.005),"YES","NO") | H15: =IF(OR(F15="WAIT",D15=""),"WAIT",IF(F15=G15,"PASS","FAIL"))
A16: B22 | B16: Business Engine | C16: =IFERROR(FORMULATEXT('[FinanceOS_v1.0-QA-RC1.xlsx]Business Engine'!B22),"(value/no formula)") | D16: ='Difference Engine'!B16 | E16: ='Difference Engine'!C16 | F16: =IF(OR(D16="",E16=""),"WAIT",IF(AND(ISNUMBER(D16),ISNUMBER(E16)),IF(ABS(E16-D16)>0.005,"YES","NO"),IF(D16=E16,"NO","YES"))) | G16: =IF(AND(ISNUMBER('Difference Engine'!E16),ABS('Difference Engine'!E16)>0.005),"YES","NO") | H16: =IF(OR(F16="WAIT",D16=""),"WAIT",IF(F16=G16,"PASS","FAIL"))
A17: B23 | B17: Business Engine | C17: =IFERROR(FORMULATEXT('[FinanceOS_v1.0-QA-RC1.xlsx]Business Engine'!B23),"(value/no formula)") | D17: ='Difference Engine'!B17 | E17: ='Difference Engine'!C17 | F17: =IF(OR(D17="",E17=""),"WAIT",IF(AND(ISNUMBER(D17),ISNUMBER(E17)),IF(ABS(E17-D17)>0.005,"YES","NO"),IF(D17=E17,"NO","YES"))) | G17: =IF(AND(ISNUMBER('Difference Engine'!E17),ABS('Difference Engine'!E17)>0.005),"YES","NO") | H17: =IF(OR(F17="WAIT",D17=""),"WAIT",IF(F17=G17,"PASS","FAIL"))
A18: B24 | B18: Business Engine | C18: =IFERROR(FORMULATEXT('[FinanceOS_v1.0-QA-RC1.xlsx]Business Engine'!B24),"(value/no formula)") | D18: ='Difference Engine'!B18 | E18: ='Difference Engine'!C18 | F18: =IF(OR(D18="",E18=""),"WAIT",IF(AND(ISNUMBER(D18),ISNUMBER(E18)),IF(ABS(E18-D18)>0.005,"YES","NO"),IF(D18=E18,"NO","YES"))) | G18: =IF(AND(ISNUMBER('Difference Engine'!E18),ABS('Difference Engine'!E18)>0.005),"YES","NO") | H18: =IF(OR(F18="WAIT",D18=""),"WAIT",IF(F18=G18,"PASS","FAIL"))
A19: B25 | B19: Business Engine | C19: =IFERROR(FORMULATEXT('[FinanceOS_v1.0-QA-RC1.xlsx]Business Engine'!B25),"(value/no formula)") | D19: ='Difference Engine'!B19 | E19: ='Difference Engine'!C19 | F19: =IF(OR(D19="",E19=""),"WAIT",IF(AND(ISNUMBER(D19),ISNUMBER(E19)),IF(ABS(E19-D19)>0.005,"YES","NO"),IF(D19=E19,"NO","YES"))) | G19: =IF(AND(ISNUMBER('Difference Engine'!E19),ABS('Difference Engine'!E19)>0.005),"YES","NO") | H19: =IF(OR(F19="WAIT",D19=""),"WAIT",IF(F19=G19,"PASS","FAIL"))
A20: B28 | B20: Business Engine | C20: =IFERROR(FORMULATEXT('[FinanceOS_v1.0-QA-RC1.xlsx]Business Engine'!B28),"(value/no formula)") | D20: ='Difference Engine'!B20 | E20: ='Difference Engine'!C20 | F20: =IF(OR(D20="",E20=""),"WAIT",IF(AND(ISNUMBER(D20),ISNUMBER(E20)),IF(ABS(E20-D20)>0.005,"YES","NO"),IF(D20=E20,"NO","YES"))) | G20: =IF(AND(ISNUMBER('Difference Engine'!E20),ABS('Difference Engine'!E20)>0.005),"YES","NO") | H20: =IF(OR(F20="WAIT",D20=""),"WAIT",IF(F20=G20,"PASS","FAIL"))
A21: B29 | B21: Business Engine | C21: =IFERROR(FORMULATEXT('[FinanceOS_v1.0-QA-RC1.xlsx]Business Engine'!B29),"(value/no formula)") | D21: ='Difference Engine'!B21 | E21: ='Difference Engine'!C21 | F21: =IF(OR(D21="",E21=""),"WAIT",IF(AND(ISNUMBER(D21),ISNUMBER(E21)),IF(ABS(E21-D21)>0.005,"YES","NO"),IF(D21=E21,"NO","YES"))) | G21: =IF(AND(ISNUMBER('Difference Engine'!E21),ABS('Difference Engine'!E21)>0.005),"YES","NO") | H21: =IF(OR(F21="WAIT",D21=""),"WAIT",IF(F21=G21,"PASS","FAIL"))
A22: B30 | B22: Business Engine | C22: =IFERROR(FORMULATEXT('[FinanceOS_v1.0-QA-RC1.xlsx]Business Engine'!B30),"(value/no formula)") | D22: ='Difference Engine'!B22 | E22: ='Difference Engine'!C22 | F22: =IF(OR(D22="",E22=""),"WAIT",IF(AND(ISNUMBER(D22),ISNUMBER(E22)),IF(ABS(E22-D22)>0.005,"YES","NO"),IF(D22=E22,"NO","YES"))) | G22: =IF(AND(ISNUMBER('Difference Engine'!E22),ABS('Difference Engine'!E22)>0.005),"YES","NO") | H22: =IF(OR(F22="WAIT",D22=""),"WAIT",IF(F22=G22,"PASS","FAIL"))
A23: B31 | B23: Business Engine | C23: =IFERROR(FORMULATEXT('[FinanceOS_v1.0-QA-RC1.xlsx]Business Engine'!B31),"(value/no formula)") | D23: ='Difference Engine'!B23 | E23: ='Difference Engine'!C23 | F23: =IF(OR(D23="",E23=""),"WAIT",IF(AND(ISNUMBER(D23),ISNUMBER(E23)),IF(ABS(E23-D23)>0.005,"YES","NO"),IF(D23=E23,"NO","YES"))) | G23: =IF(AND(ISNUMBER('Difference Engine'!E23),ABS('Difference Engine'!E23)>0.005),"YES","NO") | H23: =IF(OR(F23="WAIT",D23=""),"WAIT",IF(F23=G23,"PASS","FAIL"))
A24: B34 | B24: Business Engine | C24: =IFERROR(FORMULATEXT('[FinanceOS_v1.0-QA-RC1.xlsx]Business Engine'!B34),"(value/no formula)") | D24: ='Difference Engine'!B24 | E24: ='Difference Engine'!C24 | F24: =IF(OR(D24="",E24=""),"WAIT",IF(AND(ISNUMBER(D24),ISNUMBER(E24)),IF(ABS(E24-D24)>0.005,"YES","NO"),IF(D24=E24,"NO","YES"))) | G24: =IF(AND(ISNUMBER('Difference Engine'!E24),ABS('Difference Engine'!E24)>0.005),"YES","NO") | H24: =IF(OR(F24="WAIT",D24=""),"WAIT",IF(F24=G24,"PASS","FAIL"))
A25: B35 | B25: Business Engine | C25: =IFERROR(FORMULATEXT('[FinanceOS_v1.0-QA-RC1.xlsx]Business Engine'!B35),"(value/no formula)") | D25: ='Difference Engine'!B25 | E25: ='Difference Engine'!C25 | F25: =IF(OR(D25="",E25=""),"WAIT",IF(AND(ISNUMBER(D25),ISNUMBER(E25)),IF(ABS(E25-D25)>0.005,"YES","NO"),IF(D25=E25,"NO","YES"))) | G25: =IF(AND(ISNUMBER('Difference Engine'!E25),ABS('Difference Engine'!E25)>0.005),"YES","NO") | H25: =IF(OR(F25="WAIT",D25=""),"WAIT",IF(F25=G25,"PASS","FAIL"))
A26: B36 | B26: Business Engine | C26: =IFERROR(FORMULATEXT('[FinanceOS_v1.0-QA-RC1.xlsx]Business Engine'!B36),"(value/no formula)") | D26: ='Difference Engine'!B26 | E26: ='Difference Engine'!C26 | F26: =IF(OR(D26="",E26=""),"WAIT",IF(AND(ISNUMBER(D26),ISNUMBER(E26)),IF(ABS(E26-D26)>0.005,"YES","NO"),IF(D26=E26,"NO","YES"))) | G26: =IF(AND(ISNUMBER('Difference Engine'!E26),ABS('Difference Engine'!E26)>0.005),"YES","NO") | H26: =IF(OR(F26="WAIT",D26=""),"WAIT",IF(F26=G26,"PASS","FAIL"))
A27: B37 | B27: Business Engine | C27: =IFERROR(FORMULATEXT('[FinanceOS_v1.0-QA-RC1.xlsx]Business Engine'!B37),"(value/no formula)") | D27: ='Difference Engine'!B27 | E27: ='Difference Engine'!C27 | F27: =IF(OR(D27="",E27=""),"WAIT",IF(AND(ISNUMBER(D27),ISNUMBER(E27)),IF(ABS(E27-D27)>0.005,"YES","NO"),IF(D27=E27,"NO","YES"))) | G27: =IF(AND(ISNUMBER('Difference Engine'!E27),ABS('Difference Engine'!E27)>0.005),"YES","NO") | H27: =IF(OR(F27="WAIT",D27=""),"WAIT",IF(F27=G27,"PASS","FAIL"))
A28: B38 | B28: Business Engine | C28: =IFERROR(FORMULATEXT('[FinanceOS_v1.0-QA-RC1.xlsx]Business Engine'!B38),"(value/no formula)") | D28: ='Difference Engine'!B28 | E28: ='Difference Engine'!C28 | F28: =IF(OR(D28="",E28=""),"WAIT",IF(AND(ISNUMBER(D28),ISNUMBER(E28)),IF(ABS(E28-D28)>0.005,"YES","NO"),IF(D28=E28,"NO","YES"))) | G28: =IF(AND(ISNUMBER('Difference Engine'!E28),ABS('Difference Engine'!E28)>0.005),"YES","NO") | H28: =IF(OR(F28="WAIT",D28=""),"WAIT",IF(F28=G28,"PASS","FAIL"))
A29: B41 | B29: Business Engine | C29: =IFERROR(FORMULATEXT('[FinanceOS_v1.0-QA-RC1.xlsx]Business Engine'!B41),"(value/no formula)") | D29: ='Difference Engine'!B29 | E29: ='Difference Engine'!C29 | F29: =IF(OR(D29="",E29=""),"WAIT",IF(AND(ISNUMBER(D29),ISNUMBER(E29)),IF(ABS(E29-D29)>0.005,"YES","NO"),IF(D29=E29,"NO","YES"))) | G29: =IF(AND(ISNUMBER('Difference Engine'!E29),ABS('Difference Engine'!E29)>0.005),"YES","NO") | H29: =IF(OR(F29="WAIT",D29=""),"WAIT",IF(F29=G29,"PASS","FAIL"))
A30: B42 | B30: Business Engine | C30: =IFERROR(FORMULATEXT('[FinanceOS_v1.0-QA-RC1.xlsx]Business Engine'!B42),"(value/no formula)") | D30: ='Difference Engine'!B30 | E30: ='Difference Engine'!C30 | F30: =IF(OR(D30="",E30=""),"WAIT",IF(AND(ISNUMBER(D30),ISNUMBER(E30)),IF(ABS(E30-D30)>0.005,"YES","NO"),IF(D30=E30,"NO","YES"))) | G30: =IF(AND(ISNUMBER('Difference Engine'!E30),ABS('Difference Engine'!E30)>0.005),"YES","NO") | H30: =IF(OR(F30="WAIT",D30=""),"WAIT",IF(F30=G30,"PASS","FAIL"))
A31: B43 | B31: Business Engine | C31: =IFERROR(FORMULATEXT('[FinanceOS_v1.0-QA-RC1.xlsx]Business Engine'!B43),"(value/no formula)") | D31: ='Difference Engine'!B31 | E31: ='Difference Engine'!C31 | F31: =IF(OR(D31="",E31=""),"WAIT",IF(AND(ISNUMBER(D31),ISNUMBER(E31)),IF(ABS(E31-D31)>0.005,"YES","NO"),IF(D31=E31,"NO","YES"))) | G31: =IF(AND(ISNUMBER('Difference Engine'!E31),ABS('Difference Engine'!E31)>0.005),"YES","NO") | H31: =IF(OR(F31="WAIT",D31=""),"WAIT",IF(F31=G31,"PASS","FAIL"))
A32: B44 | B32: Business Engine | C32: =IFERROR(FORMULATEXT('[FinanceOS_v1.0-QA-RC1.xlsx]Business Engine'!B44),"(value/no formula)") | D32: ='Difference Engine'!B32 | E32: ='Difference Engine'!C32 | F32: =IF(OR(D32="",E32=""),"WAIT",IF(AND(ISNUMBER(D32),ISNUMBER(E32)),IF(ABS(E32-D32)>0.005,"YES","NO"),IF(D32=E32,"NO","YES"))) | G32: =IF(AND(ISNUMBER('Difference Engine'!E32),ABS('Difference Engine'!E32)>0.005),"YES","NO") | H32: =IF(OR(F32="WAIT",D32=""),"WAIT",IF(F32=G32,"PASS","FAIL"))
A33: B45 | B33: Business Engine | C33: =IFERROR(FORMULATEXT('[FinanceOS_v1.0-QA-RC1.xlsx]Business Engine'!B45),"(value/no formula)") | D33: ='Difference Engine'!B33 | E33: ='Difference Engine'!C33 | F33: =IF(OR(D33="",E33=""),"WAIT",IF(AND(ISNUMBER(D33),ISNUMBER(E33)),IF(ABS(E33-D33)>0.005,"YES","NO"),IF(D33=E33,"NO","YES"))) | G33: =IF(AND(ISNUMBER('Difference Engine'!E33),ABS('Difference Engine'!E33)>0.005),"YES","NO") | H33: =IF(OR(F33="WAIT",D33=""),"WAIT",IF(F33=G33,"PASS","FAIL"))
A34: B48 | B34: Business Engine | C34: =IFERROR(FORMULATEXT('[FinanceOS_v1.0-QA-RC1.xlsx]Business Engine'!B48),"(value/no formula)") | D34: ='Difference Engine'!B34 | E34: ='Difference Engine'!C34 | F34: =IF(OR(D34="",E34=""),"WAIT",IF(AND(ISNUMBER(D34),ISNUMBER(E34)),IF(ABS(E34-D34)>0.005,"YES","NO"),IF(D34=E34,"NO","YES"))) | G34: =IF(AND(ISNUMBER('Difference Engine'!E34),ABS('Difference Engine'!E34)>0.005),"YES","NO") | H34: =IF(OR(F34="WAIT",D34=""),"WAIT",IF(F34=G34,"PASS","FAIL"))
A35: B49 | B35: Business Engine | C35: =IFERROR(FORMULATEXT('[FinanceOS_v1.0-QA-RC1.xlsx]Business Engine'!B49),"(value/no formula)") | D35: ='Difference Engine'!B35 | E35: ='Difference Engine'!C35 | F35: =IF(OR(D35="",E35=""),"WAIT",IF(AND(ISNUMBER(D35),ISNUMBER(E35)),IF(ABS(E35-D35)>0.005,"YES","NO"),IF(D35=E35,"NO","YES"))) | G35: =IF(AND(ISNUMBER('Difference Engine'!E35),ABS('Difference Engine'!E35)>0.005),"YES","NO") | H35: =IF(OR(F35="WAIT",D35=""),"WAIT",IF(F35=G35,"PASS","FAIL"))
A36: B50 | B36: Business Engine | C36: =IFERROR(FORMULATEXT('[FinanceOS_v1.0-QA-RC1.xlsx]Business Engine'!B50),"(value/no formula)") | D36: ='Difference Engine'!B36 | E36: ='Difference Engine'!C36 | F36: =IF(OR(D36="",E36=""),"WAIT",IF(AND(ISNUMBER(D36),ISNUMBER(E36)),IF(ABS(E36-D36)>0.005,"YES","NO"),IF(D36=E36,"NO","YES"))) | G36: =IF(AND(ISNUMBER('Difference Engine'!E36),ABS('Difference Engine'!E36)>0.005),"YES","NO") | H36: =IF(OR(F36="WAIT",D36=""),"WAIT",IF(F36=G36,"PASS","FAIL"))
A37: B53 | B37: Business Engine | C37: =IFERROR(FORMULATEXT('[FinanceOS_v1.0-QA-RC1.xlsx]Business Engine'!B53),"(value/no formula)") | D37: ='Difference Engine'!B37 | E37: ='Difference Engine'!C37 | F37: =IF(OR(D37="",E37=""),"WAIT",IF(AND(ISNUMBER(D37),ISNUMBER(E37)),IF(ABS(E37-D37)>0.005,"YES","NO"),IF(D37=E37,"NO","YES"))) | G37: =IF(AND(ISNUMBER('Difference Engine'!E37),ABS('Difference Engine'!E37)>0.005),"YES","NO") | H37: =IF(OR(F37="WAIT",D37=""),"WAIT",IF(F37=G37,"PASS","FAIL"))
A38: B54 | B38: Business Engine | C38: =IFERROR(FORMULATEXT('[FinanceOS_v1.0-QA-RC1.xlsx]Business Engine'!B54),"(value/no formula)") | D38: ='Difference Engine'!B38 | E38: ='Difference Engine'!C38 | F38: =IF(OR(D38="",E38=""),"WAIT",IF(AND(ISNUMBER(D38),ISNUMBER(E38)),IF(ABS(E38-D38)>0.005,"YES","NO"),IF(D38=E38,"NO","YES"))) | G38: =IF(AND(ISNUMBER('Difference Engine'!E38),ABS('Difference Engine'!E38)>0.005),"YES","NO") | H38: =IF(OR(F38="WAIT",D38=""),"WAIT",IF(F38=G38,"PASS","FAIL"))
A39: B55 | B39: Business Engine | C39: =IFERROR(FORMULATEXT('[FinanceOS_v1.0-QA-RC1.xlsx]Business Engine'!B55),"(value/no formula)") | D39: ='Difference Engine'!B39 | E39: ='Difference Engine'!C39 | F39: =IF(OR(D39="",E39=""),"WAIT",IF(AND(ISNUMBER(D39),ISNUMBER(E39)),IF(ABS(E39-D39)>0.005,"YES","NO"),IF(D39=E39,"NO","YES"))) | G39: =IF(AND(ISNUMBER('Difference Engine'!E39),ABS('Difference Engine'!E39)>0.005),"YES","NO") | H39: =IF(OR(F39="WAIT",D39=""),"WAIT",IF(F39=G39,"PASS","FAIL"))
A40: B56 | B40: Business Engine | C40: =IFERROR(FORMULATEXT('[FinanceOS_v1.0-QA-RC1.xlsx]Business Engine'!B56),"(value/no formula)") | D40: ='Difference Engine'!B40 | E40: ='Difference Engine'!C40 | F40: =IF(OR(D40="",E40=""),"WAIT",IF(AND(ISNUMBER(D40),ISNUMBER(E40)),IF(ABS(E40-D40)>0.005,"YES","NO"),IF(D40=E40,"NO","YES"))) | G40: =IF(AND(ISNUMBER('Difference Engine'!E40),ABS('Difference Engine'!E40)>0.005),"YES","NO") | H40: =IF(OR(F40="WAIT",D40=""),"WAIT",IF(F40=G40,"PASS","FAIL"))
...

Sheet Coverage Matrix
A1: Business Engine Section | B1: Formula Range | C1: Cells | D1: Tested By Scenario IDs | E1: Coverage Status
A2: Accounts Summary | B2: B4:B9 | C2: 6 | D2: SCN-BASE, SCN-C, SCN-I, SCN-N, SCN-O | E2: BASELINE ONLY
A3: Account Engine H2/I2 | B3: not in RC1 freeze | C3: 0 | D3: SCN-K, SCN-L, SCN-M — no LAST cell on engine-foundation RC1 | E3: N/A — RC1
A4: Income Summary | B4: B12:B19 | C4: 8 | D4: SCN-BASE, SCN-A, SCN-F, SCN-P | E4: STRESSED
A5: Expense Summary | B5: B22:B25 | C5: 4 | D5: SCN-BASE, SCN-B, SCN-D, SCN-E, SCN-G, SCN-H, SCN-J (B23 must NOT change) | E5: STRESSED
A6: Savings Summary | B6: B28:B31 | C6: 4 | D6: SCN-BASE, SCN-A, SCN-B | E6: STRESSED
A7: Asset Summary | B7: B34:B38 | C7: 5 | D7: SCN-BASE, SCN-J (value table not auto) | E7: BASELINE ONLY
A8: Liability Summary | B8: B41:B45 | C8: 5 | D8: SCN-BASE | E8: BASELINE ONLY
A9: Net Worth | B9: B48:B50 | C9: 3 | D9: SCN-BASE, SCN-A, SCN-B | E9: STRESSED
A10: Goal Summary | B10: B53:B58 | C10: 6 | D10: SCN-BASE, SCN-G (saved amount not auto) | E10: BASELINE ONLY
A11: Financial Health | B11: B61:B68 | C11: 8 | D11: SCN-BASE, SCN-A, SCN-B | E11: STRESSED
A12: As-Of Date | B12: B1 | C12: 1 | D12: SCN-BASE | E12: STRESSED
A13: Analysis Engine | B13: B2:B109 | C13: 45 | D13: Follows Business Engine via links | E13: STRESSED

Sheet Compatibility Gate
A1: Compatibility Gate
A3: Platform | B3: Check | C3: Result
A4: Desktop | B4: Excel Desktop opens | C4: WAIT
A5: Excel Web | B5: Excel Web opens | C5: WAIT
A6: Mobile | B6: Excel Mobile opens | C6: WAIT
A7: Excel Web | B7: No compatibility popup | C7: WAIT
A8: Excel Web | B8: Business Engine visible | C8: WAIT
A9: Excel Web | B9: Analysis Engine visible | C9: WAIT
A10: Excel Web | B10: Workbook links working | C10: WAIT
A11: Excel Web | B11: All scenarios passed | C11: WAIT
A13: Overall Compatibility | B13: =IF(COUNTIF(C4:C11,"FAIL")>0,"FAIL",IF(COUNTIF(C4:C11,"PASS")=8,"PASS","WAIT"))

Sheet Formula Inventory
A1: Formula Inventory — QA-RC1 FORMULATEXT
A3: Cell | B3: FORMULATEXT | C3: Contains MAXIFS? | D3: Family flags | F3: Family | G3: Count
A4: B4 | B4: =IFERROR(FORMULATEXT('[FinanceOS_v1.0-QA-RC1.xlsx]Business Engine'!B4),"") | C4: =IF(ISNUMBER(SEARCH("MAXIFS",B4)),"YES","NO") | D4: =IF(ISNUMBER(SEARCH("AGGREGATE",B4)),"AGGREGATE ","")&IF(ISNUMBER(SEARCH("LOOKUP",B4)),"LOOKUP ","")&IF(ISNUMBER(SEARCH("FILTER",B4)),"FILTER ","") | F4: IF | G4: =COUNTIF(B:B,"*IF(*")
A5: B5 | B5: =IFERROR(FORMULATEXT('[FinanceOS_v1.0-QA-RC1.xlsx]Business Engine'!B5),"") | C5: =IF(ISNUMBER(SEARCH("MAXIFS",B5)),"YES","NO") | D5: =IF(ISNUMBER(SEARCH("AGGREGATE",B5)),"AGGREGATE ","")&IF(ISNUMBER(SEARCH("LOOKUP",B5)),"LOOKUP ","")&IF(ISNUMBER(SEARCH("FILTER",B5)),"FILTER ","") | F5: IFERROR | G5: =COUNTIF(B:B,"*IFERROR(*")
A6: B6 | B6: =IFERROR(FORMULATEXT('[FinanceOS_v1.0-QA-RC1.xlsx]Business Engine'!B6),"") | C6: =IF(ISNUMBER(SEARCH("MAXIFS",B6)),"YES","NO") | D6: =IF(ISNUMBER(SEARCH("AGGREGATE",B6)),"AGGREGATE ","")&IF(ISNUMBER(SEARCH("LOOKUP",B6)),"LOOKUP ","")&IF(ISNUMBER(SEARCH("FILTER",B6)),"FILTER ","") | F6: SUMIFS | G6: =COUNTIF(B:B,"*SUMIFS(*")
A7: B7 | B7: =IFERROR(FORMULATEXT('[FinanceOS_v1.0-QA-RC1.xlsx]Business Engine'!B7),"") | C7: =IF(ISNUMBER(SEARCH("MAXIFS",B7)),"YES","NO") | D7: =IF(ISNUMBER(SEARCH("AGGREGATE",B7)),"AGGREGATE ","")&IF(ISNUMBER(SEARCH("LOOKUP",B7)),"LOOKUP ","")&IF(ISNUMBER(SEARCH("FILTER",B7)),"FILTER ","") | F7: COUNTIFS | G7: =COUNTIF(B:B,"*COUNTIFS(*")
A8: B8 | B8: =IFERROR(FORMULATEXT('[FinanceOS_v1.0-QA-RC1.xlsx]Business Engine'!B8),"") | C8: =IF(ISNUMBER(SEARCH("MAXIFS",B8)),"YES","NO") | D8: =IF(ISNUMBER(SEARCH("AGGREGATE",B8)),"AGGREGATE ","")&IF(ISNUMBER(SEARCH("LOOKUP",B8)),"LOOKUP ","")&IF(ISNUMBER(SEARCH("FILTER",B8)),"FILTER ","") | F8: INDEX | G8: =COUNTIF(B:B,"*INDEX(*")
A9: B9 | B9: =IFERROR(FORMULATEXT('[FinanceOS_v1.0-QA-RC1.xlsx]Business Engine'!B9),"") | C9: =IF(ISNUMBER(SEARCH("MAXIFS",B9)),"YES","NO") | D9: =IF(ISNUMBER(SEARCH("AGGREGATE",B9)),"AGGREGATE ","")&IF(ISNUMBER(SEARCH("LOOKUP",B9)),"LOOKUP ","")&IF(ISNUMBER(SEARCH("FILTER",B9)),"FILTER ","") | F9: MATCH | G9: =COUNTIF(B:B,"*MATCH(*")
A10: B12 | B10: =IFERROR(FORMULATEXT('[FinanceOS_v1.0-QA-RC1.xlsx]Business Engine'!B12),"") | C10: =IF(ISNUMBER(SEARCH("MAXIFS",B10)),"YES","NO") | D10: =IF(ISNUMBER(SEARCH("AGGREGATE",B10)),"AGGREGATE ","")&IF(ISNUMBER(SEARCH("LOOKUP",B10)),"LOOKUP ","")&IF(ISNUMBER(SEARCH("FILTER",B10)),"FILTER ","") | F10: MAX | G10: =COUNTIF(B:B,"*MAX(*")
A11: B13 | B11: =IFERROR(FORMULATEXT('[FinanceOS_v1.0-QA-RC1.xlsx]Business Engine'!B13),"") | C11: =IF(ISNUMBER(SEARCH("MAXIFS",B11)),"YES","NO") | D11: =IF(ISNUMBER(SEARCH("AGGREGATE",B11)),"AGGREGATE ","")&IF(ISNUMBER(SEARCH("LOOKUP",B11)),"LOOKUP ","")&IF(ISNUMBER(SEARCH("FILTER",B11)),"FILTER ","") | F11: LOOKUP | G11: =COUNTIF(B:B,"*LOOKUP(*")
A12: B14 | B12: =IFERROR(FORMULATEXT('[FinanceOS_v1.0-QA-RC1.xlsx]Business Engine'!B14),"") | C12: =IF(ISNUMBER(SEARCH("MAXIFS",B12)),"YES","NO") | D12: =IF(ISNUMBER(SEARCH("AGGREGATE",B12)),"AGGREGATE ","")&IF(ISNUMBER(SEARCH("LOOKUP",B12)),"LOOKUP ","")&IF(ISNUMBER(SEARCH("FILTER",B12)),"FILTER ","") | F12: AGGREGATE | G12: =COUNTIF(B:B,"*AGGREGATE(*")
A13: B15 | B13: =IFERROR(FORMULATEXT('[FinanceOS_v1.0-QA-RC1.xlsx]Business Engine'!B15),"") | C13: =IF(ISNUMBER(SEARCH("MAXIFS",B13)),"YES","NO") | D13: =IF(ISNUMBER(SEARCH("AGGREGATE",B13)),"AGGREGATE ","")&IF(ISNUMBER(SEARCH("LOOKUP",B13)),"LOOKUP ","")&IF(ISNUMBER(SEARCH("FILTER",B13)),"FILTER ","") | F13: MAXIFS | G13: =COUNTIF(B:B,"*MAXIFS(*")
A14: B16 | B14: =IFERROR(FORMULATEXT('[FinanceOS_v1.0-QA-RC1.xlsx]Business Engine'!B16),"") | C14: =IF(ISNUMBER(SEARCH("MAXIFS",B14)),"YES","NO") | D14: =IF(ISNUMBER(SEARCH("AGGREGATE",B14)),"AGGREGATE ","")&IF(ISNUMBER(SEARCH("LOOKUP",B14)),"LOOKUP ","")&IF(ISNUMBER(SEARCH("FILTER",B14)),"FILTER ","") | F14: SUMPRODUCT | G14: =COUNTIF(B:B,"*SUMPRODUCT(*")
A15: B17 | B15: =IFERROR(FORMULATEXT('[FinanceOS_v1.0-QA-RC1.xlsx]Business Engine'!B17),"") | C15: =IF(ISNUMBER(SEARCH("MAXIFS",B15)),"YES","NO") | D15: =IF(ISNUMBER(SEARCH("AGGREGATE",B15)),"AGGREGATE ","")&IF(ISNUMBER(SEARCH("LOOKUP",B15)),"LOOKUP ","")&IF(ISNUMBER(SEARCH("FILTER",B15)),"FILTER ","")
A16: B18 | B16: =IFERROR(FORMULATEXT('[FinanceOS_v1.0-QA-RC1.xlsx]Business Engine'!B18),"") | C16: =IF(ISNUMBER(SEARCH("MAXIFS",B16)),"YES","NO") | D16: =IF(ISNUMBER(SEARCH("AGGREGATE",B16)),"AGGREGATE ","")&IF(ISNUMBER(SEARCH("LOOKUP",B16)),"LOOKUP ","")&IF(ISNUMBER(SEARCH("FILTER",B16)),"FILTER ","") | F16: MAXIFS GATE | G16: =IF(COUNTIF(C4:C53,"YES")>0,"MAXIFS PRESENT","OK — no MAXIFS")
A17: B19 | B17: =IFERROR(FORMULATEXT('[FinanceOS_v1.0-QA-RC1.xlsx]Business Engine'!B19),"") | C17: =IF(ISNUMBER(SEARCH("MAXIFS",B17)),"YES","NO") | D17: =IF(ISNUMBER(SEARCH("AGGREGATE",B17)),"AGGREGATE ","")&IF(ISNUMBER(SEARCH("LOOKUP",B17)),"LOOKUP ","")&IF(ISNUMBER(SEARCH("FILTER",B17)),"FILTER ","")
A18: B22 | B18: =IFERROR(FORMULATEXT('[FinanceOS_v1.0-QA-RC1.xlsx]Business Engine'!B22),"") | C18: =IF(ISNUMBER(SEARCH("MAXIFS",B18)),"YES","NO") | D18: =IF(ISNUMBER(SEARCH("AGGREGATE",B18)),"AGGREGATE ","")&IF(ISNUMBER(SEARCH("LOOKUP",B18)),"LOOKUP ","")&IF(ISNUMBER(SEARCH("FILTER",B18)),"FILTER ","")
A19: B23 | B19: =IFERROR(FORMULATEXT('[FinanceOS_v1.0-QA-RC1.xlsx]Business Engine'!B23),"") | C19: =IF(ISNUMBER(SEARCH("MAXIFS",B19)),"YES","NO") | D19: =IF(ISNUMBER(SEARCH("AGGREGATE",B19)),"AGGREGATE ","")&IF(ISNUMBER(SEARCH("LOOKUP",B19)),"LOOKUP ","")&IF(ISNUMBER(SEARCH("FILTER",B19)),"FILTER ","")
A20: B24 | B20: =IFERROR(FORMULATEXT('[FinanceOS_v1.0-QA-RC1.xlsx]Business Engine'!B24),"") | C20: =IF(ISNUMBER(SEARCH("MAXIFS",B20)),"YES","NO") | D20: =IF(ISNUMBER(SEARCH("AGGREGATE",B20)),"AGGREGATE ","")&IF(ISNUMBER(SEARCH("LOOKUP",B20)),"LOOKUP ","")&IF(ISNUMBER(SEARCH("FILTER",B20)),"FILTER ","")
A21: B25 | B21: =IFERROR(FORMULATEXT('[FinanceOS_v1.0-QA-RC1.xlsx]Business Engine'!B25),"") | C21: =IF(ISNUMBER(SEARCH("MAXIFS",B21)),"YES","NO") | D21: =IF(ISNUMBER(SEARCH("AGGREGATE",B21)),"AGGREGATE ","")&IF(ISNUMBER(SEARCH("LOOKUP",B21)),"LOOKUP ","")&IF(ISNUMBER(SEARCH("FILTER",B21)),"FILTER ","")
A22: B28 | B22: =IFERROR(FORMULATEXT('[FinanceOS_v1.0-QA-RC1.xlsx]Business Engine'!B28),"") | C22: =IF(ISNUMBER(SEARCH("MAXIFS",B22)),"YES","NO") | D22: =IF(ISNUMBER(SEARCH("AGGREGATE",B22)),"AGGREGATE ","")&IF(ISNUMBER(SEARCH("LOOKUP",B22)),"LOOKUP ","")&IF(ISNUMBER(SEARCH("FILTER",B22)),"FILTER ","")
A23: B29 | B23: =IFERROR(FORMULATEXT('[FinanceOS_v1.0-QA-RC1.xlsx]Business Engine'!B29),"") | C23: =IF(ISNUMBER(SEARCH("MAXIFS",B23)),"YES","NO") | D23: =IF(ISNUMBER(SEARCH("AGGREGATE",B23)),"AGGREGATE ","")&IF(ISNUMBER(SEARCH("LOOKUP",B23)),"LOOKUP ","")&IF(ISNUMBER(SEARCH("FILTER",B23)),"FILTER ","")
A24: B30 | B24: =IFERROR(FORMULATEXT('[FinanceOS_v1.0-QA-RC1.xlsx]Business Engine'!B30),"") | C24: =IF(ISNUMBER(SEARCH("MAXIFS",B24)),"YES","NO") | D24: =IF(ISNUMBER(SEARCH("AGGREGATE",B24)),"AGGREGATE ","")&IF(ISNUMBER(SEARCH("LOOKUP",B24)),"LOOKUP ","")&IF(ISNUMBER(SEARCH("FILTER",B24)),"FILTER ","")
A25: B31 | B25: =IFERROR(FORMULATEXT('[FinanceOS_v1.0-QA-RC1.xlsx]Business Engine'!B31),"") | C25: =IF(ISNUMBER(SEARCH("MAXIFS",B25)),"YES","NO") | D25: =IF(ISNUMBER(SEARCH("AGGREGATE",B25)),"AGGREGATE ","")&IF(ISNUMBER(SEARCH("LOOKUP",B25)),"LOOKUP ","")&IF(ISNUMBER(SEARCH("FILTER",B25)),"FILTER ","")
A26: B34 | B26: =IFERROR(FORMULATEXT('[FinanceOS_v1.0-QA-RC1.xlsx]Business Engine'!B34),"") | C26: =IF(ISNUMBER(SEARCH("MAXIFS",B26)),"YES","NO") | D26: =IF(ISNUMBER(SEARCH("AGGREGATE",B26)),"AGGREGATE ","")&IF(ISNUMBER(SEARCH("LOOKUP",B26)),"LOOKUP ","")&IF(ISNUMBER(SEARCH("FILTER",B26)),"FILTER ","")
A27: B35 | B27: =IFERROR(FORMULATEXT('[FinanceOS_v1.0-QA-RC1.xlsx]Business Engine'!B35),"") | C27: =IF(ISNUMBER(SEARCH("MAXIFS",B27)),"YES","NO") | D27: =IF(ISNUMBER(SEARCH("AGGREGATE",B27)),"AGGREGATE ","")&IF(ISNUMBER(SEARCH("LOOKUP",B27)),"LOOKUP ","")&IF(ISNUMBER(SEARCH("FILTER",B27)),"FILTER ","")
A28: B36 | B28: =IFERROR(FORMULATEXT('[FinanceOS_v1.0-QA-RC1.xlsx]Business Engine'!B36),"") | C28: =IF(ISNUMBER(SEARCH("MAXIFS",B28)),"YES","NO") | D28: =IF(ISNUMBER(SEARCH("AGGREGATE",B28)),"AGGREGATE ","")&IF(ISNUMBER(SEARCH("LOOKUP",B28)),"LOOKUP ","")&IF(ISNUMBER(SEARCH("FILTER",B28)),"FILTER ","")
A29: B37 | B29: =IFERROR(FORMULATEXT('[FinanceOS_v1.0-QA-RC1.xlsx]Business Engine'!B37),"") | C29: =IF(ISNUMBER(SEARCH("MAXIFS",B29)),"YES","NO") | D29: =IF(ISNUMBER(SEARCH("AGGREGATE",B29)),"AGGREGATE ","")&IF(ISNUMBER(SEARCH("LOOKUP",B29)),"LOOKUP ","")&IF(ISNUMBER(SEARCH("FILTER",B29)),"FILTER ","")
A30: B38 | B30: =IFERROR(FORMULATEXT('[FinanceOS_v1.0-QA-RC1.xlsx]Business Engine'!B38),"") | C30: =IF(ISNUMBER(SEARCH("MAXIFS",B30)),"YES","NO") | D30: =IF(ISNUMBER(SEARCH("AGGREGATE",B30)),"AGGREGATE ","")&IF(ISNUMBER(SEARCH("LOOKUP",B30)),"LOOKUP ","")&IF(ISNUMBER(SEARCH("FILTER",B30)),"FILTER ","")
A31: B41 | B31: =IFERROR(FORMULATEXT('[FinanceOS_v1.0-QA-RC1.xlsx]Business Engine'!B41),"") | C31: =IF(ISNUMBER(SEARCH("MAXIFS",B31)),"YES","NO") | D31: =IF(ISNUMBER(SEARCH("AGGREGATE",B31)),"AGGREGATE ","")&IF(ISNUMBER(SEARCH("LOOKUP",B31)),"LOOKUP ","")&IF(ISNUMBER(SEARCH("FILTER",B31)),"FILTER ","")
A32: B42 | B32: =IFERROR(FORMULATEXT('[FinanceOS_v1.0-QA-RC1.xlsx]Business Engine'!B42),"") | C32: =IF(ISNUMBER(SEARCH("MAXIFS",B32)),"YES","NO") | D32: =IF(ISNUMBER(SEARCH("AGGREGATE",B32)),"AGGREGATE ","")&IF(ISNUMBER(SEARCH("LOOKUP",B32)),"LOOKUP ","")&IF(ISNUMBER(SEARCH("FILTER",B32)),"FILTER ","")
A33: B43 | B33: =IFERROR(FORMULATEXT('[FinanceOS_v1.0-QA-RC1.xlsx]Business Engine'!B43),"") | C33: =IF(ISNUMBER(SEARCH("MAXIFS",B33)),"YES","NO") | D33: =IF(ISNUMBER(SEARCH("AGGREGATE",B33)),"AGGREGATE ","")&IF(ISNUMBER(SEARCH("LOOKUP",B33)),"LOOKUP ","")&IF(ISNUMBER(SEARCH("FILTER",B33)),"FILTER ","")
A34: B44 | B34: =IFERROR(FORMULATEXT('[FinanceOS_v1.0-QA-RC1.xlsx]Business Engine'!B44),"") | C34: =IF(ISNUMBER(SEARCH("MAXIFS",B34)),"YES","NO") | D34: =IF(ISNUMBER(SEARCH("AGGREGATE",B34)),"AGGREGATE ","")&IF(ISNUMBER(SEARCH("LOOKUP",B34)),"LOOKUP ","")&IF(ISNUMBER(SEARCH("FILTER",B34)),"FILTER ","")
A35: B45 | B35: =IFERROR(FORMULATEXT('[FinanceOS_v1.0-QA-RC1.xlsx]Business Engine'!B45),"") | C35: =IF(ISNUMBER(SEARCH("MAXIFS",B35)),"YES","NO") | D35: =IF(ISNUMBER(SEARCH("AGGREGATE",B35)),"AGGREGATE ","")&IF(ISNUMBER(SEARCH("LOOKUP",B35)),"LOOKUP ","")&IF(ISNUMBER(SEARCH("FILTER",B35)),"FILTER ","")
