Workbook
Name rngAccounts: Accounts!$B$2:$B$200
Name rngAccountStatus: Helpers!$A$70:$A$71
Name rngAccountType: Helpers!$A$91:$A$98
Name rngActiveAccounts: Helpers!$G$2:$G$201
Name rngActiveAssets: Helpers!$I$2:$I$201
Name rngActiveGoals: Helpers!$H$2:$H$201
Name rngActiveLiabilities: Helpers!$J$2:$J$201
Name rngAssets: Assets!$B$2:$B$200
Name rngAssetType: Helpers!$AG$2:$AG$25
Name rngBlank: Helpers!$L$2
Name rngBoolean: Helpers!$A$86:$A$87
Name rngCategories: Categories!$B$2:$B$200
Name rngCategoryType: Helpers!$A$102:$A$103
Name rngCommitmentStatus: Helpers!$A$75:$A$77
Name rngCurrency: Helpers!$A$2:$A$6
Name rngDestinationType: Helpers!$A$28:$A$34
Name rngExpenseCategories: Helpers!$E$2:$E$201
Name rngFinancialYears: Helpers!$A$126
Name rngFrequency: Helpers!$A$38:$A$41
Name rngGoals: Goals!$B$2:$B$200
Name rngGoalStatus: Helpers!$A$59:$A$61
Name rngIncomeCategories: Helpers!$F$2:$F$201
Name rngIncomeSources: 'Income Sources'!$B$2:$B$200
Name rngIncomeType: Helpers!$AI$2:$AI$10
Name rngLiabilities: Liabilities!$B$2:$B$200
Name rngLiabilityStatus: Helpers!$A$65:$A$66
Name rngLiabilityType: Helpers!$AH$2:$AH$11
Name rngMonths: Helpers!$B$111:$B$122
Name rngOwnershipType: Helpers!$A$81:$A$82
Name rngPaymentMethods: Helpers!$A$10:$A$17
Name rngPriority: Helpers!$A$45:$A$47
Name rngTransactionStatus: Helpers!$D$1:$D$4
Name rngTransactionType: Helpers!$A$21:$A$24
Name rngYesNo: Helpers!$A$86:$A$87
Name valAccountStatus: Helpers!$B$147
Name valAccountTypes: Helpers!$B$140
Name valActiveAccounts: Helpers!$G$2:$G$201
Name valActiveAssets: Helpers!$I$2:$I$201
Name valActiveGoals: Helpers!$H$2:$H$201
Name valActiveLiabilities: Helpers!$J$2:$J$201
Name valBlank: Helpers!$L$2
Name valCategoryTypes: Helpers!$B$141
Name valCommitmentStatus: Helpers!$B$148
Name valCurrencies: Helpers!$B$143
Name valDestinationTypes: Helpers!$B$144
Name valExpenseCategories: Helpers!$E$2:$E$201
Name valFrequency: Helpers!$B$138
Name valGoalStatus: Helpers!$B$146
Name valIncomeCategories: Helpers!$F$2:$F$201
Name valIncomeSources: Helpers!$K$2:$K$201
Name valPaymentMethods: Helpers!$B$137
Name valPriority: Helpers!$B$139
Name valThemes: Helpers!$B$142
Name valTransactionTypes: Helpers!$B$145
Name outLiabilityPaymentTotal: 'Business Engine'!$B$46
Name outAssetPurchaseTotal: 'Business Engine'!$B$39
Name analysisSavingsHealth: 'Analysis Engine'!$B$158
Name analysisExpenseHealth: 'Analysis Engine'!$B$159
Name analysisDebtHealth: 'Analysis Engine'!$B$160
Name analysisAssetHealth: 'Analysis Engine'!$B$161

Sheet Settings
A1: Setting ID | B1: Setting Name | C1: Setting Value | D1: Setting Category | E1: Description

Sheet Categories
A1: Category ID | B1: Category Name | C1: Category Type | D1: Parent Category | E1: Status | F1: Display Order | G1: Notes

Sheet Accounts
A1: Account ID | B1: Account Name | C1: Account Type | D1: Institution | E1: Opening Balance | F1: Current Balance | G1: Currency | H1: Include in Dashboard | I1: Status | J1: Notes
F2: =IF(tblAccounts[[#This Row],[Account Name]]="","",INDEX('Business Engine'!$H$2:$H$200,ROW()-ROW(tblAccounts[#Headers])))
F3: =IF(tblAccounts[[#This Row],[Account Name]]="","",INDEX('Business Engine'!$H$2:$H$200,ROW()-ROW(tblAccounts[#Headers])))
F4: =IF(tblAccounts[[#This Row],[Account Name]]="","",INDEX('Business Engine'!$H$2:$H$200,ROW()-ROW(tblAccounts[#Headers])))
F5: =IF(tblAccounts[[#This Row],[Account Name]]="","",INDEX('Business Engine'!$H$2:$H$200,ROW()-ROW(tblAccounts[#Headers])))
F6: =IF(tblAccounts[[#This Row],[Account Name]]="","",INDEX('Business Engine'!$H$2:$H$200,ROW()-ROW(tblAccounts[#Headers])))
F7: =IF(tblAccounts[[#This Row],[Account Name]]="","",INDEX('Business Engine'!$H$2:$H$200,ROW()-ROW(tblAccounts[#Headers])))
F8: =IF(tblAccounts[[#This Row],[Account Name]]="","",INDEX('Business Engine'!$H$2:$H$200,ROW()-ROW(tblAccounts[#Headers])))
F9: =IF(tblAccounts[[#This Row],[Account Name]]="","",INDEX('Business Engine'!$H$2:$H$200,ROW()-ROW(tblAccounts[#Headers])))
F10: =IF(tblAccounts[[#This Row],[Account Name]]="","",INDEX('Business Engine'!$H$2:$H$200,ROW()-ROW(tblAccounts[#Headers])))
F11: =IF(tblAccounts[[#This Row],[Account Name]]="","",INDEX('Business Engine'!$H$2:$H$200,ROW()-ROW(tblAccounts[#Headers])))
F12: =IF(tblAccounts[[#This Row],[Account Name]]="","",INDEX('Business Engine'!$H$2:$H$200,ROW()-ROW(tblAccounts[#Headers])))
F13: =IF(tblAccounts[[#This Row],[Account Name]]="","",INDEX('Business Engine'!$H$2:$H$200,ROW()-ROW(tblAccounts[#Headers])))
... F200: =IF(tblAccounts[[#This Row],[Account Name]]="","",INDEX('Business Engine'!$H$2:$H$200,ROW()-ROW(tblAccounts[#Headers])))

Sheet Income Sources
A1: Income Source ID | B1: Income Source Name | C1: Income Category | D1: Default Receiving Account | E1: Status | F1: Notes

Sheet Assets
A1: Asset ID | B1: Asset Name | C1: Asset Category | D1: Asset Type | E1: Linked Account | F1: Purchase Date | G1: Purchase Value | H1: Current Value | I1: Appreciation Amount | J1: Appreciation % | K1: Ownership Type | L1: Status | M1: Notes
I2: =IF(tblAssets[[#This Row],[Asset ID]]="","",tblAssets[[#This Row],[Current Value]]-tblAssets[[#This Row],[Purchase Value]]) -> 0 | J2: =IF(OR(tblAssets[[#This Row],[Asset ID]]="",tblAssets[[#This Row],[Purchase Value]]=0),"",tblAssets[[#This Row],[Appreciation Amount]]/tblAssets[[#This Row],[Purchase Value]]) -> 0
I3: =IF(tblAssets[[#This Row],[Asset ID]]="","",tblAssets[[#This Row],[Current Value]]-tblAssets[[#This Row],[Purchase Value]]) -> 0 | J3: =IF(OR(tblAssets[[#This Row],[Asset ID]]="",tblAssets[[#This Row],[Purchase Value]]=0),"",tblAssets[[#This Row],[Appreciation Amount]]/tblAssets[[#This Row],[Purchase Value]]) -> 0
I4: =IF(tblAssets[[#This Row],[Asset ID]]="","",tblAssets[[#This Row],[Current Value]]-tblAssets[[#This Row],[Purchase Value]]) -> 0 | J4: =IF(OR(tblAssets[[#This Row],[Asset ID]]="",tblAssets[[#This Row],[Purchase Value]]=0),"",tblAssets[[#This Row],[Appreciation Amount]]/tblAssets[[#This Row],[Purchase Value]]) -> 0
I5: =IF(tblAssets[[#This Row],[Asset ID]]="","",tblAssets[[#This Row],[Current Value]]-tblAssets[[#This Row],[Purchase Value]]) -> 0 | J5: =IF(OR(tblAssets[[#This Row],[Asset ID]]="",tblAssets[[#This Row],[Purchase Value]]=0),"",tblAssets[[#This Row],[Appreciation Amount]]/tblAssets[[#This Row],[Purchase Value]]) -> 0
I6: =IF(tblAssets[[#This Row],[Asset ID]]="","",tblAssets[[#This Row],[Current Value]]-tblAssets[[#This Row],[Purchase Value]]) -> 0 | J6: =IF(OR(tblAssets[[#This Row],[Asset ID]]="",tblAssets[[#This Row],[Purchase Value]]=0),"",tblAssets[[#This Row],[Appreciation Amount]]/tblAssets[[#This Row],[Purchase Value]]) -> 0
I7: =IF(tblAssets[[#This Row],[Asset ID]]="","",tblAssets[[#This Row],[Current Value]]-tblAssets[[#This Row],[Purchase Value]]) -> 0 | J7: =IF(OR(tblAssets[[#This Row],[Asset ID]]="",tblAssets[[#This Row],[Purchase Value]]=0),"",tblAssets[[#This Row],[Appreciation Amount]]/tblAssets[[#This Row],[Purchase Value]]) -> 0
I8: =IF(tblAssets[[#This Row],[Asset ID]]="","",tblAssets[[#This Row],[Current Value]]-tblAssets[[#This Row],[Purchase Value]]) -> 0 | J8: =IF(OR(tblAssets[[#This Row],[Asset ID]]="",tblAssets[[#This Row],[Purchase Value]]=0),"",tblAssets[[#This Row],[Appreciation Amount]]/tblAssets[[#This Row],[Purchase Value]]) -> 0
I9: =IF(tblAssets[[#This Row],[Asset ID]]="","",tblAssets[[#This Row],[Current Value]]-tblAssets[[#This Row],[Purchase Value]]) -> 0 | J9: =IF(OR(tblAssets[[#This Row],[Asset ID]]="",tblAssets[[#This Row],[Purchase Value]]=0),"",tblAssets[[#This Row],[Appreciation Amount]]/tblAssets[[#This Row],[Purchase Value]]) -> 0
I10: =IF(tblAssets[[#This Row],[Asset ID]]="","",tblAssets[[#This Row],[Current Value]]-tblAssets[[#This Row],[Purchase Value]]) -> 0 | J10: =IF(OR(tblAssets[[#This Row],[Asset ID]]="",tblAssets[[#This Row],[Purchase Value]]=0),"",tblAssets[[#This Row],[Appreciation Amount]]/tblAssets[[#This Row],[Purchase Value]]) -> 0
I11: =IF(tblAssets[[#This Row],[Asset ID]]="","",tblAssets[[#This Row],[Current Value]]-tblAssets[[#This Row],[Purchase Value]]) -> 0 | J11: =IF(OR(tblAssets[[#This Row],[Asset ID]]="",tblAssets[[#This Row],[Purchase Value]]=0),"",tblAssets[[#This Row],[Appreciation Amount]]/tblAssets[[#This Row],[Purchase Value]]) -> 0
I12: =IF(tblAssets[[#This Row],[Asset ID]]="","",tblAssets[[#This Row],[Current Value]]-tblAssets[[#This Row],[Purchase Value]]) -> 0 | J12: =IF(OR(tblAssets[[#This Row],[Asset ID]]="",tblAssets[[#This Row],[Purchase Value]]=0),"",tblAssets[[#This Row],[Appreciation Amount]]/tblAssets[[#This Row],[Purchase Value]]) -> 0
I13: =IF(tblAssets[[#This Row],[Asset ID]]="","",tblAssets[[#This Row],[Current Value]]-tblAssets[[#This Row],[Purchase Value]]) -> 0 | J13: =IF(OR(tblAssets[[#This Row],[Asset ID]]="",tblAssets[[#This Row],[Purchase Value]]=0),"",tblAssets[[#This Row],[Appreciation Amount]]/tblAssets[[#This Row],[Purchase Value]]) -> 0
... I200: =IF(tblAssets[[#This Row],[Asset ID]]="","",tblAssets[[#This Row],[Current Value]]-tblAssets[[#This Row],[Purchase Value]]) -> 0 | J200: =IF(OR(tblAssets[[#This Row],[Asset ID]]="",tblAssets[[#This Row],[Purchase Value]]=0),"",tblAssets[[#This Row],[Appreciation Amount]]/tblAssets[[#This Row],[Purchase Value]]) -> 0

Sheet Liabilities
A1: Liability ID | B1: Liability Name | C1: Liability Type | D1: Institution | E1: Original Amount | F1: Outstanding Balance | G1: Interest Rate | H1: EMI Amount | I1: EMI Frequency | J1: EMI Due Day | K1: Start Date | L1: End Date | M1: Linked Payment Account | N1: Auto EMI | O1: Status | P1: Notes

Sheet Recurring Commitments
A1: Commitment ID | B1: Commitment Name | C1: Commitment Type | D1: Linked Liability ID | E1: Linked Goal ID | F1: Payment Account | G1: Amount | H1: Frequency | I1: Due Day | J1: Start Date | K1: End Date | L1: Auto Generate | M1: Status | N1: Notes

Sheet Transactions
A1: Transaction ID | B1: Transaction Date | C1: Transaction Type | D1: Source Account | E1: Destination Type | F1: Destination Name | G1: Category | H1: Income Source | I1: Amount | J1: Payment Method | K1: Transaction Status | L1: Notes | M1: Created Timestamp

Sheet Goals
A1: Goal ID | B1: Goal Name | C1: Goal Category | D1: Goal Account | E1: Target Amount | F1: Current Saved Amount | G1: Remaining Amount | H1: Monthly Contribution Target | I1: Target Date | J1: Priority | K1: Goal Status | L1: Notes
F2: =IF(tblGoals[[#This Row],[Goal ID]]="","",IFERROR(SUMPRODUCT((tblTransactions[Transaction Type]="Expense")*(tblTransactions[Destination Type]="Goal")*((tblTransactions[Transaction Status]="Completed")+(tblTransactions[Transaction Status]="Reconciled"))*(IFERROR(INDEX(tblGoals[Goal ID],MATCH(tblTransactions[Destination Name],tblGoals[Goal ID],0)),IFERROR(INDEX(tblGoals[Goal ID],MATCH(tblTransactions[Destination Name],tblGoals[Goal Name],0)),""))=tblGoals[[#This Row],[Goal ID]])*(tblTransactions[Amount])),0)) | G2: =MAX(0,tblGoals[[#This Row],[Target Amount]]-tblGoals[[#This Row],[Current Saved Amount]]) -> 0
F3: =IF(tblGoals[[#This Row],[Goal ID]]="","",IFERROR(SUMPRODUCT((tblTransactions[Transaction Type]="Expense")*(tblTransactions[Destination Type]="Goal")*((tblTransactions[Transaction Status]="Completed")+(tblTransactions[Transaction Status]="Reconciled"))*(IFERROR(INDEX(tblGoals[Goal ID],MATCH(tblTransactions[Destination Name],tblGoals[Goal ID],0)),IFERROR(INDEX(tblGoals[Goal ID],MATCH(tblTransactions[Destination Name],tblGoals[Goal Name],0)),""))=tblGoals[[#This Row],[Goal ID]])*(tblTransactions[Amount])),0)) | G3: =MAX(0,tblGoals[[#This Row],[Target Amount]]-tblGoals[[#This Row],[Current Saved Amount]]) -> 0
F4: =IF(tblGoals[[#This Row],[Goal ID]]="","",IFERROR(SUMPRODUCT((tblTransactions[Transaction Type]="Expense")*(tblTransactions[Destination Type]="Goal")*((tblTransactions[Transaction Status]="Completed")+(tblTransactions[Transaction Status]="Reconciled"))*(IFERROR(INDEX(tblGoals[Goal ID],MATCH(tblTransactions[Destination Name],tblGoals[Goal ID],0)),IFERROR(INDEX(tblGoals[Goal ID],MATCH(tblTransactions[Destination Name],tblGoals[Goal Name],0)),""))=tblGoals[[#This Row],[Goal ID]])*(tblTransactions[Amount])),0)) | G4: =MAX(0,tblGoals[[#This Row],[Target Amount]]-tblGoals[[#This Row],[Current Saved Amount]]) -> 0
F5: =IF(tblGoals[[#This Row],[Goal ID]]="","",IFERROR(SUMPRODUCT((tblTransactions[Transaction Type]="Expense")*(tblTransactions[Destination Type]="Goal")*((tblTransactions[Transaction Status]="Completed")+(tblTransactions[Transaction Status]="Reconciled"))*(IFERROR(INDEX(tblGoals[Goal ID],MATCH(tblTransactions[Destination Name],tblGoals[Goal ID],0)),IFERROR(INDEX(tblGoals[Goal ID],MATCH(tblTransactions[Destination Name],tblGoals[Goal Name],0)),""))=tblGoals[[#This Row],[Goal ID]])*(tblTransactions[Amount])),0)) | G5: =MAX(0,tblGoals[[#This Row],[Target Amount]]-tblGoals[[#This Row],[Current Saved Amount]]) -> 0
F6: =IF(tblGoals[[#This Row],[Goal ID]]="","",IFERROR(SUMPRODUCT((tblTransactions[Transaction Type]="Expense")*(tblTransactions[Destination Type]="Goal")*((tblTransactions[Transaction Status]="Completed")+(tblTransactions[Transaction Status]="Reconciled"))*(IFERROR(INDEX(tblGoals[Goal ID],MATCH(tblTransactions[Destination Name],tblGoals[Goal ID],0)),IFERROR(INDEX(tblGoals[Goal ID],MATCH(tblTransactions[Destination Name],tblGoals[Goal Name],0)),""))=tblGoals[[#This Row],[Goal ID]])*(tblTransactions[Amount])),0)) | G6: =MAX(0,tblGoals[[#This Row],[Target Amount]]-tblGoals[[#This Row],[Current Saved Amount]]) -> 0
F7: =IF(tblGoals[[#This Row],[Goal ID]]="","",IFERROR(SUMPRODUCT((tblTransactions[Transaction Type]="Expense")*(tblTransactions[Destination Type]="Goal")*((tblTransactions[Transaction Status]="Completed")+(tblTransactions[Transaction Status]="Reconciled"))*(IFERROR(INDEX(tblGoals[Goal ID],MATCH(tblTransactions[Destination Name],tblGoals[Goal ID],0)),IFERROR(INDEX(tblGoals[Goal ID],MATCH(tblTransactions[Destination Name],tblGoals[Goal Name],0)),""))=tblGoals[[#This Row],[Goal ID]])*(tblTransactions[Amount])),0)) | G7: =MAX(0,tblGoals[[#This Row],[Target Amount]]-tblGoals[[#This Row],[Current Saved Amount]]) -> 0
F8: =IF(tblGoals[[#This Row],[Goal ID]]="","",IFERROR(SUMPRODUCT((tblTransactions[Transaction Type]="Expense")*(tblTransactions[Destination Type]="Goal")*((tblTransactions[Transaction Status]="Completed")+(tblTransactions[Transaction Status]="Reconciled"))*(IFERROR(INDEX(tblGoals[Goal ID],MATCH(tblTransactions[Destination Name],tblGoals[Goal ID],0)),IFERROR(INDEX(tblGoals[Goal ID],MATCH(tblTransactions[Destination Name],tblGoals[Goal Name],0)),""))=tblGoals[[#This Row],[Goal ID]])*(tblTransactions[Amount])),0)) | G8: =MAX(0,tblGoals[[#This Row],[Target Amount]]-tblGoals[[#This Row],[Current Saved Amount]]) -> 0
F9: =IF(tblGoals[[#This Row],[Goal ID]]="","",IFERROR(SUMPRODUCT((tblTransactions[Transaction Type]="Expense")*(tblTransactions[Destination Type]="Goal")*((tblTransactions[Transaction Status]="Completed")+(tblTransactions[Transaction Status]="Reconciled"))*(IFERROR(INDEX(tblGoals[Goal ID],MATCH(tblTransactions[Destination Name],tblGoals[Goal ID],0)),IFERROR(INDEX(tblGoals[Goal ID],MATCH(tblTransactions[Destination Name],tblGoals[Goal Name],0)),""))=tblGoals[[#This Row],[Goal ID]])*(tblTransactions[Amount])),0)) | G9: =MAX(0,tblGoals[[#This Row],[Target Amount]]-tblGoals[[#This Row],[Current Saved Amount]]) -> 0
F10: =IF(tblGoals[[#This Row],[Goal ID]]="","",IFERROR(SUMPRODUCT((tblTransactions[Transaction Type]="Expense")*(tblTransactions[Destination Type]="Goal")*((tblTransactions[Transaction Status]="Completed")+(tblTransactions[Transaction Status]="Reconciled"))*(IFERROR(INDEX(tblGoals[Goal ID],MATCH(tblTransactions[Destination Name],tblGoals[Goal ID],0)),IFERROR(INDEX(tblGoals[Goal ID],MATCH(tblTransactions[Destination Name],tblGoals[Goal Name],0)),""))=tblGoals[[#This Row],[Goal ID]])*(tblTransactions[Amount])),0)) | G10: =MAX(0,tblGoals[[#This Row],[Target Amount]]-tblGoals[[#This Row],[Current Saved Amount]]) -> 0
F11: =IF(tblGoals[[#This Row],[Goal ID]]="","",IFERROR(SUMPRODUCT((tblTransactions[Transaction Type]="Expense")*(tblTransactions[Destination Type]="Goal")*((tblTransactions[Transaction Status]="Completed")+(tblTransactions[Transaction Status]="Reconciled"))*(IFERROR(INDEX(tblGoals[Goal ID],MATCH(tblTransactions[Destination Name],tblGoals[Goal ID],0)),IFERROR(INDEX(tblGoals[Goal ID],MATCH(tblTransactions[Destination Name],tblGoals[Goal Name],0)),""))=tblGoals[[#This Row],[Goal ID]])*(tblTransactions[Amount])),0)) | G11: =MAX(0,tblGoals[[#This Row],[Target Amount]]-tblGoals[[#This Row],[Current Saved Amount]]) -> 0
F12: =IF(tblGoals[[#This Row],[Goal ID]]="","",IFERROR(SUMPRODUCT((tblTransactions[Transaction Type]="Expense")*(tblTransactions[Destination Type]="Goal")*((tblTransactions[Transaction Status]="Completed")+(tblTransactions[Transaction Status]="Reconciled"))*(IFERROR(INDEX(tblGoals[Goal ID],MATCH(tblTransactions[Destination Name],tblGoals[Goal ID],0)),IFERROR(INDEX(tblGoals[Goal ID],MATCH(tblTransactions[Destination Name],tblGoals[Goal Name],0)),""))=tblGoals[[#This Row],[Goal ID]])*(tblTransactions[Amount])),0)) | G12: =MAX(0,tblGoals[[#This Row],[Target Amount]]-tblGoals[[#This Row],[Current Saved Amount]]) -> 0
F13: =IF(tblGoals[[#This Row],[Goal ID]]="","",IFERROR(SUMPRODUCT((tblTransactions[Transaction Type]="Expense")*(tblTransactions[Destination Type]="Goal")*((tblTransactions[Transaction Status]="Completed")+(tblTransactions[Transaction Status]="Reconciled"))*(IFERROR(INDEX(tblGoals[Goal ID],MATCH(tblTransactions[Destination Name],tblGoals[Goal ID],0)),IFERROR(INDEX(tblGoals[Goal ID],MATCH(tblTransactions[Destination Name],tblGoals[Goal Name],0)),""))=tblGoals[[#This Row],[Goal ID]])*(tblTransactions[Amount])),0)) | G13: =MAX(0,tblGoals[[#This Row],[Target Amount]]-tblGoals[[#This Row],[Current Saved Amount]]) -> 0
... F200: =IF(tblGoals[[#This Row],[Goal ID]]="","",IFERROR(SUMPRODUCT((tblTransactions[Transaction Type]="Expense")*(tblTransactions[Destination Type]="Goal")*((tblTransactions[Transaction Status]="Completed")+(tblTransactions[Transaction Status]="Reconciled"))*(IFERROR(INDEX(tblGoals[Goal ID],MATCH(tblTransactions[Destination Name],tblGoals[Goal ID],0)),IFERROR(INDEX(tblGoals[Goal ID],MATCH(tblTransactions[Destination Name],tblGoals[Goal Name],0)),""))=tblGoals[[#This Row],[Goal ID]])*(tblTransactions[Amount])),0)) | G200: =MAX(0,tblGoals[[#This Row],[Target Amount]]-tblGoals[[#This Row],[Current Saved Amount]]) -> 0

Sheet Helpers
A1: Currency Code | B1: Currency Name | C1: Symbol | D1: Completed | E1: valExpenseCategories | F1: valIncomeCategories | G1: valActiveAccounts | H1: valActiveGoals | I1: valActiveAssets | J1: valActiveLiabilities | K1: valIncomeSources | L1: valBlank | AG1: Asset Type | AH1: Liability Type | AI1: Income Type
A2: INR | D2: Pending | E2: =IFERROR(SORT(UNIQUE(FILTER(tblCategories[Category Name],(tblCategories[Category Type]="Expense")*(tblCategories[Status]="Active")))),"") | F2: =IFERROR(SORT(UNIQUE(FILTER(tblCategories[Category Name],(tblCategories[Category Type]="Income")*(tblCategories[Status]="Active")))),"") | G2: =IFERROR(SORT(UNIQUE(FILTER(tblAccounts[Account Name],tblAccounts[Status]="Active"))),"") | H2: =IFERROR(SORT(UNIQUE(FILTER(tblGoals[Goal Name],tblGoals[Goal Status]="Active"))),"") | I2: =IFERROR(SORT(UNIQUE(FILTER(tblAssets[Asset Name],tblAssets[Status]="Active"))),"") | J2: =IFERROR(SORT(UNIQUE(FILTER(tblLiabilities[Liability Name],tblLiabilities[Status]="Active"))),"") | K2: =IFERROR(SORT(UNIQUE(FILTER(tblIncomeSources[Income Source Name],tblIncomeSources[Status]="Active"))),"") | AG2: Mutual Fund | AH2: Home Loan | AI2: Salary
A3: USD | D3: Cancelled | AG3: Stock | AH3: Personal Loan | AI3: Freelance
A4: EUR | D4: Reconciled | AG4: ETF | AH4: Education Loan | AI4: Bonus
A5: GBP | AG5: Gold ETF | AH5: Vehicle Loan | AI5: Rental Income
A6: AED | AG6: Bond | AH6: Gold Loan | AI6: Interest
AG7: SIP | AH7: Credit Card | AI7: Cashback
AG8: Fixed Deposit | AH8: Buy Now Pay Later | AI8: Refund
A9: Payment Method | AG9: PPF | AH9: Family Loan | AI9: Business Income
A10: Bank Transfer | AG10: EPF | AH10: Business Loan | AI10: Investment
A11: Cash | AG11: NPS | AH11: Other Liability
A12: UPI | AG12: Gold Jewellery
A13: Debit Card | AG13: Gold Coin
A14: Credit Card | AG14: Vehicle
A15: Wallet | AG15: Electronics
A16: Net Banking | AG16: Furniture
A17: Other | AG17: Watch
AG18: Other Physical Asset
AG19: Residential Property
A20: Transaction Type | AG20: Commercial Property
A21: Income | AG21: Land
A22: Expense | AG22: Plot
A23: Transfer | AG23: Emergency Cash
A24: Adjustment | AG24: Foreign Currency
AG25: Cash Reserve
A27: Destination Type
A28: Expense Category
A29: Income Category
A30: Account
A31: Goal
A32: Liability
A33: Asset
A34: Other
A37: Frequency
A38: Monthly
A39: Quarterly
A40: Half-Yearly
... A107: FinanceOS Default
A110: Month Number | B110: Month Name | C110: Short Name
A111: 1 | B111: January | C111: Jan
...

Sheet Business Engine
A1: As-Of Date | D1: Account Name | E1: Opening Balance | F1: Money In | G1: Money Out | H1: Current Balance | I1: Last Transaction Date | J1: Account Type | K1: Dashboard Enabled | L1: Status
D2: =IF(INDEX(tblAccounts[Account Name],ROW()-1)="","",INDEX(tblAccounts[Account Name],ROW()-1)) | E2: =IF($D2="","",IFERROR(INDEX(tblAccounts[Opening Balance],ROW()-1),0)) | F2: =IF($D2="","",SUMIFS(tblTransactions[Amount],tblTransactions[Transaction Type],"Income",tblTransactions[Transaction Status],"Completed",tblTransactions[Source Account],$D2)+SUMIFS(tblTransactions[Amount],tblTransactions[Transaction Type],"Income",tblTransactions[Transaction Status],"Reconciled",tblTransactions[Source Account],$D2)+SUMIFS(tblTransactions[Amount],tblTransactions[Transaction Type],"Transfer",tblTransactions[Transaction Status],"Completed",tblTransactions[Destination Type],"Account",tblTransactions[Destination Name],$D2)+SUMIFS(tblTransactions[Amount],tblTransactions[Transaction Type],"Transfer",tblTransactions[Transaction Status],"Reconciled",tblTransactions[Destination Type],"Account",tblTransactions[Destination Name],$D2)+SUMIFS(tblTransactions[Amount],tblTransactions[Transaction Type],"Adjustment",tblTransactions[Transaction Status],"Completed",tblTransactions[Source Account],$D2,tblTransactions[Amount],">0")+SUMIFS(tblTransactions[Amount],tblTransactions[Transaction Type],"Adjustment",tblTransactions[Transaction Status],"Reconciled",tblTransactions[Source Account],$D2,tblTransactions[Amount],">0")) | G2: =IF($D2="","",SUMIFS(tblTransactions[Amount],tblTransactions[Transaction Type],"Expense",tblTransactions[Transaction Status],"Completed",tblTransactions[Source Account],$D2)+SUMIFS(tblTransactions[Amount],tblTransactions[Transaction Type],"Expense",tblTransactions[Transaction Status],"Reconciled",tblTransactions[Source Account],$D2)+SUMIFS(tblTransactions[Amount],tblTransactions[Transaction Type],"Transfer",tblTransactions[Transaction Status],"Completed",tblTransactions[Source Account],$D2)+SUMIFS(tblTransactions[Amount],tblTransactions[Transaction Type],"Transfer",tblTransactions[Transaction Status],"Reconciled",tblTransactions[Source Account],$D2)-SUMIFS(tblTransactions[Amount],tblTransactions[Transaction Type],"Adjustment",tblTransactions[Transaction Status],"Completed",tblTransactions[Source Account],$D2,tblTransactions[Amount],"<0")-SUMIFS(tblTransactions[Amount],tblTransactions[Transaction Type],"Adjustment",tblTransactions[Transaction Status],"Reconciled",tblTransactions[Source Account],$D2,tblTransactions[Amount],"<0")) | H2: =IF($D2="","",$E2+$F2-$G2) | I2: =#N/A -> #N/A | J2: =IF($D2="","",IFERROR(INDEX(tblAccounts[Account Type],ROW()-1),"")) | K2: =IF($D2="","",IFERROR(INDEX(tblAccounts[Include in Dashboard],ROW()-1),"")) | L2: =IF($D2="","",IFERROR(INDEX(tblAccounts[Status],ROW()-1),""))
A3: SECTION 1 — Accounts Summary | D3: =IF(INDEX(tblAccounts[Account Name],ROW()-1)="","",INDEX(tblAccounts[Account Name],ROW()-1)) | E3: =IF($D3="","",IFERROR(INDEX(tblAccounts[Opening Balance],ROW()-1),0)) | F3: =IF($D3="","",SUMIFS(tblTransactions[Amount],tblTransactions[Transaction Type],"Income",tblTransactions[Transaction Status],"Completed",tblTransactions[Source Account],$D3)+SUMIFS(tblTransactions[Amount],tblTransactions[Transaction Type],"Income",tblTransactions[Transaction Status],"Reconciled",tblTransactions[Source Account],$D3)+SUMIFS(tblTransactions[Amount],tblTransactions[Transaction Type],"Transfer",tblTransactions[Transaction Status],"Completed",tblTransactions[Destination Type],"Account",tblTransactions[Destination Name],$D3)+SUMIFS(tblTransactions[Amount],tblTransactions[Transaction Type],"Transfer",tblTransactions[Transaction Status],"Reconciled",tblTransactions[Destination Type],"Account",tblTransactions[Destination Name],$D3)+SUMIFS(tblTransactions[Amount],tblTransactions[Transaction Type],"Adjustment",tblTransactions[Transaction Status],"Completed",tblTransactions[Source Account],$D3,tblTransactions[Amount],">0")+SUMIFS(tblTransactions[Amount],tblTransactions[Transaction Type],"Adjustment",tblTransactions[Transaction Status],"Reconciled",tblTransactions[Source Account],$D3,tblTransactions[Amount],">0")) | G3: =IF($D3="","",SUMIFS(tblTransactions[Amount],tblTransactions[Transaction Type],"Expense",tblTransactions[Transaction Status],"Completed",tblTransactions[Source Account],$D3)+SUMIFS(tblTransactions[Amount],tblTransactions[Transaction Type],"Expense",tblTransactions[Transaction Status],"Reconciled",tblTransactions[Source Account],$D3)+SUMIFS(tblTransactions[Amount],tblTransactions[Transaction Type],"Transfer",tblTransactions[Transaction Status],"Completed",tblTransactions[Source Account],$D3)+SUMIFS(tblTransactions[Amount],tblTransactions[Transaction Type],"Transfer",tblTransactions[Transaction Status],"Reconciled",tblTransactions[Source Account],$D3)-SUMIFS(tblTransactions[Amount],tblTransactions[Transaction Type],"Adjustment",tblTransactions[Transaction Status],"Completed",tblTransactions[Source Account],$D3,tblTransactions[Amount],"<0")-SUMIFS(tblTransactions[Amount],tblTransactions[Transaction Type],"Adjustment",tblTransactions[Transaction Status],"Reconciled",tblTransactions[Source Account],$D3,tblTransactions[Amount],"<0")) | H3: =IF($D3="","",$E3+$F3-$G3) | I3: =#N/A -> #N/A | J3: =IF($D3="","",IFERROR(INDEX(tblAccounts[Account Type],ROW()-1),"")) | K3: =IF($D3="","",IFERROR(INDEX(tblAccounts[Include in Dashboard],ROW()-1),"")) | L3: =IF($D3="","",IFERROR(INDEX(tblAccounts[Status],ROW()-1),""))
A4: Total Active Account Balance | B4: =IFERROR(SUMIFS($H$2:$H$200,$L$2:$L$200,"Active",$K$2:$K$200,"Yes"),0) -> 0 | D4: =IF(INDEX(tblAccounts[Account Name],ROW()-1)="","",INDEX(tblAccounts[Account Name],ROW()-1)) | E4: =IF($D4="","",IFERROR(INDEX(tblAccounts[Opening Balance],ROW()-1),0)) | F4: =IF($D4="","",SUMIFS(tblTransactions[Amount],tblTransactions[Transaction Type],"Income",tblTransactions[Transaction Status],"Completed",tblTransactions[Source Account],$D4)+SUMIFS(tblTransactions[Amount],tblTransactions[Transaction Type],"Income",tblTransactions[Transaction Status],"Reconciled",tblTransactions[Source Account],$D4)+SUMIFS(tblTransactions[Amount],tblTransactions[Transaction Type],"Transfer",tblTransactions[Transaction Status],"Completed",tblTransactions[Destination Type],"Account",tblTransactions[Destination Name],$D4)+SUMIFS(tblTransactions[Amount],tblTransactions[Transaction Type],"Transfer",tblTransactions[Transaction Status],"Reconciled",tblTransactions[Destination Type],"Account",tblTransactions[Destination Name],$D4)+SUMIFS(tblTransactions[Amount],tblTransactions[Transaction Type],"Adjustment",tblTransactions[Transaction Status],"Completed",tblTransactions[Source Account],$D4,tblTransactions[Amount],">0")+SUMIFS(tblTransactions[Amount],tblTransactions[Transaction Type],"Adjustment",tblTransactions[Transaction Status],"Reconciled",tblTransactions[Source Account],$D4,tblTransactions[Amount],">0")) | G4: =IF($D4="","",SUMIFS(tblTransactions[Amount],tblTransactions[Transaction Type],"Expense",tblTransactions[Transaction Status],"Completed",tblTransactions[Source Account],$D4)+SUMIFS(tblTransactions[Amount],tblTransactions[Transaction Type],"Expense",tblTransactions[Transaction Status],"Reconciled",tblTransactions[Source Account],$D4)+SUMIFS(tblTransactions[Amount],tblTransactions[Transaction Type],"Transfer",tblTransactions[Transaction Status],"Completed",tblTransactions[Source Account],$D4)+SUMIFS(tblTransactions[Amount],tblTransactions[Transaction Type],"Transfer",tblTransactions[Transaction Status],"Reconciled",tblTransactions[Source Account],$D4)-SUMIFS(tblTransactions[Amount],tblTransactions[Transaction Type],"Adjustment",tblTransactions[Transaction Status],"Completed",tblTransactions[Source Account],$D4,tblTransactions[Amount],"<0")-SUMIFS(tblTransactions[Amount],tblTransactions[Transaction Type],"Adjustment",tblTransactions[Transaction Status],"Reconciled",tblTransactions[Source Account],$D4,tblTransactions[Amount],"<0")) | H4: =IF($D4="","",$E4+$F4-$G4) | I4: =#N/A -> #N/A | J4: =IF($D4="","",IFERROR(INDEX(tblAccounts[Account Type],ROW()-1),"")) | K4: =IF($D4="","",IFERROR(INDEX(tblAccounts[Include in Dashboard],ROW()-1),"")) | L4: =IF($D4="","",IFERROR(INDEX(tblAccounts[Status],ROW()-1),""))
A5: Number of Active Accounts | B5: =COUNTIFS($D$2:$D$200,"<>",$L$2:$L$200,"Active",$K$2:$K$200,"Yes") -> 0 | D5: =IF(INDEX(tblAccounts[Account Name],ROW()-1)="","",INDEX(tblAccounts[Account Name],ROW()-1)) | E5: =IF($D5="","",IFERROR(INDEX(tblAccounts[Opening Balance],ROW()-1),0)) | F5: =IF($D5="","",SUMIFS(tblTransactions[Amount],tblTransactions[Transaction Type],"Income",tblTransactions[Transaction Status],"Completed",tblTransactions[Source Account],$D5)+SUMIFS(tblTransactions[Amount],tblTransactions[Transaction Type],"Income",tblTransactions[Transaction Status],"Reconciled",tblTransactions[Source Account],$D5)+SUMIFS(tblTransactions[Amount],tblTransactions[Transaction Type],"Transfer",tblTransactions[Transaction Status],"Completed",tblTransactions[Destination Type],"Account",tblTransactions[Destination Name],$D5)+SUMIFS(tblTransactions[Amount],tblTransactions[Transaction Type],"Transfer",tblTransactions[Transaction Status],"Reconciled",tblTransactions[Destination Type],"Account",tblTransactions[Destination Name],$D5)+SUMIFS(tblTransactions[Amount],tblTransactions[Transaction Type],"Adjustment",tblTransactions[Transaction Status],"Completed",tblTransactions[Source Account],$D5,tblTransactions[Amount],">0")+SUMIFS(tblTransactions[Amount],tblTransactions[Transaction Type],"Adjustment",tblTransactions[Transaction Status],"Reconciled",tblTransactions[Source Account],$D5,tblTransactions[Amount],">0")) | G5: =IF($D5="","",SUMIFS(tblTransactions[Amount],tblTransactions[Transaction Type],"Expense",tblTransactions[Transaction Status],"Completed",tblTransactions[Source Account],$D5)+SUMIFS(tblTransactions[Amount],tblTransactions[Transaction Type],"Expense",tblTransactions[Transaction Status],"Reconciled",tblTransactions[Source Account],$D5)+SUMIFS(tblTransactions[Amount],tblTransactions[Transaction Type],"Transfer",tblTransactions[Transaction Status],"Completed",tblTransactions[Source Account],$D5)+SUMIFS(tblTransactions[Amount],tblTransactions[Transaction Type],"Transfer",tblTransactions[Transaction Status],"Reconciled",tblTransactions[Source Account],$D5)-SUMIFS(tblTransactions[Amount],tblTransactions[Transaction Type],"Adjustment",tblTransactions[Transaction Status],"Completed",tblTransactions[Source Account],$D5,tblTransactions[Amount],"<0")-SUMIFS(tblTransactions[Amount],tblTransactions[Transaction Type],"Adjustment",tblTransactions[Transaction Status],"Reconciled",tblTransactions[Source Account],$D5,tblTransactions[Amount],"<0")) | H5: =IF($D5="","",$E5+$F5-$G5) | I5: =#N/A -> #N/A | J5: =IF($D5="","",IFERROR(INDEX(tblAccounts[Account Type],ROW()-1),"")) | K5: =IF($D5="","",IFERROR(INDEX(tblAccounts[Include in Dashboard],ROW()-1),"")) | L5: =IF($D5="","",IFERROR(INDEX(tblAccounts[Status],ROW()-1),""))
A6: Cash Accounts Total | B6: =IFERROR(SUMIFS($H$2:$H$200,$J$2:$J$200,"Cash",$L$2:$L$200,"Active",$K$2:$K$200,"Yes"),0) -> 0 | D6: =IF(INDEX(tblAccounts[Account Name],ROW()-1)="","",INDEX(tblAccounts[Account Name],ROW()-1)) | E6: =IF($D6="","",IFERROR(INDEX(tblAccounts[Opening Balance],ROW()-1),0)) | F6: =IF($D6="","",SUMIFS(tblTransactions[Amount],tblTransactions[Transaction Type],"Income",tblTransactions[Transaction Status],"Completed",tblTransactions[Source Account],$D6)+SUMIFS(tblTransactions[Amount],tblTransactions[Transaction Type],"Income",tblTransactions[Transaction Status],"Reconciled",tblTransactions[Source Account],$D6)+SUMIFS(tblTransactions[Amount],tblTransactions[Transaction Type],"Transfer",tblTransactions[Transaction Status],"Completed",tblTransactions[Destination Type],"Account",tblTransactions[Destination Name],$D6)+SUMIFS(tblTransactions[Amount],tblTransactions[Transaction Type],"Transfer",tblTransactions[Transaction Status],"Reconciled",tblTransactions[Destination Type],"Account",tblTransactions[Destination Name],$D6)+SUMIFS(tblTransactions[Amount],tblTransactions[Transaction Type],"Adjustment",tblTransactions[Transaction Status],"Completed",tblTransactions[Source Account],$D6,tblTransactions[Amount],">0")+SUMIFS(tblTransactions[Amount],tblTransactions[Transaction Type],"Adjustment",tblTransactions[Transaction Status],"Reconciled",tblTransactions[Source Account],$D6,tblTransactions[Amount],">0")) | G6: =IF($D6="","",SUMIFS(tblTransactions[Amount],tblTransactions[Transaction Type],"Expense",tblTransactions[Transaction Status],"Completed",tblTransactions[Source Account],$D6)+SUMIFS(tblTransactions[Amount],tblTransactions[Transaction Type],"Expense",tblTransactions[Transaction Status],"Reconciled",tblTransactions[Source Account],$D6)+SUMIFS(tblTransactions[Amount],tblTransactions[Transaction Type],"Transfer",tblTransactions[Transaction Status],"Completed",tblTransactions[Source Account],$D6)+SUMIFS(tblTransactions[Amount],tblTransactions[Transaction Type],"Transfer",tblTransactions[Transaction Status],"Reconciled",tblTransactions[Source Account],$D6)-SUMIFS(tblTransactions[Amount],tblTransactions[Transaction Type],"Adjustment",tblTransactions[Transaction Status],"Completed",tblTransactions[Source Account],$D6,tblTransactions[Amount],"<0")-SUMIFS(tblTransactions[Amount],tblTransactions[Transaction Type],"Adjustment",tblTransactions[Transaction Status],"Reconciled",tblTransactions[Source Account],$D6,tblTransactions[Amount],"<0")) | H6: =IF($D6="","",$E6+$F6-$G6) | I6: =#N/A -> #N/A | J6: =IF($D6="","",IFERROR(INDEX(tblAccounts[Account Type],ROW()-1),"")) | K6: =IF($D6="","",IFERROR(INDEX(tblAccounts[Include in Dashboard],ROW()-1),"")) | L6: =IF($D6="","",IFERROR(INDEX(tblAccounts[Status],ROW()-1),""))
A7: Savings Accounts Total | B7: =IFERROR(SUMIFS($H$2:$H$200,$J$2:$J$200,"Savings Bank",$L$2:$L$200,"Active",$K$2:$K$200,"Yes"),0) -> 0 | D7: =IF(INDEX(tblAccounts[Account Name],ROW()-1)="","",INDEX(tblAccounts[Account Name],ROW()-1)) | E7: =IF($D7="","",IFERROR(INDEX(tblAccounts[Opening Balance],ROW()-1),0)) | F7: =IF($D7="","",SUMIFS(tblTransactions[Amount],tblTransactions[Transaction Type],"Income",tblTransactions[Transaction Status],"Completed",tblTransactions[Source Account],$D7)+SUMIFS(tblTransactions[Amount],tblTransactions[Transaction Type],"Income",tblTransactions[Transaction Status],"Reconciled",tblTransactions[Source Account],$D7)+SUMIFS(tblTransactions[Amount],tblTransactions[Transaction Type],"Transfer",tblTransactions[Transaction Status],"Completed",tblTransactions[Destination Type],"Account",tblTransactions[Destination Name],$D7)+SUMIFS(tblTransactions[Amount],tblTransactions[Transaction Type],"Transfer",tblTransactions[Transaction Status],"Reconciled",tblTransactions[Destination Type],"Account",tblTransactions[Destination Name],$D7)+SUMIFS(tblTransactions[Amount],tblTransactions[Transaction Type],"Adjustment",tblTransactions[Transaction Status],"Completed",tblTransactions[Source Account],$D7,tblTransactions[Amount],">0")+SUMIFS(tblTransactions[Amount],tblTransactions[Transaction Type],"Adjustment",tblTransactions[Transaction Status],"Reconciled",tblTransactions[Source Account],$D7,tblTransactions[Amount],">0")) | G7: =IF($D7="","",SUMIFS(tblTransactions[Amount],tblTransactions[Transaction Type],"Expense",tblTransactions[Transaction Status],"Completed",tblTransactions[Source Account],$D7)+SUMIFS(tblTransactions[Amount],tblTransactions[Transaction Type],"Expense",tblTransactions[Transaction Status],"Reconciled",tblTransactions[Source Account],$D7)+SUMIFS(tblTransactions[Amount],tblTransactions[Transaction Type],"Transfer",tblTransactions[Transaction Status],"Completed",tblTransactions[Source Account],$D7)+SUMIFS(tblTransactions[Amount],tblTransactions[Transaction Type],"Transfer",tblTransactions[Transaction Status],"Reconciled",tblTransactions[Source Account],$D7)-SUMIFS(tblTransactions[Amount],tblTransactions[Transaction Type],"Adjustment",tblTransactions[Transaction Status],"Completed",tblTransactions[Source Account],$D7,tblTransactions[Amount],"<0")-SUMIFS(tblTransactions[Amount],tblTransactions[Transaction Type],"Adjustment",tblTransactions[Transaction Status],"Reconciled",tblTransactions[Source Account],$D7,tblTransactions[Amount],"<0")) | H7: =IF($D7="","",$E7+$F7-$G7) | I7: =#N/A -> #N/A | J7: =IF($D7="","",IFERROR(INDEX(tblAccounts[Account Type],ROW()-1),"")) | K7: =IF($D7="","",IFERROR(INDEX(tblAccounts[Include in Dashboard],ROW()-1),"")) | L7: =IF($D7="","",IFERROR(INDEX(tblAccounts[Status],ROW()-1),""))
A8: Investment Accounts Total | B8: =IFERROR(SUMIFS($H$2:$H$200,$J$2:$J$200,"Investment Account",$L$2:$L$200,"Active",$K$2:$K$200,"Yes"),0) -> 0 | D8: =IF(INDEX(tblAccounts[Account Name],ROW()-1)="","",INDEX(tblAccounts[Account Name],ROW()-1)) | E8: =IF($D8="","",IFERROR(INDEX(tblAccounts[Opening Balance],ROW()-1),0)) | F8: =IF($D8="","",SUMIFS(tblTransactions[Amount],tblTransactions[Transaction Type],"Income",tblTransactions[Transaction Status],"Completed",tblTransactions[Source Account],$D8)+SUMIFS(tblTransactions[Amount],tblTransactions[Transaction Type],"Income",tblTransactions[Transaction Status],"Reconciled",tblTransactions[Source Account],$D8)+SUMIFS(tblTransactions[Amount],tblTransactions[Transaction Type],"Transfer",tblTransactions[Transaction Status],"Completed",tblTransactions[Destination Type],"Account",tblTransactions[Destination Name],$D8)+SUMIFS(tblTransactions[Amount],tblTransactions[Transaction Type],"Transfer",tblTransactions[Transaction Status],"Reconciled",tblTransactions[Destination Type],"Account",tblTransactions[Destination Name],$D8)+SUMIFS(tblTransactions[Amount],tblTransactions[Transaction Type],"Adjustment",tblTransactions[Transaction Status],"Completed",tblTransactions[Source Account],$D8,tblTransactions[Amount],">0")+SUMIFS(tblTransactions[Amount],tblTransactions[Transaction Type],"Adjustment",tblTransactions[Transaction Status],"Reconciled",tblTransactions[Source Account],$D8,tblTransactions[Amount],">0")) | G8: =IF($D8="","",SUMIFS(tblTransactions[Amount],tblTransactions[Transaction Type],"Expense",tblTransactions[Transaction Status],"Completed",tblTransactions[Source Account],$D8)+SUMIFS(tblTransactions[Amount],tblTransactions[Transaction Type],"Expense",tblTransactions[Transaction Status],"Reconciled",tblTransactions[Source Account],$D8)+SUMIFS(tblTransactions[Amount],tblTransactions[Transaction Type],"Transfer",tblTransactions[Transaction Status],"Completed",tblTransactions[Source Account],$D8)+SUMIFS(tblTransactions[Amount],tblTransactions[Transaction Type],"Transfer",tblTransactions[Transaction Status],"Reconciled",tblTransactions[Source Account],$D8)-SUMIFS(tblTransactions[Amount],tblTransactions[Transaction Type],"Adjustment",tblTransactions[Transaction Status],"Completed",tblTransactions[Source Account],$D8,tblTransactions[Amount],"<0")-SUMIFS(tblTransactions[Amount],tblTransactions[Transaction Type],"Adjustment",tblTransactions[Transaction Status],"Reconciled",tblTransactions[Source Account],$D8,tblTransactions[Amount],"<0")) | H8: =IF($D8="","",$E8+$F8-$G8) | I8: =#N/A -> #N/A | J8: =IF($D8="","",IFERROR(INDEX(tblAccounts[Account Type],ROW()-1),"")) | K8: =IF($D8="","",IFERROR(INDEX(tblAccounts[Include in Dashboard],ROW()-1),"")) | L8: =IF($D8="","",IFERROR(INDEX(tblAccounts[Status],ROW()-1),""))
A9: Credit Accounts Total | B9: =IFERROR(SUMIFS($H$2:$H$200,$J$2:$J$200,"Credit Card",$L$2:$L$200,"Active",$K$2:$K$200,"Yes"),0) -> 0 | D9: =IF(INDEX(tblAccounts[Account Name],ROW()-1)="","",INDEX(tblAccounts[Account Name],ROW()-1)) | E9: =IF($D9="","",IFERROR(INDEX(tblAccounts[Opening Balance],ROW()-1),0)) | F9: =IF($D9="","",SUMIFS(tblTransactions[Amount],tblTransactions[Transaction Type],"Income",tblTransactions[Transaction Status],"Completed",tblTransactions[Source Account],$D9)+SUMIFS(tblTransactions[Amount],tblTransactions[Transaction Type],"Income",tblTransactions[Transaction Status],"Reconciled",tblTransactions[Source Account],$D9)+SUMIFS(tblTransactions[Amount],tblTransactions[Transaction Type],"Transfer",tblTransactions[Transaction Status],"Completed",tblTransactions[Destination Type],"Account",tblTransactions[Destination Name],$D9)+SUMIFS(tblTransactions[Amount],tblTransactions[Transaction Type],"Transfer",tblTransactions[Transaction Status],"Reconciled",tblTransactions[Destination Type],"Account",tblTransactions[Destination Name],$D9)+SUMIFS(tblTransactions[Amount],tblTransactions[Transaction Type],"Adjustment",tblTransactions[Transaction Status],"Completed",tblTransactions[Source Account],$D9,tblTransactions[Amount],">0")+SUMIFS(tblTransactions[Amount],tblTransactions[Transaction Type],"Adjustment",tblTransactions[Transaction Status],"Reconciled",tblTransactions[Source Account],$D9,tblTransactions[Amount],">0")) | G9: =IF($D9="","",SUMIFS(tblTransactions[Amount],tblTransactions[Transaction Type],"Expense",tblTransactions[Transaction Status],"Completed",tblTransactions[Source Account],$D9)+SUMIFS(tblTransactions[Amount],tblTransactions[Transaction Type],"Expense",tblTransactions[Transaction Status],"Reconciled",tblTransactions[Source Account],$D9)+SUMIFS(tblTransactions[Amount],tblTransactions[Transaction Type],"Transfer",tblTransactions[Transaction Status],"Completed",tblTransactions[Source Account],$D9)+SUMIFS(tblTransactions[Amount],tblTransactions[Transaction Type],"Transfer",tblTransactions[Transaction Status],"Reconciled",tblTransactions[Source Account],$D9)-SUMIFS(tblTransactions[Amount],tblTransactions[Transaction Type],"Adjustment",tblTransactions[Transaction Status],"Completed",tblTransactions[Source Account],$D9,tblTransactions[Amount],"<0")-SUMIFS(tblTransactions[Amount],tblTransactions[Transaction Type],"Adjustment",tblTransactions[Transaction Status],"Reconciled",tblTransactions[Source Account],$D9,tblTransactions[Amount],"<0")) | H9: =IF($D9="","",$E9+$F9-$G9) | I9: =#N/A -> #N/A | J9: =IF($D9="","",IFERROR(INDEX(tblAccounts[Account Type],ROW()-1),"")) | K9: =IF($D9="","",IFERROR(INDEX(tblAccounts[Include in Dashboard],ROW()-1),"")) | L9: =IF($D9="","",IFERROR(INDEX(tblAccounts[Status],ROW()-1),""))
D10: =IF(INDEX(tblAccounts[Account Name],ROW()-1)="","",INDEX(tblAccounts[Account Name],ROW()-1)) | E10: =IF($D10="","",IFERROR(INDEX(tblAccounts[Opening Balance],ROW()-1),0)) | F10: =IF($D10="","",SUMIFS(tblTransactions[Amount],tblTransactions[Transaction Type],"Income",tblTransactions[Transaction Status],"Completed",tblTransactions[Source Account],$D10)+SUMIFS(tblTransactions[Amount],tblTransactions[Transaction Type],"Income",tblTransactions[Transaction Status],"Reconciled",tblTransactions[Source Account],$D10)+SUMIFS(tblTransactions[Amount],tblTransactions[Transaction Type],"Transfer",tblTransactions[Transaction Status],"Completed",tblTransactions[Destination Type],"Account",tblTransactions[Destination Name],$D10)+SUMIFS(tblTransactions[Amount],tblTransactions[Transaction Type],"Transfer",tblTransactions[Transaction Status],"Reconciled",tblTransactions[Destination Type],"Account",tblTransactions[Destination Name],$D10)+SUMIFS(tblTransactions[Amount],tblTransactions[Transaction Type],"Adjustment",tblTransactions[Transaction Status],"Completed",tblTransactions[Source Account],$D10,tblTransactions[Amount],">0")+SUMIFS(tblTransactions[Amount],tblTransactions[Transaction Type],"Adjustment",tblTransactions[Transaction Status],"Reconciled",tblTransactions[Source Account],$D10,tblTransactions[Amount],">0")) | G10: =IF($D10="","",SUMIFS(tblTransactions[Amount],tblTransactions[Transaction Type],"Expense",tblTransactions[Transaction Status],"Completed",tblTransactions[Source Account],$D10)+SUMIFS(tblTransactions[Amount],tblTransactions[Transaction Type],"Expense",tblTransactions[Transaction Status],"Reconciled",tblTransactions[Source Account],$D10)+SUMIFS(tblTransactions[Amount],tblTransactions[Transaction Type],"Transfer",tblTransactions[Transaction Status],"Completed",tblTransactions[Source Account],$D10)+SUMIFS(tblTransactions[Amount],tblTransactions[Transaction Type],"Transfer",tblTransactions[Transaction Status],"Reconciled",tblTransactions[Source Account],$D10)-SUMIFS(tblTransactions[Amount],tblTransactions[Transaction Type],"Adjustment",tblTransactions[Transaction Status],"Completed",tblTransactions[Source Account],$D10,tblTransactions[Amount],"<0")-SUMIFS(tblTransactions[Amount],tblTransactions[Transaction Type],"Adjustment",tblTransactions[Transaction Status],"Reconciled",tblTransactions[Source Account],$D10,tblTransactions[Amount],"<0")) | H10: =IF($D10="","",$E10+$F10-$G10) | I10: =#N/A -> #N/A | J10: =IF($D10="","",IFERROR(INDEX(tblAccounts[Account Type],ROW()-1),"")) | K10: =IF($D10="","",IFERROR(INDEX(tblAccounts[Include in Dashboard],ROW()-1),"")) | L10: =IF($D10="","",IFERROR(INDEX(tblAccounts[Status],ROW()-1),""))
A11: SECTION 2 — Income Summary | D11: =IF(INDEX(tblAccounts[Account Name],ROW()-1)="","",INDEX(tblAccounts[Account Name],ROW()-1)) | E11: =IF($D11="","",IFERROR(INDEX(tblAccounts[Opening Balance],ROW()-1),0)) | F11: =IF($D11="","",SUMIFS(tblTransactions[Amount],tblTransactions[Transaction Type],"Income",tblTransactions[Transaction Status],"Completed",tblTransactions[Source Account],$D11)+SUMIFS(tblTransactions[Amount],tblTransactions[Transaction Type],"Income",tblTransactions[Transaction Status],"Reconciled",tblTransactions[Source Account],$D11)+SUMIFS(tblTransactions[Amount],tblTransactions[Transaction Type],"Transfer",tblTransactions[Transaction Status],"Completed",tblTransactions[Destination Type],"Account",tblTransactions[Destination Name],$D11)+SUMIFS(tblTransactions[Amount],tblTransactions[Transaction Type],"Transfer",tblTransactions[Transaction Status],"Reconciled",tblTransactions[Destination Type],"Account",tblTransactions[Destination Name],$D11)+SUMIFS(tblTransactions[Amount],tblTransactions[Transaction Type],"Adjustment",tblTransactions[Transaction Status],"Completed",tblTransactions[Source Account],$D11,tblTransactions[Amount],">0")+SUMIFS(tblTransactions[Amount],tblTransactions[Transaction Type],"Adjustment",tblTransactions[Transaction Status],"Reconciled",tblTransactions[Source Account],$D11,tblTransactions[Amount],">0")) | G11: =IF($D11="","",SUMIFS(tblTransactions[Amount],tblTransactions[Transaction Type],"Expense",tblTransactions[Transaction Status],"Completed",tblTransactions[Source Account],$D11)+SUMIFS(tblTransactions[Amount],tblTransactions[Transaction Type],"Expense",tblTransactions[Transaction Status],"Reconciled",tblTransactions[Source Account],$D11)+SUMIFS(tblTransactions[Amount],tblTransactions[Transaction Type],"Transfer",tblTransactions[Transaction Status],"Completed",tblTransactions[Source Account],$D11)+SUMIFS(tblTransactions[Amount],tblTransactions[Transaction Type],"Transfer",tblTransactions[Transaction Status],"Reconciled",tblTransactions[Source Account],$D11)-SUMIFS(tblTransactions[Amount],tblTransactions[Transaction Type],"Adjustment",tblTransactions[Transaction Status],"Completed",tblTransactions[Source Account],$D11,tblTransactions[Amount],"<0")-SUMIFS(tblTransactions[Amount],tblTransactions[Transaction Type],"Adjustment",tblTransactions[Transaction Status],"Reconciled",tblTransactions[Source Account],$D11,tblTransactions[Amount],"<0")) | H11: =IF($D11="","",$E11+$F11-$G11) | I11: =#N/A -> #N/A | J11: =IF($D11="","",IFERROR(INDEX(tblAccounts[Account Type],ROW()-1),"")) | K11: =IF($D11="","",IFERROR(INDEX(tblAccounts[Include in Dashboard],ROW()-1),"")) | L11: =IF($D11="","",IFERROR(INDEX(tblAccounts[Status],ROW()-1),""))
A12: Monthly Salary Income | B12: =IFERROR(SUMPRODUCT((tblTransactions[Transaction Type]="Income")*(tblTransactions[Transaction Date]>=DATE(YEAR($B$1),MONTH($B$1),1))*(tblTransactions[Transaction Date]<DATE(YEAR($B$1),MONTH($B$1)+1,1))*(tblTransactions[Amount])*((tblTransactions[Transaction Status]="Completed")+(tblTransactions[Transaction Status]="Reconciled"))*(IFERROR(INDEX(tblIncomeSources[Income Category],MATCH(tblTransactions[Income Source],tblIncomeSources[Income Source Name],0)),"")="Salary")),0) -> 0 | D12: =IF(INDEX(tblAccounts[Account Name],ROW()-1)="","",INDEX(tblAccounts[Account Name],ROW()-1)) | E12: =IF($D12="","",IFERROR(INDEX(tblAccounts[Opening Balance],ROW()-1),0)) | F12: =IF($D12="","",SUMIFS(tblTransactions[Amount],tblTransactions[Transaction Type],"Income",tblTransactions[Transaction Status],"Completed",tblTransactions[Source Account],$D12)+SUMIFS(tblTransactions[Amount],tblTransactions[Transaction Type],"Income",tblTransactions[Transaction Status],"Reconciled",tblTransactions[Source Account],$D12)+SUMIFS(tblTransactions[Amount],tblTransactions[Transaction Type],"Transfer",tblTransactions[Transaction Status],"Completed",tblTransactions[Destination Type],"Account",tblTransactions[Destination Name],$D12)+SUMIFS(tblTransactions[Amount],tblTransactions[Transaction Type],"Transfer",tblTransactions[Transaction Status],"Reconciled",tblTransactions[Destination Type],"Account",tblTransactions[Destination Name],$D12)+SUMIFS(tblTransactions[Amount],tblTransactions[Transaction Type],"Adjustment",tblTransactions[Transaction Status],"Completed",tblTransactions[Source Account],$D12,tblTransactions[Amount],">0")+SUMIFS(tblTransactions[Amount],tblTransactions[Transaction Type],"Adjustment",tblTransactions[Transaction Status],"Reconciled",tblTransactions[Source Account],$D12,tblTransactions[Amount],">0")) | G12: =IF($D12="","",SUMIFS(tblTransactions[Amount],tblTransactions[Transaction Type],"Expense",tblTransactions[Transaction Status],"Completed",tblTransactions[Source Account],$D12)+SUMIFS(tblTransactions[Amount],tblTransactions[Transaction Type],"Expense",tblTransactions[Transaction Status],"Reconciled",tblTransactions[Source Account],$D12)+SUMIFS(tblTransactions[Amount],tblTransactions[Transaction Type],"Transfer",tblTransactions[Transaction Status],"Completed",tblTransactions[Source Account],$D12)+SUMIFS(tblTransactions[Amount],tblTransactions[Transaction Type],"Transfer",tblTransactions[Transaction Status],"Reconciled",tblTransactions[Source Account],$D12)-SUMIFS(tblTransactions[Amount],tblTransactions[Transaction Type],"Adjustment",tblTransactions[Transaction Status],"Completed",tblTransactions[Source Account],$D12,tblTransactions[Amount],"<0")-SUMIFS(tblTransactions[Amount],tblTransactions[Transaction Type],"Adjustment",tblTransactions[Transaction Status],"Reconciled",tblTransactions[Source Account],$D12,tblTransactions[Amount],"<0")) | H12: =IF($D12="","",$E12+$F12-$G12) | I12: =#N/A -> #N/A | J12: =IF($D12="","",IFERROR(INDEX(tblAccounts[Account Type],ROW()-1),"")) | K12: =IF($D12="","",IFERROR(INDEX(tblAccounts[Include in Dashboard],ROW()-1),"")) | L12: =IF($D12="","",IFERROR(INDEX(tblAccounts[Status],ROW()-1),""))
A13: Monthly Business Income | B13: =IFERROR(SUMPRODUCT((tblTransactions[Transaction Type]="Income")*(tblTransactions[Transaction Date]>=DATE(YEAR($B$1),MONTH($B$1),1))*(tblTransactions[Transaction Date]<DATE(YEAR($B$1),MONTH($B$1)+1,1))*(tblTransactions[Amount])*((tblTransactions[Transaction Status]="Completed")+(tblTransactions[Transaction Status]="Reconciled"))*(IFERROR(INDEX(tblIncomeSources[Income Category],MATCH(tblTransactions[Income Source],tblIncomeSources[Income Source Name],0)),"")="Business Income")),0) -> 0 | D13: =IF(INDEX(tblAccounts[Account Name],ROW()-1)="","",INDEX(tblAccounts[Account Name],ROW()-1)) | E13: =IF($D13="","",IFERROR(INDEX(tblAccounts[Opening Balance],ROW()-1),0)) | F13: =IF($D13="","",SUMIFS(tblTransactions[Amount],tblTransactions[Transaction Type],"Income",tblTransactions[Transaction Status],"Completed",tblTransactions[Source Account],$D13)+SUMIFS(tblTransactions[Amount],tblTransactions[Transaction Type],"Income",tblTransactions[Transaction Status],"Reconciled",tblTransactions[Source Account],$D13)+SUMIFS(tblTransactions[Amount],tblTransactions[Transaction Type],"Transfer",tblTransactions[Transaction Status],"Completed",tblTransactions[Destination Type],"Account",tblTransactions[Destination Name],$D13)+SUMIFS(tblTransactions[Amount],tblTransactions[Transaction Type],"Transfer",tblTransactions[Transaction Status],"Reconciled",tblTransactions[Destination Type],"Account",tblTransactions[Destination Name],$D13)+SUMIFS(tblTransactions[Amount],tblTransactions[Transaction Type],"Adjustment",tblTransactions[Transaction Status],"Completed",tblTransactions[Source Account],$D13,tblTransactions[Amount],">0")+SUMIFS(tblTransactions[Amount],tblTransactions[Transaction Type],"Adjustment",tblTransactions[Transaction Status],"Reconciled",tblTransactions[Source Account],$D13,tblTransactions[Amount],">0")) | G13: =IF($D13="","",SUMIFS(tblTransactions[Amount],tblTransactions[Transaction Type],"Expense",tblTransactions[Transaction Status],"Completed",tblTransactions[Source Account],$D13)+SUMIFS(tblTransactions[Amount],tblTransactions[Transaction Type],"Expense",tblTransactions[Transaction Status],"Reconciled",tblTransactions[Source Account],$D13)+SUMIFS(tblTransactions[Amount],tblTransactions[Transaction Type],"Transfer",tblTransactions[Transaction Status],"Completed",tblTransactions[Source Account],$D13)+SUMIFS(tblTransactions[Amount],tblTransactions[Transaction Type],"Transfer",tblTransactions[Transaction Status],"Reconciled",tblTransactions[Source Account],$D13)-SUMIFS(tblTransactions[Amount],tblTransactions[Transaction Type],"Adjustment",tblTransactions[Transaction Status],"Completed",tblTransactions[Source Account],$D13,tblTransactions[Amount],"<0")-SUMIFS(tblTransactions[Amount],tblTransactions[Transaction Type],"Adjustment",tblTransactions[Transaction Status],"Reconciled",tblTransactions[Source Account],$D13,tblTransactions[Amount],"<0")) | H13: =IF($D13="","",$E13+$F13-$G13) | I13: =#N/A -> #N/A | J13: =IF($D13="","",IFERROR(INDEX(tblAccounts[Account Type],ROW()-1),"")) | K13: =IF($D13="","",IFERROR(INDEX(tblAccounts[Include in Dashboard],ROW()-1),"")) | L13: =IF($D13="","",IFERROR(INDEX(tblAccounts[Status],ROW()-1),""))
A14: Monthly Freelance Income | B14: =IFERROR(SUMPRODUCT((tblTransactions[Transaction Type]="Income")*(tblTransactions[Transaction Date]>=DATE(YEAR($B$1),MONTH($B$1),1))*(tblTransactions[Transaction Date]<DATE(YEAR($B$1),MONTH($B$1)+1,1))*(tblTransactions[Amount])*((tblTransactions[Transaction Status]="Completed")+(tblTransactions[Transaction Status]="Reconciled"))*(IFERROR(INDEX(tblIncomeSources[Income Category],MATCH(tblTransactions[Income Source],tblIncomeSources[Income Source Name],0)),"")="Freelance")),0) -> 0 | D14: =IF(INDEX(tblAccounts[Account Name],ROW()-1)="","",INDEX(tblAccounts[Account Name],ROW()-1)) | E14: =IF($D14="","",IFERROR(INDEX(tblAccounts[Opening Balance],ROW()-1),0)) | F14: =IF($D14="","",SUMIFS(tblTransactions[Amount],tblTransactions[Transaction Type],"Income",tblTransactions[Transaction Status],"Completed",tblTransactions[Source Account],$D14)+SUMIFS(tblTransactions[Amount],tblTransactions[Transaction Type],"Income",tblTransactions[Transaction Status],"Reconciled",tblTransactions[Source Account],$D14)+SUMIFS(tblTransactions[Amount],tblTransactions[Transaction Type],"Transfer",tblTransactions[Transaction Status],"Completed",tblTransactions[Destination Type],"Account",tblTransactions[Destination Name],$D14)+SUMIFS(tblTransactions[Amount],tblTransactions[Transaction Type],"Transfer",tblTransactions[Transaction Status],"Reconciled",tblTransactions[Destination Type],"Account",tblTransactions[Destination Name],$D14)+SUMIFS(tblTransactions[Amount],tblTransactions[Transaction Type],"Adjustment",tblTransactions[Transaction Status],"Completed",tblTransactions[Source Account],$D14,tblTransactions[Amount],">0")+SUMIFS(tblTransactions[Amount],tblTransactions[Transaction Type],"Adjustment",tblTransactions[Transaction Status],"Reconciled",tblTransactions[Source Account],$D14,tblTransactions[Amount],">0")) | G14: =IF($D14="","",SUMIFS(tblTransactions[Amount],tblTransactions[Transaction Type],"Expense",tblTransactions[Transaction Status],"Completed",tblTransactions[Source Account],$D14)+SUMIFS(tblTransactions[Amount],tblTransactions[Transaction Type],"Expense",tblTransactions[Transaction Status],"Reconciled",tblTransactions[Source Account],$D14)+SUMIFS(tblTransactions[Amount],tblTransactions[Transaction Type],"Transfer",tblTransactions[Transaction Status],"Completed",tblTransactions[Source Account],$D14)+SUMIFS(tblTransactions[Amount],tblTransactions[Transaction Type],"Transfer",tblTransactions[Transaction Status],"Reconciled",tblTransactions[Source Account],$D14)-SUMIFS(tblTransactions[Amount],tblTransactions[Transaction Type],"Adjustment",tblTransactions[Transaction Status],"Completed",tblTransactions[Source Account],$D14,tblTransactions[Amount],"<0")-SUMIFS(tblTransactions[Amount],tblTransactions[Transaction Type],"Adjustment",tblTransactions[Transaction Status],"Reconciled",tblTransactions[Source Account],$D14,tblTransactions[Amount],"<0")) | H14: =IF($D14="","",$E14+$F14-$G14) | I14: =#N/A -> #N/A | J14: =IF($D14="","",IFERROR(INDEX(tblAccounts[Account Type],ROW()-1),"")) | K14: =IF($D14="","",IFERROR(INDEX(tblAccounts[Include in Dashboard],ROW()-1),"")) | L14: =IF($D14="","",IFERROR(INDEX(tblAccounts[Status],ROW()-1),""))
